Workbook

Sheet Soal
A1: BDI (The Beck Depression Inventory) Test | G1: “RAHASIA”
A3: NAMA | C3: :
A4: JENIS KELAMIN | C4: :
A5: USIA | C5: :
A6: PENDIDIKAN | C6: :
A7: PEKERJAAN | C7: :
A9: Pilihlah salah satu penyataan yang anda anggap sesuai dengan diri anda saat ini, dengan memberi tanda silang (x) pada huruf di depan penyataan yang anda pilih :
B11: 1 | D11: Saya tidak merasa sedih | R11: =IF(C11="X",1,"0") -> 0 | T11: =IF(C11="X",0,"0") -> 0
D12: Saya merasa sedih | R12: =IF(C12="X",1,"0") -> 0 | T12: =IF(C12="X",1,"0") -> 0
D13: Saya merasa sedih sepanjang waktu dan saya tidak dapat menghilangkannya | R13: =IF(C13="X",1,"0") -> 0 | T13: =IF(C13="X",2,"0") -> 0
D14: Saya begitu sedih sehingga saya merasa tidak tahan lagi | R14: =IF(C14="X",1,"0") -> 0 | T14: =IF(C14="X",3,"0") -> 0
B16: =B11+1 -> 2 | D16: Saya tidak merasa berkecil hati terhadap masa depan | R16: =IF(C16="X",1,"0") -> 0 | T16: =IF(C16="X",0,"0") -> 0
D17: Saya merasa berkecil hati terhadap masa depan | R17: =IF(C17="X",1,"0") -> 0 | T17: =IF(C17="X",1,"0") -> 0
D18: Saya merasa tidak ada sesuatu yang saya nantikan | R18: =IF(C18="X",1,"0") -> 0 | T18: =IF(C18="X",2,"0") -> 0
D19: Saya merasa bahwa tidak ada harapan di masa depan dan segala sesuatunya tidak dapat diperbaiki | R19: =IF(C19="X",1,"0") -> 0 | T19: =IF(C19="X",3,"0") -> 0
B21: =B16+1 -> 3 | D21: Saya tidak merasa gagal | R21: =IF(C21="X",1,"0") -> 0 | T21: =IF(C21="X",0,"0") -> 0
D22: Saya merasa lebih banyak mengalami kegagalan daripada rata – rata orang | R22: =IF(C22="X",1,"0") -> 0 | T22: =IF(C22="X",1,"0") -> 0
D23: Kalau saya meninjau kembali hidup saya, yang dapat saya lihat hanyalah banyak kegagalan | R23: =IF(C23="X",1,"0") -> 0 | T23: =IF(C23="X",2,"0") -> 0
D24: Saya merasa sebagai seorang pribadi yang gagal total | R24: =IF(C24="X",1,"0") -> 0 | T24: =IF(C24="X",3,"0") -> 0
B26: =B21+1 -> 4 | D26: Saya memperoleh kepuasan atas segala sesuatu seperti biasanya | R26: =IF(C26="X",1,"0") -> 0 | T26: =IF(C26="X",0,"0") -> 0
D27: Saya tidak dapat menikmati segala sesuatu seperti biasanya | R27: =IF(C27="X",1,"0") -> 0 | T27: =IF(C27="X",1,"0") -> 0
D28: Saya tidak lagi memperoleh kepuasan yang nyata dari segala sesuatu | R28: =IF(C28="X",1,"0") -> 0 | T28: =IF(C28="X",2,"0") -> 0
D29: Saya merasa tidak puas atau bosan terhadap apa saja | R29: =IF(C29="X",1,"0") -> 0 | T29: =IF(C29="X",3,"0") -> 0
B31: =B26+1 -> 5 | D31: Saya tidak merasa bersalah | R31: =IF(C31="X",1,"0") -> 0 | T31: =IF(C31="X",0,"0") -> 0
D32: Saya cukup sering merasa bersalah | R32: =IF(C32="X",1,"0") -> 0 | T32: =IF(C32="X",1,"0") -> 0
D33: Saya sering merasa sangat bersalah | R33: =IF(C33="X",1,"0") -> 0 | T33: =IF(C33="X",2,"0") -> 0
D34: Saya merasa bersalah sepanjang waktu | R34: =IF(C34="X",1,"0") -> 0 | T34: =IF(C34="X",3,"0") -> 0
B36: =B31+1 -> 6 | D36: Saya tidak merasa bahwa saya sedang dihukum | R36: =IF(C36="X",1,"0") -> 0 | T36: =IF(C36="X",0,"0") -> 0
D37: Saya merasa bahwa saya mungkin dihukum | R37: =IF(C37="X",1,"0") -> 0 | T37: =IF(C37="X",1,"0") -> 0
D38: Saya mengharapkan agar dihukum | R38: =IF(C38="X",1,"0") -> 0 | T38: =IF(C38="X",2,"0") -> 0
D39: Saya merasa bahwa saya sedang dihukum | R39: =IF(C39="X",1,"0") -> 0 | T39: =IF(C39="X",3,"0") -> 0
B41: =B36+1 -> 7 | D41: Saya tidak merasa kecewa terhadap diri saya sendiri | R41: =IF(C41="X",1,"0") -> 0 | T41: =IF(C41="X",0,"0") -> 0
D42: Saya merasa kecewa terhadap diri saya sendiri | R42: =IF(C42="X",1,"0") -> 0 | T42: =IF(C42="X",1,"0") -> 0
D43: Saya merasa jijik terhadap diri saya sendiri | R43: =IF(C43="X",1,"0") -> 0 | T43: =IF(C43="X",2,"0") -> 0
D44: Saya membenci diri saya sendiri | R44: =IF(C44="X",1,"0") -> 0 | T44: =IF(C44="X",3,"0") -> 0
B46: =B41+1 -> 8 | D46: Saya tidak merasa bahwa saya lebih buruk daripada orang lain | R46: =IF(C46="X",1,"0") -> 0 | T46: =IF(C46="X",0,"0") -> 0
D47: Saya selalu mencela diri saya sendiri karena kelemahan atau kekeliruan saya | R47: =IF(C47="X",1,"0") -> 0 | T47: =IF(C47="X",1,"0") -> 0
D48: Saya menyalahkan diri saya sendiri sepanjang waktu atas kesalahan – kesalahan saya | R48: =IF(C48="X",1,"0") -> 0 | T48: =IF(C48="X",2,"0") -> 0
D49: Saya menyalahkan diri saya sendiri atas semua hal buruk yang terjadi | R49: =IF(C49="X",1,"0") -> 0 | T49: =IF(C49="X",3,"0") -> 0
B51: =B46+1 -> 9 | D51: Saya tidak mempunyai pikiran untuk bunuh diri | R51: =IF(C51="X",1,"0") -> 0 | T51: =IF(C51="X",0,"0") -> 0
...

Sheet Skoring
A1: =Soal!A1 -> BDI (The Beck Depression Inventory) Test | K1: =Soal!G1 -> “RAHASIA”
A3: =Soal!A3 -> NAMA | E3: =Soal!C3 -> : | F3: =Soal!D3 -> 0
A4: =Soal!A4 -> JENIS KELAMIN | E4: =Soal!C4 -> : | F4: =Soal!D4 -> 0
A5: =Soal!A5 -> USIA | E5: =Soal!C5 -> : | F5: =Soal!D5 -> 0
A6: =Soal!A6 -> PENDIDIKAN | E6: =Soal!C6 -> : | F6: =Soal!D6 -> 0
A7: =Soal!A7 -> PEKERJAAN | E7: =Soal!C7 -> : | F7: =Soal!D7 -> 0
B9: 1 | C9: =Soal!T11 -> 0 | E9: =B9+1 -> 2 | F9: =Soal!T16 -> 0 | H9: =E9+1 -> 3 | I9: =Soal!T21 -> 0 | K9: =H9+1 -> 4 | L9: =Soal!T26 -> 0 | N9: =K9+1 -> 5 | O9: =Soal!T31 -> 0 | Q9: =N9+1 -> 6 | R9: =Soal!T36 -> 0 | T9: =Q9+1 -> 7 | U9: =Soal!T41 -> 0 | W9: =T9+1 -> 8 | X9: =Soal!T46 -> 0 | Z9: =W9+1 -> 9 | AA9: =Soal!T51 -> 0 | AC9: =Z9+1 -> 10 | AD9: =Soal!T56 -> 0
C10: =Soal!T12 -> 0 | F10: =Soal!T17 -> 0 | I10: =Soal!T22 -> 0 | L10: =Soal!T27 -> 0 | O10: =Soal!T32 -> 0 | R10: =Soal!T37 -> 0 | U10: =Soal!T42 -> 0 | X10: =Soal!T47 -> 0 | AA10: =Soal!T52 -> 0 | AD10: =Soal!T57 -> 0
C11: =Soal!T13 -> 0 | F11: =Soal!T18 -> 0 | I11: =Soal!T23 -> 0 | L11: =Soal!T28 -> 0 | O11: =Soal!T33 -> 0 | R11: =Soal!T38 -> 0 | U11: =Soal!T43 -> 0 | X11: =Soal!T48 -> 0 | AA11: =Soal!T53 -> 0 | AD11: =Soal!T58 -> 0
C12: =Soal!T14 -> 0 | F12: =Soal!T19 -> 0 | I12: =Soal!T24 -> 0 | L12: =Soal!T29 -> 0 | O12: =Soal!T34 -> 0 | R12: =Soal!T39 -> 0 | U12: =Soal!T44 -> 0 | X12: =Soal!T49 -> 0 | AA12: =Soal!T54 -> 0 | AD12: =Soal!T59 -> 0
B15: =AC9+1 -> 11 | C15: =Soal!T61 -> 0 | E15: =B15+1 -> 12 | F15: =Soal!T66 -> 0 | H15: =E15+1 -> 13 | I15: =Soal!T71 -> 0 | K15: =H15+1 -> 14 | L15: =Soal!T76 -> 0 | N15: =K15+1 -> 15 | O15: =Soal!T81 -> 0 | Q15: =N15+1 -> 16 | R15: =Soal!T86 -> 0 | T15: =Q15+1 -> 17 | U15: =Soal!T91 -> 0 | W15: =T15+1 -> 18 | X15: =Soal!T96 -> 0 | Z15: =W15+1 -> 19 | AA15: =Soal!T101 -> 0 | AC15: =Z15+1 -> 20 | AD15: =Soal!T106 -> 0
C16: =Soal!T62 -> 0 | F16: =Soal!T67 -> 0 | I16: =Soal!T72 -> 0 | L16: =Soal!T77 -> 0 | O16: =Soal!T82 -> 0 | R16: =Soal!T87 -> 0 | U16: =Soal!T92 -> 0 | X16: =Soal!T97 -> 0 | AA16: =Soal!T102 -> 0 | AD16: =Soal!T107 -> 0
C17: =Soal!T63 -> 0 | F17: =Soal!T68 -> 0 | I17: =Soal!T73 -> 0 | L17: =Soal!T78 -> 0 | O17: =Soal!T83 -> 0 | R17: =Soal!T88 -> 0 | U17: =Soal!T93 -> 0 | X17: =Soal!T98 -> 0 | AA17: =Soal!T103 -> 0 | AD17: =Soal!T108 -> 0
C18: =Soal!T64 -> 0 | F18: =Soal!T69 -> 0 | I18: =Soal!T74 -> 0 | L18: =Soal!T79 -> 0 | O18: =Soal!T84 -> 0 | R18: =Soal!T89 -> 0 | U18: =Soal!T94 -> 0 | X18: =Soal!T99 -> 0 | AA18: =Soal!T104 -> 0 | AD18: =Soal!T109 -> 0
B21: =AC15+1 -> 21 | C21: =Soal!T111 -> 0 | F21: =SUM(C9:C24) -> 0 | G21: =SUM(R9:R18) -> 0 | J21: =SUM(F21:G25) -> 0 | L21: Interpretasi :
C22: =Soal!T112 -> 0 | F22: =SUM(F9:F18) -> 0 | G22: =SUM(U9:U18) -> 0 | L22: =IF(AND(J21>=0,J21<=10),"Naik turun perasaan ini cenderung masih tergolong wajar",IF(AND(J21>=11,J21<=16),"Cenderung gangguan “mood” atau perasaan murung yang ringan, sebaiknya mulai relax, refresing atau menghibur diri sendiri",IF(AND(J21>=17,J21<=20),"Cenderung garis batas depresi klinis, sebaiknya mulai konsultasikan dengan profesional",IF(AND(J21>=21,J21<=30),"Cenderung depresi Sedang, sebaiknya mulai konsultasikan dengan profesional",IF(AND(J21>=31,J21<=40),"Cenderung depresi Parah, sebaiknya mulai konsultasikan dengan profesional","Cenderung depresi Ekstrim, sebaiknya mulai konsultasikan dengan profesional"))))) -> Naik turun perasaan ini cenderung masih tergolong wajar
C23: =Soal!T113 -> 0 | F23: =SUM(I9:I18) -> 0 | G23: =SUM(X9:X18) -> 0
C24: =Soal!T114 -> 0 | F24: =SUM(L9:L18) -> 0 | G24: =SUM(AA9:AA18) -> 0
F25: =SUM(O9:O18) -> 0 | G25: =SUM(AD9:AD18) -> 0
