Workbook

Sheet Input
A1: Software Skoring IST | O1: RW
A2: SoftwarePsikotes.com | N2: SE | O2: =C93 -> 0
N3: WA | O3: =F93 -> 0
A4: Nomor | C4: : | N4: AN | O4: =I93 -> 0
A5: Nama | C5: : | N5: GE | O5: =K89 -> 0
A6: Tgl Lahir / Usia | C6: : | N6: ME | O6: =L119 -> 0
A7: Tgl Tes | C7: : | N7: RA | O7: =O93 -> 0
A8: Pendidikan | C8: : | N8: ZR | O8: =C119 -> 0
A9: Tujuan Tes | C9: : | N9: FA | O9: =F119 -> 0
N10: WU | O10: =I119 -> 0
N11: JML | O11: =SUM(O2:O10) -> 0
B13: Perhatian: Pemeriksa hanya boleh mengisi di kolom berwarna putih di tabel!
B15: SE | E15: WA | H15: AN | K15: GE | N15: RA
B16: No | C16: Jawaban Klien | E16: No | F16: Jawaban Klien | H16: No | I16: Jawaban Klien | K16: No | L16: Jawaban Klien | N16: No | O16: Jawaban Klien
B18: 1 | E18: 21 | H18: 41 | K18: 61 | N18: 77
B19: 2 | E19: 22 | H19: 42 | K19: 62 | N19: 78
B20: 3 | E20: 23 | H20: 43 | K20: 63 | N20: 79
B21: 4 | E21: 24 | H21: 44 | K21: 64 | N21: 80
B22: 5 | E22: 25 | H22: 45 | K22: 65 | N22: 81
B23: 6 | E23: 26 | H23: 46 | K23: 66 | N23: 82
B24: 7 | E24: 27 | H24: 47 | K24: 67 | N24: 83
B25: 8 | E25: 28 | H25: 48 | K25: 68 | N25: 84
B26: 9 | E26: 29 | H26: 49 | K26: 69 | N26: 85
B27: 10 | E27: 30 | H27: 50 | K27: 70 | N27: 86
B28: 11 | E28: 31 | H28: 51 | K28: 71 | N28: 87
B29: 12 | E29: 32 | H29: 52 | K29: 72 | N29: 88
... B33: 16 | E33: 36 | H33: 56 | K33: 76 | N33: 92
B34: 17 | E34: 37 | H34: 57 | N34: 93
B35: 18 | E35: 38 | H35: 58 | N35: 94
B36: 19 | E36: 39 | H36: 59 | N36: 95
B37: 20 | E37: 40 | H37: 60 | N37: 96
B41: ZR | E41: FA | H41: WU | K41: ME
B42: No | C42: Jawaban Klien | E42: No | F42: Jawaban Klien | H42: No | I42: Jawaban Klien | K42: No | L42: Jawaban Klien
B44: 97 | E44: 117 | H44: 137 | K44: 157
B45: 98 | E45: 118 | H45: 138 | K45: 158
B46: 99 | E46: 119 | H46: 139 | K46: 159
B47: 100 | E47: 120 | H47: 140 | K47: 160
B48: 101 | E48: 121 | H48: 141 | K48: 161
B49: 102 | E49: 122 | H49: 142 | K49: 162
B50: 103 | E50: 123 | H50: 143 | K50: 163
...

Sheet Output
A1: - Software Psikotes -
J7: RW | K7: SW
I9: SE | J9: =Input!O2 -> 0 | K9: =Norma!A10 -> 60
I10: WA | J10: =Input!O3 -> 0 | K10: =Norma!A11 -> 35
I11: AN | J11: =Input!O4 -> 0 | K11: =Norma!A12 -> 34
I12: GE | J12: =Input!O5 -> 0 | K12: =Norma!A13 -> 57
I13: ME | J13: =Input!O6 -> 0 | K13: =Norma!A14 -> 52
I14: RA | J14: =Input!O7 -> 0 | K14: =Norma!A15 -> 60
I15: ZR | J15: =Input!O8 -> 0 | K15: =Norma!A16 -> 60
I16: FA | J16: =Input!O9 -> 0 | K16: =Norma!A17 -> 45
I17: WU | J17: =Input!O10 -> 0 | K17: =Norma!A18 -> 55
N18: SE | Q18: WA | T18: AN | W18: GE | Z18: ME | AC18: RA | AF18: ZR | AI18: FA | AL18: WU
I19: IQ | J19: =SUM(J9:J17) -> 0 | K19: =Norma!A20 -> #N/A
B25: Nomor | C25: : | D25: =IF(Input!D4>0,Input!D4,"")
B26: Nama | C26: : | D26: =IF(Input!D5>0,Input!D5,"")
B27: Tgl Lahir/Usia | C27: : | D27: =IF(Input!D6>0,Input!D6,"")
B28: Tgl Tes | C28: : | D28: =IF(Input!D7>0,Input!D7,"")
B29: Pendidikan | C29: : | D29: =IF(Input!D8>0,Input!D8,"")
B30: Tujuan Tes | C30: : | D30: =IF(Input!D9>0,Input!D9,"")

Sheet Norma
A1: RAHASIA | D1: SE | G1: WA | J1: AN | M1: GE | P1: ME | S1: RA | V1: ZR | Y1: FA | AB1: WU
C2: RW | D2: SLTP | E2: SLTA | F2: SARJ | G2: SLTP | H2: SLTA | I2: SARJ | J2: SLTP | K2: SLTA | L2: SARJ | M2: SLTP | N2: SLTA | O2: SARJ | P2: SLTP | Q2: SLTA | R2: SARJ | S2: SLTP | T2: SLTA | U2: SARJ | V2: SLTP | W2: SLTA | X2: SARJ | Y2: SLTP | Z2: SLTA | AA2: SARJ | AB2: SLTP | AC2: SLTA | AD2: SARJ
C3: 0 | D3: 69 | E3: 71 | F3: 60 | G3: 68 | H3: 67 | I3: 35 | J3: 76 | K3: 79 | L3: 34 | M3: 78 | N3: 70 | O3: 57 | P3: 71 | Q3: 74 | R3: 52 | S3: 79 | T3: 79 | U3: 60 | V3: 79 | W3: 85 | X3: 60 | Y3: 66 | Z3: 69 | AA3: 45 | AB3: 74 | AC3: 75 | AD3: 55 | AE3: 0
C4: 1 | D4: 73 | E4: 75 | F4: 65 | G4: 72 | H4: 71 | I4: 40 | J4: 80 | K4: 83 | L4: 42 | M4: 80 | N4: 72 | O4: 60 | P4: 74 | Q4: 76 | R4: 56 | S4: 82 | T4: 82 | U4: 65 | V4: 81 | W4: 87 | X4: 64 | Y4: 69 | Z4: 73 | AA4: 50 | AB4: 76 | AC4: 78 | AD4: 60 | AE4: 1
C5: 2 | D5: 77 | E5: 78 | F5: 70 | G5: 76 | H5: 74 | I5: 45 | J5: 83 | K5: 86 | L5: 60 | M5: 82 | N5: 75 | O5: 63 | P5: 76 | Q5: 78 | R5: 60 | S5: 84 | T5: 84 | U5: 70 | V5: 84 | W5: 89 | X5: 68 | Y5: 73 | Z5: 75 | AA5: 55 | AB5: 79 | AC5: 81 | AD5: 65 | AE5: 2
C6: 3 | D6: 82 | E6: 82 | F6: 75 | G6: 80 | H6: 78 | I6: 50 | J6: 87 | K6: 89 | L6: 68 | M6: 84 | N6: 77 | O6: 64 | P6: 78 | Q6: 80 | R6: 64 | S6: 87 | T6: 87 | U6: 75 | V6: 86 | W6: 91 | X6: 72 | Y6: 76 | Z6: 79 | AA6: 60 | AB6: 82 | AC6: 84 | AD6: 70 | AE6: 3
C7: 4 | D7: 86 | E7: 86 | F7: 80 | G7: 84 | H7: 81 | I7: 55 | J7: 90 | K7: 92 | L7: 76 | M7: 86 | N7: 79 | O7: 67 | P7: 81 | Q7: 82 | R7: 68 | S7: 90 | T7: 89 | U7: 80 | V7: 88 | W7: 93 | X7: 76 | Y7: 79 | Z7: 82 | AA7: 65 | AB7: 85 | AC7: 87 | AD7: 75 | AE7: 4
A8: HASIL SW | C8: 5 | D8: 90 | E8: 90 | F8: 85 | G8: 87 | H8: 84 | I8: 60 | J8: 94 | K8: 96 | L8: 84 | M8: 88 | N8: 81 | O8: 70 | P8: 83 | Q8: 84 | R8: 72 | S8: 92 | T8: 92 | U8: 85 | V8: 91 | W8: 95 | X8: 80 | Y8: 82 | Z8: 85 | AA8: 70 | AB8: 88 | AC8: 90 | AD8: 80 | AE8: 5
C9: 6 | D9: 94 | E9: 93 | F9: 90 | G9: 91 | H9: 88 | I9: 65 | J9: 98 | K9: 99 | L9: 92 | M9: 90 | N9: 84 | O9: 73 | P9: 86 | Q9: 87 | R9: 76 | S9: 95 | T9: 95 | U9: 90 | V9: 93 | W9: 96 | X9: 84 | Y9: 86 | Z9: 88 | AA9: 75 | AB9: 91 | AC9: 93 | AD9: 85 | AE9: 6
A10: =IF(Output!J9>20,"Salah",IF(Output!$D$29="SLTP",VLOOKUP(Output!J9,Norma!$C$3:$AD$35,2),IF(Output!$D$29="SLTA",(VLOOKUP(Output!J9,Norma!$C$3:$AD$35,3)),(VLOOKUP(Output!J9,Norma!$C$3:$AD$35,4))))) -> 60 | C10: 7 | D10: 98 | E10: 97 | F10: 95 | G10: 95 | H10: 92 | I10: 70 | J10: 101 | K10: 102 | L10: 100 | M10: 92 | N10: 86 | O10: 76 | P10: 88 | Q10: 89 | R10: 80 | S10: 98 | T10: 97 | U10: 95 | V10: 95 | W10: 98 | X10: 88 | Y10: 89 | Z10: 91 | AA10: 80 | AB10: 94 | AC10: 96 | AD10: 90 | AE10: 7
A11: =IF(Output!J10>20,"Salah",IF(Output!$D$29="SLTP",VLOOKUP(Output!J10,Norma!$C$3:$AD$35,5),IF(Output!$D$29="SLTA",(VLOOKUP(Output!J10,Norma!$C$3:$AD$35,6)),(VLOOKUP(Output!J10,Norma!$C$3:$AD$35,7))))) -> 35 | C11: 8 | D11: 102 | E11: 101 | F11: 100 | G11: 99 | H11: 95 | I11: 75 | J11: 105 | K11: 106 | L11: 108 | M11: 94 | N11: 88 | O11: 79 | P11: 91 | Q11: 91 | R11: 84 | S11: 100 | T11: 100 | U11: 100 | V11: 98 | W11: 100 | X11: 92 | Y11: 92 | Z11: 94 | AA11: 85 | AB11: 97 | AC11: 99 | AD11: 95 | AE11: 8
A12: =IF(Output!J11>20,"Salah",IF(Output!$D$29="SLTP",VLOOKUP(Output!J11,Norma!$C$3:$AD$35,8),IF(Output!$D$29="SLTA",(VLOOKUP(Output!J11,Norma!$C$3:$AD$35,9)),(VLOOKUP(Output!J11,Norma!$C$3:$AD$35,10))))) -> 34 | C12: 9 | D12: 106 | E12: 105 | F12: 105 | G12: 103 | H12: 98 | I12: 80 | J12: 108 | K12: 109 | L12: 116 | M12: 96 | N12: 90 | O12: 81 | P12: 93 | Q12: 93 | R12: 88 | S12: 103 | T12: 102 | U12: 105 | V12: 100 | W12: 102 | X12: 96 | Y12: 95 | Z12: 97 | AA12: 90 | AB12: 100 | AC12: 102 | AD12: 100 | AE12: 9
A13: =IF(Output!J12>32,"Salah",IF(Output!$D$29="SLTP",VLOOKUP(Output!J12,Norma!$C$3:$AD$35,11),IF(Output!$D$29="SLTA",(VLOOKUP(Output!J12,Norma!$C$3:$AD$35,12)),(VLOOKUP(Output!J12,Norma!$C$3:$AD$35,13))))) -> 57 | C13: 10 | D13: 110 | E13: 108 | F13: 110 | G13: 107 | H13: 102 | I13: 85 | J13: 112 | K13: 112 | L13: 124 | M13: 97 | N13: 93 | O13: 84 | P13: 95 | Q13: 95 | R13: 92 | S13: 106 | T13: 105 | U13: 110 | V13: 102 | W13: 104 | X13: 100 | Y13: 99 | Z13: 100 | AA13: 95 | AB13: 103 | AC13: 105 | AD13: 105 | AE13: 10
A14: =IF(Output!J13>20,"Salah",IF(Output!$D$29="SLTP",VLOOKUP(Output!J13,Norma!$C$3:$AD$35,14),IF(Output!$D$29="SLTA",(VLOOKUP(Output!J13,Norma!$C$3:$AD$35,15)),(VLOOKUP(Output!J13,Norma!$C$3:$AD$35,16))))) -> 52 | C14: 11 | D14: 114 | E14: 112 | F14: 115 | G14: 111 | H14: 105 | I14: 90 | J14: 115 | K14: 115 | L14: 132 | M14: 99 | N14: 95 | O14: 87 | P14: 98 | Q14: 97 | R14: 96 | S14: 108 | T14: 107 | U14: 115 | V14: 105 | W14: 106 | X14: 104 | Y14: 102 | Z14: 103 | AA14: 100 | AB14: 106 | AC14: 108 | AD14: 110 | AE14: 11
A15: =IF(Output!J14>20,"Salah",IF(Output!$D$29="SLTP",VLOOKUP(Output!J14,Norma!$C$3:$AD$35,17),IF(Output!$D$29="SLTA",(VLOOKUP(Output!J14,Norma!$C$3:$AD$35,18)),(VLOOKUP(Output!J14,Norma!$C$3:$AD$35,19))))) -> 60 | C15: 12 | D15: 118 | E15: 116 | F15: 120 | G15: 114 | H15: 109 | I15: 95 | J15: 119 | K15: 119 | L15: 140 | M15: 101 | N15: 97 | O15: 90 | P15: 100 | Q15: 100 | R15: 100 | S15: 111 | T15: 110 | U15: 120 | V15: 107 | W15: 108 | X15: 108 | Y15: 105 | Z15: 106 | AA15: 105 | AB15: 109 | AC15: 111 | AD15: 115 | AE15: 12
A16: =IF(Output!J15>20,"Salah",IF(Output!$D$29="SLTP",VLOOKUP(Output!J15,Norma!$C$3:$AD$35,20),IF(Output!$D$29="SLTA",(VLOOKUP(Output!J15,Norma!$C$3:$AD$35,21)),(VLOOKUP(Output!J15,Norma!$C$3:$AD$35,22))))) -> 60 | C16: 13 | D16: 122 | E16: 120 | F16: 125 | G16: 118 | H16: 112 | I16: 100 | J16: 122 | K16: 122 | L16: 148 | M16: 103 | N16: 99 | O16: 93 | P16: 103 | Q16: 102 | R16: 104 | S16: 114 | T16: 112 | U16: 125 | V16: 109 | W16: 109 | X16: 112 | Y16: 108 | Z16: 109 | AA16: 110 | AB16: 112 | AC16: 114 | AD16: 120 | AE16: 13
A17: =IF(Output!J16>20,"Salah",IF(Output!$D$29="SLTP",VLOOKUP(Output!J16,Norma!$C$3:$AD$35,23),IF(Output!$D$29="SLTA",(VLOOKUP(Output!J16,Norma!$C$3:$AD$35,24)),(VLOOKUP(Output!J16,Norma!$C$3:$AD$35,25))))) -> 45 | C17: 14 | D17: 126 | E17: 123 | F17: 130 | G17: 122 | H17: 116 | I17: 105 | J17: 126 | K17: 125 | L17: 156 | M17: 105 | N17: 101 | O17: 96 | P17: 105 | Q17: 104 | R17: 108 | S17: 116 | T17: 115 | U17: 130 | V17: 112 | W17: 111 | X17: 116 | Y17: 112 | Z17: 112 | AA17: 115 | AB17: 115 | AC17: 117 | AD17: 125 | AE17: 14
A18: =IF(Output!J17>20,"Salah",IF(Output!$D$29="SLTP",VLOOKUP(Output!J17,Norma!$C$3:$AD$35,26),IF(Output!$D$29="SLTA",(VLOOKUP(Output!J17,Norma!$C$3:$AD$35,27)),(VLOOKUP(Output!J17,Norma!$C$3:$AD$35,28))))) -> 55 | C18: 15 | D18: 130 | E18: 127 | F18: 135 | G18: 126 | H18: 119 | I18: 110 | J18: 130 | K18: 129 | L18: 164 | M18: 107 | N18: 104 | O18: 97 | P18: 108 | Q18: 106 | R18: 112 | S18: 119 | T18: 118 | U18: 135 | V18: 114 | W18: 113 | X18: 120 | Y18: 115 | Z18: 115 | AA18: 120 | AB18: 118 | AC18: 120 | AD18: 130 | AE18: 15
A19: TOTAL | C19: 16 | D19: 134 | E19: 131 | F19: 140 | G19: 130 | H19: 123 | I19: 115 | J19: 133 | K19: 132 | L19: 172 | M19: 109 | N19: 106 | O19: 100 | P19: 110 | Q19: 108 | R19: 116 | S19: 122 | T19: 120 | U19: 140 | V19: 116 | W19: 115 | X19: 124 | Y19: 118 | Z19: 118 | AA19: 125 | AB19: 121 | AC19: 123 | AD19: 135 | AE19: 16
A20: =IF(Output!$D$29="sltp",VLOOKUP(Output!$J$19,Norma!$C$38:$D$161,2),VLOOKUP(Output!$J$19,Norma!$E$38:$F$166,2)) -> #N/A | C20: 17 | D20: 139 | E20: 135 | F20: 145 | G20: 134 | H20: 126 | I20: 120 | J20: 137 | K20: 135 | L20: 180 | M20: 111 | N20: 108 | O20: 103 | P20: 113 | Q20: 110 | R20: 120 | S20: 124 | T20: 123 | U20: 145 | V20: 119 | W20: 117 | X20: 128 | Y20: 121 | Z20: 121 | AA20: 130 | AB20: 124 | AC20: 126 | AD20: 140 | AE20: 17
C21: 18 | D21: 143 | E21: 138 | F21: 150 | G21: 138 | H21: 130 | I21: 125 | J21: 140 | K21: 138 | L21: 188 | M21: 113 | N21: 110 | O21: 106 | P21: 115 | Q21: 112 | R21: 124 | S21: 127 | T21: 125 | U21: 150 | V21: 121 | W21: 119 | X21: 132 | Y21: 124 | Z21: 124 | AA21: 135 | AB21: 127 | AC21: 129 | AD21: 145 | AE21: 18
C22: 19 | D22: 147 | E22: 142 | F22: 155 | G22: 141 | H22: 133 | I22: 130 | J22: 144 | K22: 142 | L22: 196 | M22: 115 | N22: 113 | O22: 109 | P22: 117 | Q22: 115 | R22: 128 | S22: 130 | T22: 128 | U22: 155 | V22: 123 | W22: 121 | X22: 136 | Y22: 128 | Z22: 127 | AA22: 140 | AB22: 130 | AC22: 131 | AD22: 150 | AE22: 19
C23: 20 | D23: 151 | E23: 146 | F23: 160 | G23: 145 | H23: 137 | I23: 135 | J23: 147 | K23: 145 | L23: 204 | M23: 117 | N23: 115 | O23: 111 | P23: 120 | Q23: 117 | R23: 132 | S23: 132 | T23: 130 | U23: 160 | V23: 126 | W23: 122 | X23: 140 | Y23: 131 | Z23: 130 | AA23: 145 | AB23: 133 | AC23: 134 | AD23: 155 | AE23: 20
C24: 21 | M24: 119 | N24: 117 | O24: 114 | AE24: 21
C25: 22 | M25: 121 | N25: 119 | O25: 117 | AE25: 22
C26: 23 | M26: 123 | N26: 122 | O26: 120 | AE26: 23
C27: 24 | M27: 125 | N27: 124 | O27: 123 | AE27: 24
C28: 25 | M28: 127 | N28: 126 | O28: 126 | AE28: 25
C29: 26 | M29: 129 | N29: 129 | O29: 129 | AE29: 26
C30: 27 | M30: 131 | N30: 131 | O30: 131 | AE30: 27
C31: 28 | M31: 133 | N31: 133 | O31: 134 | AE31: 28
C32: 29 | M32: 135 | N32: 135 | O32: 137 | AE32: 29
C33: 30 | M33: 137 | N33: 137 | O33: 140 | AE33: 30
C34: 31 | M34: 139 | N34: 140 | O34: 143 | AE34: 31
C35: 32 | M35: 141 | N35: 142 | O35: 146 | AE35: 32
C38: SLTP | D38: IQ Total | E38: >SLTP | F38: IQ Total
C39: 28 | D39: 77 | E39: 25 | F39: 70
C40: 29 | D40: 77 | E40: 26 | F40: 70
C41: 30 | D41: 78 | E41: 27 | F41: 71
C42: 31 | D42: 78 | E42: 28 | F42: 71
...
