Workbook

Sheet Test
A1: TES KPR-V (Kuder Preference Record-Vocational)
C5: Isikan x pada kolom + (Paling disukai) atau - (Paling tidak disukai)
C7: Pertanyaan | D7: + | E7: - | F7: Jawaban Klien | G7: + | H7: - | I7: N | J7: E | K7: Laki-laki | L7: 1
A8: 1 | B8: a | C8: Jika bepergian memperhatikan orang lain | F8: =IF(D8="x",IF(E8<>"x","Paling Disukai","ERROR"),IF(E8="x","Paling Tidak Disukai","")) | G8: =IF(D8="x",IF(E8<>"x",1,0),0) -> 0 | H8: =IF(E8="x",IF(D8<>"x",1,0),0) -> 0 | I8: =IF(E8="x",0,IF(D8<>"x",1,0)) -> 1 | J8: =IF(E8="x",IF(D8<>"x",0,1),0) -> 0 | K8: Perempuan
B9: b | C9: Jika bepergian memperhatikan pemandangan alam | F9: =IF(D9="x",IF(E9<>"x","Paling Disukai","ERROR"),IF(E9="x","Paling Tidak Disukai","")) | G9: =IF(D9="x",IF(E9<>"x",1,0),0) -> 0 | H9: =IF(E9="x",IF(D9<>"x",1,0),0) -> 0 | I9: =IF(E9="x",0,IF(D9<>"x",1,0)) -> 1 | J9: =IF(E9="x",IF(D9<>"x",0,1),0) -> 0
B10: c | C10: Jika bepergian memperhatikan hasil-hasil tanaman | F10: =IF(D10="x",IF(E10<>"x","Paling Disukai","ERROR"),IF(E10="x","Paling Tidak Disukai","")) | G10: =IF(D10="x",IF(E10<>"x",1,0),0) -> 0 | H10: =IF(E10="x",IF(D10<>"x",1,0),0) -> 0 | I10: =IF(E10="x",0,IF(D10<>"x",1,0)) -> 1 | J10: =IF(E10="x",IF(D10<>"x",0,1),0) -> 0
B11: d | C11: Membacakan pelajaran untuk mahasiswa tuna netra | F11: =IF(D11="x",IF(E11<>"x","Paling Disukai","ERROR"),IF(E11="x","Paling Tidak Disukai","")) | G11: =IF(D11="x",IF(E11<>"x",1,0),0) -> 0 | H11: =IF(E11="x",IF(D11<>"x",1,0),0) -> 0 | I11: =IF(E11="x",0,IF(D11<>"x",1,0)) -> 1 | J11: =IF(E11="x",IF(D11<>"x",0,1),0) -> 0
B12: e | C12: Mencatat kendaraan yang lewat di suatu tempat tertentu | F12: =IF(D12="x",IF(E12<>"x","Paling Disukai","ERROR"),IF(E12="x","Paling Tidak Disukai","")) | G12: =IF(D12="x",IF(E12<>"x",1,0),0) -> 0 | H12: =IF(E12="x",IF(D12<>"x",1,0),0) -> 0 | I12: =IF(E12="x",0,IF(D12<>"x",1,0)) -> 1 | J12: =IF(E12="x",IF(D12<>"x",0,1),0) -> 0
B13: f | C13: Mewawancarai orang-orang untuk lembaga pendapat umum / survey | F13: =IF(D13="x",IF(E13<>"x","Paling Disukai","ERROR"),IF(E13="x","Paling Tidak Disukai","")) | G13: =IF(D13="x",IF(E13<>"x",1,0),0) -> 0 | H13: =IF(E13="x",IF(D13<>"x",1,0),0) -> 0 | I13: =IF(E13="x",0,IF(D13<>"x",1,0)) -> 1 | J13: =IF(E13="x",IF(D13<>"x",0,1),0) -> 0
B14: g | C14: Pergi ke tempat hiburan di mall | F14: =IF(D14="x",IF(E14<>"x","Paling Disukai","ERROR"),IF(E14="x","Paling Tidak Disukai","")) | G14: =IF(D14="x",IF(E14<>"x",1,0),0) -> 0 | H14: =IF(E14="x",IF(D14<>"x",1,0),0) -> 0 | I14: =IF(E14="x",0,IF(D14<>"x",1,0)) -> 1 | J14: =IF(E14="x",IF(D14<>"x",0,1),0) -> 0
B15: h | C15: Melihat pameran bahan makanan dalam kaleng di mall | F15: =IF(D15="x",IF(E15<>"x","Paling Disukai","ERROR"),IF(E15="x","Paling Tidak Disukai","")) | G15: =IF(D15="x",IF(E15<>"x",1,0),0) -> 0 | H15: =IF(E15="x",IF(D15<>"x",1,0),0) -> 0 | I15: =IF(E15="x",0,IF(D15<>"x",1,0)) -> 1 | J15: =IF(E15="x",IF(D15<>"x",0,1),0) -> 0
B16: j | C16: Melihat pameran hewan peliharaan di mall | F16: =IF(D16="x",IF(E16<>"x","Paling Disukai","ERROR"),IF(E16="x","Paling Tidak Disukai","")) | G16: =IF(D16="x",IF(E16<>"x",1,0),0) -> 0 | H16: =IF(E16="x",IF(D16<>"x",1,0),0) -> 0 | I16: =IF(E16="x",0,IF(D16<>"x",1,0)) -> 1 | J16: =IF(E16="x",IF(D16<>"x",0,1),0) -> 0
B17: k | C17: Melatih pendidikan jasmani/olahraga di sekolah | F17: =IF(D17="x",IF(E17<>"x","Paling Disukai","ERROR"),IF(E17="x","Paling Tidak Disukai","")) | G17: =IF(D17="x",IF(E17<>"x",1,0),0) -> 0 | H17: =IF(E17="x",IF(D17<>"x",1,0),0) -> 0 | I17: =IF(E17="x",0,IF(D17<>"x",1,0)) -> 1 | J17: =IF(E17="x",IF(D17<>"x",0,1),0) -> 0
B18: l | C18: Pergi memancing | F18: =IF(D18="x",IF(E18<>"x","Paling Disukai","ERROR"),IF(E18="x","Paling Tidak Disukai","")) | G18: =IF(D18="x",IF(E18<>"x",1,0),0) -> 0 | H18: =IF(E18="x",IF(D18<>"x",1,0),0) -> 0 | I18: =IF(E18="x",0,IF(D18<>"x",1,0)) -> 1 | J18: =IF(E18="x",IF(D18<>"x",0,1),0) -> 0
B19: m | C19: Bermain sepak bola | F19: =IF(D19="x",IF(E19<>"x","Paling Disukai","ERROR"),IF(E19="x","Paling Tidak Disukai","")) | G19: =IF(D19="x",IF(E19<>"x",1,0),0) -> 0 | H19: =IF(E19="x",IF(D19<>"x",1,0),0) -> 0 | I19: =IF(E19="x",0,IF(D19<>"x",1,0)) -> 1 | J19: =IF(E19="x",IF(D19<>"x",0,1),0) -> 0
B20: n | C20: Membaca di perpustakaan | F20: =IF(D20="x",IF(E20<>"x","Paling Disukai","ERROR"),IF(E20="x","Paling Tidak Disukai","")) | G20: =IF(D20="x",IF(E20<>"x",1,0),0) -> 0 | H20: =IF(E20="x",IF(D20<>"x",1,0),0) -> 0 | I20: =IF(E20="x",0,IF(D20<>"x",1,0)) -> 1 | J20: =IF(E20="x",IF(D20<>"x",0,1),0) -> 0
... B49: T | C49: Menggambar pemandangan yang indah | F49: =IF(D49="x",IF(E49<>"x","Paling Disukai","ERROR"),IF(E49="x","Paling Tidak Disukai","")) | G49: =IF(D49="x",IF(E49<>"x",1,0),0) -> 0 | H49: =IF(E49="x",IF(D49<>"x",1,0),0) -> 0 | I49: =IF(E49="x",0,IF(D49<>"x",1,0)) -> 1 | J49: =IF(E49="x",IF(D49<>"x",0,1),0) -> 0
A50: 2 | B50: A | C50: Menonton televisi tentang cara menanam buah-buahan | F50: =IF(D50="x",IF(E50<>"x","Paling Disukai","ERROR"),IF(E50="x","Paling Tidak Disukai","")) | G50: =IF(D50="x",IF(E50<>"x",1,0),0) -> 0 | H50: =IF(E50="x",IF(D50<>"x",1,0),0) -> 0 | I50: =IF(E50="x",0,IF(D50<>"x",1,0)) -> 1 | J50: =IF(E50="x",IF(D50<>"x",0,1),0) -> 0
B51: B | C51: Menonton televisi tentang pembuatan barang-barang plastik | F51: =IF(D51="x",IF(E51<>"x","Paling Disukai","ERROR"),IF(E51="x","Paling Tidak Disukai","")) | G51: =IF(D51="x",IF(E51<>"x",1,0),0) -> 0 | H51: =IF(E51="x",IF(D51<>"x",1,0),0) -> 0 | I51: =IF(E51="x",0,IF(D51<>"x",1,0)) -> 1 | J51: =IF(E51="x",IF(D51<>"x",0,1),0) -> 0
B52: C | C52: Menonton televisi tentang pengambilan foto hewan-hewan liar | F52: =IF(D52="x",IF(E52<>"x","Paling Disukai","ERROR"),IF(E52="x","Paling Tidak Disukai","")) | G52: =IF(D52="x",IF(E52<>"x",1,0),0) -> 0 | H52: =IF(E52="x",IF(D52<>"x",1,0),0) -> 0 | I52: =IF(E52="x",0,IF(D52<>"x",1,0)) -> 1 | J52: =IF(E52="x",IF(D52<>"x",0,1),0) -> 0
B53: D | C53: Menulis di surat kabar/majalah tentang konsultasi masalah pribadi | F53: =IF(D53="x",IF(E53<>"x","Paling Disukai","ERROR"),IF(E53="x","Paling Tidak Disukai","")) | G53: =IF(D53="x",IF(E53<>"x",1,0),0) -> 0 | H53: =IF(E53="x",IF(D53<>"x",1,0),0) -> 0 | I53: =IF(E53="x",0,IF(D53<>"x",1,0)) -> 1 | J53: =IF(E53="x",IF(D53<>"x",0,1),0) -> 0
B54: E | C54: Memelihara anjing yang baik | F54: =IF(D54="x",IF(E54<>"x","Paling Disukai","ERROR"),IF(E54="x","Paling Tidak Disukai","")) | G54: =IF(D54="x",IF(E54<>"x",1,0),0) -> 0 | H54: =IF(E54="x",IF(D54<>"x",1,0),0) -> 0 | I54: =IF(E54="x",0,IF(D54<>"x",1,0)) -> 1 | J54: =IF(E54="x",IF(D54<>"x",0,1),0) -> 0
B55: F | C55: Mencaritahu manfaat dari bermacam-macam surat bisnis | F55: =IF(D55="x",IF(E55<>"x","Paling Disukai","ERROR"),IF(E55="x","Paling Tidak Disukai","")) | G55: =IF(D55="x",IF(E55<>"x",1,0),0) -> 0 | H55: =IF(E55="x",IF(D55<>"x",1,0),0) -> 0 | I55: =IF(E55="x",0,IF(D55<>"x",1,0)) -> 1 | J55: =IF(E55="x",IF(D55<>"x",0,1),0) -> 0
B56: G | C56: Menjadi ahli dalam permainan kartu remi/bridge | F56: =IF(D56="x",IF(E56<>"x","Paling Disukai","ERROR"),IF(E56="x","Paling Tidak Disukai","")) | G56: =IF(D56="x",IF(E56<>"x",1,0),0) -> 0 | H56: =IF(E56="x",IF(D56<>"x",1,0),0) -> 0 | I56: =IF(E56="x",0,IF(D56<>"x",1,0)) -> 1 | J56: =IF(E56="x",IF(D56<>"x",0,1),0) -> 0
B57: H | C57: Menjadi ahli dalam erosi tanah | F57: =IF(D57="x",IF(E57<>"x","Paling Disukai","ERROR"),IF(E57="x","Paling Tidak Disukai","")) | G57: =IF(D57="x",IF(E57<>"x",1,0),0) -> 0 | H57: =IF(E57="x",IF(D57<>"x",1,0),0) -> 0 | I57: =IF(E57="x",0,IF(D57<>"x",1,0)) -> 1 | J57: =IF(E57="x",IF(D57<>"x",0,1),0) -> 0
B58: J | C58: Menjadi ahli dalam poster iklan | F58: =IF(D58="x",IF(E58<>"x","Paling Disukai","ERROR"),IF(E58="x","Paling Tidak Disukai","")) | G58: =IF(D58="x",IF(E58<>"x",1,0),0) -> 0 | H58: =IF(E58="x",IF(D58<>"x",1,0),0) -> 0 | I58: =IF(E58="x",0,IF(D58<>"x",1,0)) -> 1 | J58: =IF(E58="x",IF(D58<>"x",0,1),0) -> 0
B59: K | C59: Mengunjungi studio film | F59: =IF(D59="x",IF(E59<>"x","Paling Disukai","ERROR"),IF(E59="x","Paling Tidak Disukai","")) | G59: =IF(D59="x",IF(E59<>"x",1,0),0) -> 0 | H59: =IF(E59="x",IF(D59<>"x",1,0),0) -> 0 | I59: =IF(E59="x",0,IF(D59<>"x",1,0)) -> 1 | J59: =IF(E59="x",IF(D59<>"x",0,1),0) -> 0
B60: L | C60: Mengunjungi kebun raya yang terkenal pemandangannya | F60: =IF(D60="x",IF(E60<>"x","Paling Disukai","ERROR"),IF(E60="x","Paling Tidak Disukai","")) | G60: =IF(D60="x",IF(E60<>"x",1,0),0) -> 0 | H60: =IF(E60="x",IF(D60<>"x",1,0),0) -> 0 | I60: =IF(E60="x",0,IF(D60<>"x",1,0)) -> 1 | J60: =IF(E60="x",IF(D60<>"x",0,1),0) -> 0
B61: M | C61: Mengunjungi bekas tempat peperangan | F61: =IF(D61="x",IF(E61<>"x","Paling Disukai","ERROR"),IF(E61="x","Paling Tidak Disukai","")) | G61: =IF(D61="x",IF(E61<>"x",1,0),0) -> 0 | H61: =IF(E61="x",IF(D61<>"x",1,0),0) -> 0 | I61: =IF(E61="x",0,IF(D61<>"x",1,0)) -> 1 | J61: =IF(E61="x",IF(D61<>"x",0,1),0) -> 0
B62: N | C62: Membaca biografi orang-orang terkenal | F62: =IF(D62="x",IF(E62<>"x","Paling Disukai","ERROR"),IF(E62="x","Paling Tidak Disukai","")) | G62: =IF(D62="x",IF(E62<>"x",1,0),0) -> 0 | H62: =IF(E62="x",IF(D62<>"x",1,0),0) -> 0 | I62: =IF(E62="x",0,IF(D62<>"x",1,0)) -> 1 | J62: =IF(E62="x",IF(D62<>"x",0,1),0) -> 0
... B91: t | C91: Mengarang pertunjukkan musik komedi | F91: =IF(D91="x",IF(E91<>"x","Paling Disukai","ERROR"),IF(E91="x","Paling Tidak Disukai","")) | G91: =IF(D91="x",IF(E91<>"x",1,0),0) -> 0 | H91: =IF(E91="x",IF(D91<>"x",1,0),0) -> 0 | I91: =IF(E91="x",0,IF(D91<>"x",1,0)) -> 1 | J91: =IF(E91="x",IF(D91<>"x",0,1),0) -> 0
A92: 3 | B92: a | C92: Mengajar bahasa Indonesia | F92: =IF(D92="x",IF(E92<>"x","Paling Disukai","ERROR"),IF(E92="x","Paling Tidak Disukai","")) | G92: =IF(D92="x",IF(E92<>"x",1,0),0) -> 0 | H92: =IF(E92="x",IF(D92<>"x",1,0),0) -> 0 | I92: =IF(E92="x",0,IF(D92<>"x",1,0)) -> 1 | J92: =IF(E92="x",IF(D92<>"x",0,1),0) -> 0
B93: b | C93: Menerima pesanan barang dagangan melalui telepon | F93: =IF(D93="x",IF(E93<>"x","Paling Disukai","ERROR"),IF(E93="x","Paling Tidak Disukai","")) | G93: =IF(D93="x",IF(E93<>"x",1,0),0) -> 0 | H93: =IF(E93="x",IF(D93<>"x",1,0),0) -> 0 | I93: =IF(E93="x",0,IF(D93<>"x",1,0)) -> 1 | J93: =IF(E93="x",IF(D93<>"x",0,1),0) -> 0
B94: c | C94: Menanyakan pendapat orang melalui telepon untuk survey/jajak pendapat | F94: =IF(D94="x",IF(E94<>"x","Paling Disukai","ERROR"),IF(E94="x","Paling Tidak Disukai","")) | G94: =IF(D94="x",IF(E94<>"x",1,0),0) -> 0 | H94: =IF(E94="x",IF(D94<>"x",1,0),0) -> 0 | I94: =IF(E94="x",0,IF(D94<>"x",1,0)) -> 1 | J94: =IF(E94="x",IF(D94<>"x",0,1),0) -> 0
B95: d | C95: Menjadi pembeli barang dagangan yang jual di toko miliki pemerintah | F95: =IF(D95="x",IF(E95<>"x","Paling Disukai","ERROR"),IF(E95="x","Paling Tidak Disukai","")) | G95: =IF(D95="x",IF(E95<>"x",1,0),0) -> 0 | H95: =IF(E95="x",IF(D95<>"x",1,0),0) -> 0 | I95: =IF(E95="x",0,IF(D95<>"x",1,0)) -> 1 | J95: =IF(E95="x",IF(D95<>"x",0,1),0) -> 0
B96: e | C96: Mewawancarai para pelamar pekerjaan pada sebuah toko | F96: =IF(D96="x",IF(E96<>"x","Paling Disukai","ERROR"),IF(E96="x","Paling Tidak Disukai","")) | G96: =IF(D96="x",IF(E96<>"x",1,0),0) -> 0 | H96: =IF(E96="x",IF(D96<>"x",1,0),0) -> 0 | I96: =IF(E96="x",0,IF(D96<>"x",1,0)) -> 1 | J96: =IF(E96="x",IF(D96<>"x",0,1),0) -> 0
B97: f | C97: Menjadi seorang pengembala sapi | F97: =IF(D97="x",IF(E97<>"x","Paling Disukai","ERROR"),IF(E97="x","Paling Tidak Disukai","")) | G97: =IF(D97="x",IF(E97<>"x",1,0),0) -> 0 | H97: =IF(E97="x",IF(D97<>"x",1,0),0) -> 0 | I97: =IF(E97="x",0,IF(D97<>"x",1,0)) -> 1 | J97: =IF(E97="x",IF(D97<>"x",0,1),0) -> 0
B98: g | C98: Bertugas mencari pegawai untuk suatu perusahaan | F98: =IF(D98="x",IF(E98<>"x","Paling Disukai","ERROR"),IF(E98="x","Paling Tidak Disukai","")) | G98: =IF(D98="x",IF(E98<>"x",1,0),0) -> 0 | H98: =IF(E98="x",IF(D98<>"x",1,0),0) -> 0 | I98: =IF(E98="x",0,IF(D98<>"x",1,0)) -> 1 | J98: =IF(E98="x",IF(D98<>"x",0,1),0) -> 0
B99: h | C99: Menulis cerita tentang hewan-hewan buas | F99: =IF(D99="x",IF(E99<>"x","Paling Disukai","ERROR"),IF(E99="x","Paling Tidak Disukai","")) | G99: =IF(D99="x",IF(E99<>"x",1,0),0) -> 0 | H99: =IF(E99="x",IF(D99<>"x",1,0),0) -> 0 | I99: =IF(E99="x",0,IF(D99<>"x",1,0)) -> 1 | J99: =IF(E99="x",IF(D99<>"x",0,1),0) -> 0
B100: j | C100: Menulis satu kolom dalam sebuah surat kabar/majalah mengenai konsultasi pribadi | F100: =IF(D100="x",IF(E100<>"x","Paling Disukai","ERROR"),IF(E100="x","Paling Tidak Disukai","")) | G100: =IF(D100="x",IF(E100<>"x",1,0),0) -> 0 | H100: =IF(E100="x",IF(D100<>"x",1,0),0) -> 0 | I100: =IF(E100="x",0,IF(D100<>"x",1,0)) -> 1 | J100: =IF(E100="x",IF(D100<>"x",0,1),0) -> 0
...

Sheet Hasil
B2: Nama | D2: :
B3: Usia | D3: : | O3: T skor untuk skala klinis dan validitas Kuder
B4: Jenis Kelamin | D4: :
P5: Laki-laki | AA5: Perempuan
B6: Minat | C6: Raw Skor | D6: T Score | E6: Kategori | N6: =Test!L7 -> 1 | O6: RS | P6: Out | Q6: Me | R6: Com | S6: Sci | T6: Per | U6: Art | V6: Lit | W6: Mus | X6: S.S | Y6: Cler | Z6: Skor | AA6: Out | AB6: Me | AC6: Com | AD6: Sci | AE6: Per | AF6: Art | AG6: Lit | AH6: Mus | AI6: S.S | AJ6: Cler
A7: V | B7: Verification | C7: =+Test!G9+Test!H10+Test!G14+Test!H15+Test!G71+Test!H72+Test!G73+Test!H104+Test!G106+Test!H122+Test!G123+Test!G124+Test!H155+Test!G156+Test!G157+Test!H186+Test!H187+Test!H188+Test!G189+Test!G190+Test!G212+Test!G214+Test!H221+Test!H222+Test!G223+Test!H263+Test!H265+Test!G287+Test!G289+Test!H317+Test!H318+Test!G319+Test!G335+Test!H336+Test!H337+Test!G356+Test!H357+Test!H358+Test!G365+Test!G366+Test!H367+Test!H377+Test!H378+Test!G379+Test!G386+Test!G387+Test!G431+Test!H432+Test!H440+Test!G441+Test!H449+Test!G450+Test!G451+Test!H465+Test!G466+Test!G476+Test!G477+Test!G491+Test!H492+Test!G493+Test!G503+Test!H504+Test!H505 -> 0 | D7: =C7 -> 0 | E7: =IF(D7<=37,"Kurang valid dikarenakan testee kurang bersungguh-sungguh, atau karena jawaban testee kurang konsisten.",IF(D7<=44,"Valid","Kurang valid dikarenakan testee tidak mengerti atau tidak mengikuti petunjuk tes yang berlaku.")) -> Kurang valid dikarenakan testee kurang bersungguh-sungguh, atau karena jawaban testee kurang konsisten. | O7: 0 | P7: 0 | Q7: 0 | R7: 0 | S7: 0 | T7: 0 | U7: 0 | V7: 0 | W7: 0 | X7: 0 | Y7: 0 | Z7: 0 | AA7: 0 | AB7: 0 | AC7: 0 | AD7: 0 | AE7: 0 | AF7: 0 | AG7: 0 | AH7: 0 | AI7: 0 | AJ7: 0
A8: 0 | B8: Outdoor | C8: =+Test!H8+Test!G9+Test!G10+Test!H14+Test!H15+Test!G16+Test!H17+Test!G18+Test!H19+Test!H23+Test!G24+Test!G25+Test!H29+Test!H30+Test!G31+Test!G50+Test!H51+Test!G52+Test!H53+Test!G54+Test!H55+Test!H56+Test!G57+Test!H58+Test!H59+Test!G60+Test!G61+Test!H62+Test!H63+Test!G64+Test!H65+Test!G66+Test!H67+Test!H95+Test!H96+Test!G97+Test!H98+Test!G99+Test!H100+Test!H101+Test!G102+Test!G103+Test!G104+Test!H105+Test!G106+Test!H137+Test!G138+Test!H139+Test!H149+Test!H150+Test!G151+Test!H164+Test!H165+Test!G166+Test!H185+Test!H186+Test!G187+Test!H191+Test!G192+Test!G193+Test!G222+Test!H227+Test!H228+Test!G229+Test!G230+Test!H231+Test!H232+Test!G233+Test!G234+Test!H235+Test!H260+Test!G261+Test!H262+Test!G263+Test!G264+Test!H265+Test!H269+Test!G270+Test!H271+Test!H302+Test!H303+Test!G304+Test!H320+Test!G321+Test!G322+Test!H347+Test!H386+Test!G387+Test!H388+Test!H398+Test!H399+Test!G400+Test!H404+Test!G405+Test!G406+Test!H428+Test!G429+Test!G430+Test!H431+Test!H432+Test!G433+Test!G434+Test!H435+Test!H436+Test!H437+Test!H438+Test!G439+Test!H473+Test!H474+Test!G475+Test!H476+Test!G477+Test!H478+Test!H479+Test!G480+Test!H481+Test!G482+Test!H483+Test!H484+Test!H488+Test!G489+Test!H490 -> 0 | D8: =IF($N$6=1,VLOOKUP(C8,$O$7:$Y$106,2),IF($N$6=2,VLOOKUP(C8,$Z$7:$AJ$106,2))) -> 0 | E8: =IF(D8<=24%,"Rendah",IF(D8<=74%,"Cukup",IF(D8<=100%,"Tinggi"))) -> Rendah | O8: 1 | P8: 0 | Q8: 0 | R8: 0 | S8: 0 | T8: 0 | U8: 0 | V8: 0 | W8: 0.01 | X8: 0 | Y8: 0 | Z8: 1 | AA8: 0 | AB8: 0 | AC8: 0 | AD8: 0 | AE8: 0 | AF8: 0 | AG8: 0 | AH8: 0 | AI8: 0 | AJ8: 0
A9: 1 | B9: Mechanical | C9: =+Test!H35+Test!H36+Test!G37+Test!H38+Test!H39+Test!G40+Test!H41+Test!H42+Test!G43+Test!G47+Test!H48+Test!H49+Test!H173+Test!G174+Test!H175+Test!H203+Test!H204+Test!G205+Test!H209+Test!G210+Test!H211+Test!G215+Test!H216+Test!H217+Test!H239+Test!G240+Test!H241+Test!G242+Test!H243+Test!H244+Test!G245+Test!H246+Test!H247+Test!G251+Test!H252+Test!H253+Test!H254+Test!G255+Test!H256+Test!G257+Test!H258+Test!H259+Test!H281+Test!H282+Test!G283+Test!H290+Test!H291+Test!G292+Test!H293+Test!G294+Test!H295+Test!H299+Test!H300+Test!G301+Test!G326+Test!H327+Test!H328+Test!H332+Test!H333+Test!G334+Test!H341+Test!G342+Test!H343+Test!G368+Test!H369+Test!H370+Test!G374+Test!H375+Test!H376+Test!H380+Test!G381+Test!H382+Test!H410+Test!H411+Test!G412+Test!H414+Test!G415+Test!H416+Test!G417+Test!H418+Test!H455+Test!G456+Test!H457+Test!G464+Test!H465+Test!H466+Test!G467+Test!H468+Test!H469+Test!H497+Test!H498+Test!G499+Test!G506+Test!H507+Test!H508+Test!G509+Test!H510+Test!H511 -> 0 | D9: =IF($N$6=1,VLOOKUP(C9,$O$7:$Y$106,3),IF($N$6=2,VLOOKUP(C9,$Z$7:$AJ$106,3))) -> 0 | E9: =IF(D9<=24%,"Rendah",IF(D9<=74%,"Cukup",IF(D9<=100%,"Tinggi"))) -> Rendah | O9: 2 | P9: 0 | Q9: 0 | R9: 0 | S9: 0 | T9: 0 | U9: 0 | V9: 0 | W9: 0.03 | X9: 0 | Y9: 0 | Z9: 2 | AA9: 0 | AB9: 0 | AC9: 0 | AD9: 0 | AE9: 0 | AF9: 0 | AG9: 0 | AH9: 0.01 | AI9: 0 | AJ9: 0
A10: 2 | B10: Computational | C10: =+Test!H11+Test!G12+Test!H13+Test!H176+Test!H177+Test!G178+Test!G179+Test!H180+Test!H181+Test!G182+Test!H183+Test!H184+Test!H224+Test!G225+Test!H226+Test!G239+Test!H240+Test!H241+Test!H245+Test!G246+Test!G247+Test!G260+Test!H261+Test!H262+Test!H281+Test!G282+Test!H283+Test!G302+Test!H303+Test!H304+Test!G308+Test!H309+Test!H310+Test!H323+Test!H324+Test!G325+Test!H326+Test!G327+Test!H328+Test!H329+Test!G330+Test!H331+Test!H332+Test!H333+Test!G334+Test!G347+Test!H348+Test!H349+Test!H350+Test!G351+Test!H352+Test!H368+Test!G369+Test!H370+Test!H371+Test!G372+Test!H373+Test!H374+Test!H375+Test!G376+Test!G392+Test!H393+Test!H394+Test!H410+Test!G411+Test!H412+Test!H416+Test!H417+Test!G418+Test!G443+Test!H444+Test!H445+Test!H455+Test!H456+Test!G457+Test!G488+Test!H489+Test!H490+Test!G497+Test!H498+Test!H499 -> 0 | D10: =IF($N$6=1,VLOOKUP(C10,$O$7:$Y$106,4),IF($N$6=2,VLOOKUP(C10,$Z$7:$AJ$106,4))) -> 0 | E10: =IF(D10<=24%,"Rendah",IF(D10<=74%,"Cukup",IF(D10<=100%,"Tinggi"))) -> Rendah | O10: 3 | P10: 0 | Q10: 0 | R10: 0 | S10: 0 | T10: 0 | U10: 0 | V10: 0 | W10: 0.05 | X10: 0 | Y10: 0 | Z10: 3 | AA10: 0 | AB10: 0 | AC10: 0 | AD10: 0 | AE10: 0 | AF10: 0 | AG10: 0 | AH10: 0.02 | AI10: 0 | AJ10: 0
A11: 3 | B11: Scientific | C11: =+Test!H26+Test!H27+Test!G28+Test!G35+Test!H36+Test!H37+Test!H41+Test!G42+Test!H43+Test!H65+Test!G66+Test!H67+Test!H68+Test!H69+Test!G70+Test!H83+Test!G84+Test!H85+Test!G86+Test!H87+Test!H88+Test!H89+Test!G90+Test!H91+Test!H108+Test!H109+Test!H110+Test!G111+Test!H112+Test!H116+Test!G117+Test!H118+Test!H119+Test!H120+Test!G121+Test!H125+Test!G126+Test!H127+Test!H128+Test!H129+Test!G130+Test!G131+Test!G132+Test!H133+Test!H152+Test!G153+Test!H154+Test!H158+Test!G159+Test!H160+Test!G167+Test!H168+Test!H169+Test!G170+Test!H171+Test!H172+Test!H173+Test!G174+Test!H175+Test!H191+Test!H192+Test!G193+Test!G194+Test!H195+Test!H196+Test!H200+Test!G201+Test!H202+Test!H206+Test!H207+Test!G208+Test!H209+Test!H210+Test!G211+Test!H212+Test!H213+Test!G214+Test!H230+Test!H231+Test!G232+Test!H233+Test!H234+Test!G235+Test!H236+Test!G237+Test!H238+Test!G278+Test!H279+Test!H280+Test!G296+Test!G297+Test!H298+Test!H299+Test!G300+Test!H301+Test!G380+Test!G381+Test!H382+Test!G383+Test!H384+Test!H385+Test!H506+Test!H507+Test!G508 -> 0 | D11: =IF($N$6=1,VLOOKUP(C11,$O$7:$Y$106,5),IF($N$6=2,VLOOKUP(C11,$Z$7:$AJ$106,5))) -> 0 | E11: =IF(D11<=24%,"Rendah",IF(D11<=74%,"Cukup",IF(D11<=100%,"Tinggi"))) -> Rendah | O11: 4 | P11: 0 | Q11: 0 | R11: 0 | S11: 0 | T11: 0 | U11: 0 | V11: 0.01 | W11: 0.08 | X11: 0 | Y11: 0 | Z11: 4 | AA11: 0 | AB11: 0.01 | AC11: 0.01 | AD11: 0 | AE11: 0 | AF11: 0 | AG11: 0.01 | AH11: 0.04 | AI11: 0 | AJ11: 0
A12: 4 | B12: Persuasive | C12: =+Test!H11+Test!H12+Test!G13+Test!G29+Test!H30+Test!H31+Test!H35+Test!G36+Test!H37+Test!H56+Test!H57+Test!G58+Test!H74+Test!G75+Test!H76+Test!H77+Test!G78+Test!H79+Test!G80+Test!H81+Test!H82+Test!H92+Test!H93+Test!G94+Test!G134+Test!H135+Test!H136+Test!G140+Test!H141+Test!H142+Test!G149+Test!H150+Test!H151+Test!G158+Test!H159+Test!H160+Test!H161+Test!G162+Test!H163+Test!H164+Test!G165+Test!H166+Test!G176+Test!H177+Test!H178+Test!H179+Test!G180+Test!H181+Test!H185+Test!G186+Test!H187+Test!G191+Test!H192+Test!H193+Test!H194+Test!H195+Test!G196+Test!H206+Test!G207+Test!H208+Test!G224+Test!H225+Test!G226+Test!H239+Test!H240+Test!G241+Test!H242+Test!G243+Test!H244+Test!G245+Test!H246+Test!H247+Test!H266+Test!H267+Test!G268+Test!H275+Test!G276+Test!G277+Test!H290+Test!G291+Test!H292+Test!G305+Test!H306+Test!H307+Test!H308+Test!G309+Test!H310+Test!H311+Test!H312+Test!G313+Test!H314+Test!G315+Test!H316+Test!H344+Test!G345+Test!G346+Test!H347+Test!H348+Test!G349+Test!H350+Test!H351+Test!G352+Test!H353+Test!G354+Test!H355+Test!G389+Test!H390+Test!G391+Test!H392+Test!G393+Test!H394+Test!G403+Test!H434+Test!H435+Test!G436+Test!G437+Test!H438+Test!H439+Test!H470+Test!H471+Test!G472+Test!H476+Test!H477+Test!G478+Test!G487 -> 0 | D12: =IF($N$6=1,VLOOKUP(C12,$O$7:$Y$106,6),IF($N$6=2,VLOOKUP(C12,$Z$7:$AJ$106,6))) -> 0 | E12: =IF(D12<=24%,"Rendah",IF(D12<=74%,"Cukup",IF(D12<=100%,"Tinggi"))) -> Rendah | O12: 5 | P12: 0 | Q12: 0 | R12: 0 | S12: 0 | T12: 0 | U12: 0.01 | V12: 0.02 | W12: 0.11 | X12: 0 | Y12: 0 | Z12: 5 | AA12: 0 | AB12: 0.01 | AC12: 0.01 | AD12: 0 | AE12: 0 | AF12: 0.01 | AG12: 0.01 | AH12: 0.06 | AI12: 0 | AJ12: 0
A13: 5 | B13: Artistic | C13: =+Test!G41+Test!H42+Test!H43+Test!H44+Test!H45+Test!G46+Test!H47+Test!H48+Test!G49+Test!H80+Test!H81+Test!G82+Test!G83+Test!H84+Test!H85+Test!G164+Test!H165+Test!H166+Test!H167+Test!H168+Test!G169+Test!G173+Test!H174+Test!H175+Test!G206+Test!H207+Test!H208+Test!G275+Test!H276+Test!H277+Test!H278+Test!G279+Test!H280+Test!G290+Test!H291+Test!H292+Test!G299+Test!H300+Test!H301+Test!H323+Test!G324+Test!H325+Test!G329+Test!H330+Test!H331+Test!H338+Test!G339+Test!H340+Test!H359+Test!H360+Test!G361+Test!H362+Test!G363+Test!G364+Test!H371+Test!H372+Test!G373+Test!H380+Test!H381+Test!G382+Test!G401+Test!H402+Test!H403+Test!H446+Test!H447+Test!G448+Test!H485+Test!H486+Test!G487+Test!H494+Test!G495+Test!H496+Test!H500+Test!G501+Test!H502+Test!H506+Test!G507+Test!H508 -> 0 | D13: =IF($N$6=1,VLOOKUP(C13,$O$7:$Y$106,7),IF($N$6=2,VLOOKUP(C13,$Z$7:$AJ$106,7))) -> 0 | E13: =IF(D13<=24%,"Rendah",IF(D13<=74%,"Cukup",IF(D13<=100%,"Tinggi"))) -> Rendah | O13: 6 | P13: 0 | Q13: 0 | R13: 0 | S13: 0 | T13: 0 | U13: 0.01 | V13: 0.03 | W13: 0.15 | X13: 0 | Y13: 0 | Z13: 6 | AA13: 0 | AB13: 0.02 | AC13: 0.02 | AD13: 0 | AE13: 0.01 | AF13: 0.01 | AG13: 0.02 | AH13: 0.09 | AI13: 0 | AJ13: 0
A14: 6 | B14: Literacy | C14: =+Test!G20+Test!H21+Test!H22+Test!G92+Test!H93+Test!H94+Test!H107+Test!H108+Test!G109+Test!H140+Test!G141+Test!H142+Test!H143+Test!H144+Test!G145+Test!G146+Test!H147+Test!H148+Test!G152+Test!H153+Test!H154+Test!H182+Test!G183+Test!H184+Test!H218+Test!H219+Test!G220+Test!H236+Test!H237+Test!G238+Test!H275+Test!G276+Test!H277+Test!H278+Test!H279+Test!G280+Test!G347+Test!H348+Test!H349+Test!G353+Test!H354+Test!H355+Test!H359+Test!G360+Test!H361+Test!H362+Test!H363+Test!G364+Test!G395+Test!H396+Test!H397+Test!H401+Test!G402+Test!H403+Test!H437+Test!G438+Test!H439+Test!H446+Test!G447+Test!H448+Test!H485+Test!G486+Test!H487 -> 0 | D14: =IF($N$6=1,VLOOKUP(C14,$O$7:$Y$106,8),IF($N$6=2,VLOOKUP(C14,$Z$7:$AJ$106,8))) -> 0 | E14: =IF(D14<=24%,"Rendah",IF(D14<=74%,"Cukup",IF(D14<=100%,"Tinggi"))) -> Rendah | O14: 7 | P14: 0 | Q14: 0 | R14: 0 | S14: 0 | T14: 0 | U14: 0.01 | V14: 0.05 | W14: 0.2 | X14: 0 | Y14: 0 | Z14: 7 | AA14: 0 | AB14: 0.03 | AC14: 0.03 | AD14: 0 | AE14: 0.01 | AF14: 0.01 | AG14: 0.03 | AH14: 0.13 | AI14: 0 | AJ14: 0
A15: 7 | B15: Musical | C15: =+Test!H29+Test!G30+Test!H31+Test!H47+Test!G48+Test!H49+Test!H86+Test!H87+Test!G88+Test!H89+Test!H90+Test!G91+Test!H128+Test!G129+Test!H130+Test!H200+Test!H201+Test!G202+Test!H203+Test!G204+Test!H205+Test!H242+Test!H243+Test!G244+Test!G254+Test!H255+Test!H256+Test!G338+Test!H339+Test!H340+Test!H383+Test!G384+Test!H385+Test!H422+Test!G423+Test!H424+Test!G452+Test!H453+Test!H454+Test!H458+Test!H459+Test!G460+Test!H500+Test!H501+Test!G502 -> 0 | D15: =IF($N$6=1,VLOOKUP(C15,$O$7:$Y$106,9),IF($N$6=2,VLOOKUP(C15,$Z$7:$AJ$106,9))) -> 0 | E15: =IF(D15<=24%,"Rendah",IF(D15<=74%,"Cukup",IF(D15<=100%,"Tinggi"))) -> Rendah | O15: 8 | P15: 0 | Q15: 0 | R15: 0.01 | S15: 0 | T15: 0 | U15: 0.02 | V15: 0.07 | W15: 0.28 | X15: 0 | Y15: 0 | Z15: 8 | AA15: 0 | AB15: 0.04 | AC15: 0.04 | AD15: 0 | AE15: 0.01 | AF15: 0.02 | AG15: 0.04 | AH15: 0.16 | AI15: 0.01 | AJ15: 0
A16: 8 | B16: Social Service | C16: =+Test!G11+Test!H12+Test!H13+Test!G68+Test!H69+Test!H70+Test!G74+Test!H75+Test!H76+Test!H107+Test!G108+Test!H109+Test!G113+Test!H114+Test!H115+Test!H116+Test!H117+Test!G118+Test!H122+Test!G123+Test!H124+Test!H152+Test!H153+Test!G154+Test!H158+Test!H159+Test!G160+Test!H167+Test!G168+Test!H169+Test!H179+Test!H180+Test!G181+Test!H182+Test!H183+Test!G184+Test!G185+Test!H186+Test!H187+Test!G203+Test!H204+Test!H205+Test!G212+Test!H213+Test!H214+Test!H242+Test!G243+Test!H244+Test!H248+Test!G249+Test!H250+Test!H254+Test!H255+Test!G256+Test!H260+Test!H261+Test!G262+Test!G266+Test!H267+Test!H268+Test!G278+Test!H279+Test!H280+Test!H296+Test!G297+Test!G298+Test!G302+Test!H304+Test!G323+Test!H324+Test!H325+Test!H326+Test!H327+Test!G328+Test!G344+Test!H345+Test!H346+Test!G350+Test!H351+Test!H352+Test!H353+Test!H354+Test!G355+Test!G359+Test!H360+Test!H361+Test!H362+Test!G363+Test!H364+Test!G383+Test!H384+Test!H385+Test!H407+Test!G408+Test!H409+Test!H413+Test!G414+Test!H415+Test!H422+Test!H423+Test!G424+Test!H425+Test!H426+Test!G427+Test!H452+Test!H453+Test!G454+Test!H461+Test!H462+Test!G463+Test!H494+Test!H495+Test!G496+Test!H509+Test!G510+Test!H511 -> 0 | D16: =IF($N$6=1,VLOOKUP(C16,$O$7:$Y$106,10),IF($N$6=2,VLOOKUP(C16,$Z$7:$AJ$106,10))) -> 0 | E16: =IF(D16<=24%,"Rendah",IF(D16<=74%,"Cukup",IF(D16<=100%,"Tinggi"))) -> Rendah | O16: 9 | P16: 0 | Q16: 0 | R16: 0.01 | S16: 0 | T16: 0 | U16: 0.04 | V16: 0.1 | W16: 0.36 | X16: 0 | Y16: 0 | Z16: 9 | AA16: 0.01 | AB16: 0.05 | AC16: 0.05 | AD16: 0 | AE16: 0.01 | AF16: 0.03 | AG16: 0.06 | AH16: 0.19 | AI16: 0.01 | AJ16: 0
A17: 9 | B17: Clerical | C17: =+Test!H32+Test!H33+Test!G34+Test!H65+Test!H66+Test!G67+Test!H77+Test!H78+Test!G79+Test!H86+Test!G87+Test!H88+Test!H92+Test!G93+Test!H94+Test!H113+Test!H114+Test!G115+Test!G116+Test!H117+Test!H118+Test!H125+Test!H126+Test!G127+Test!H131+Test!H132+Test!G133+Test!H140+Test!H141+Test!G142+Test!H143+Test!G144+Test!H145+Test!H149+Test!G150+Test!H151+Test!G158+Test!H159+Test!H160+Test!H161+Test!H162+Test!G163+Test!H170+Test!G171+Test!H172+Test!G182+Test!H183+Test!H184+Test!G197+Test!H198+Test!H199+Test!G209+Test!H210+Test!H211+Test!H218+Test!G219+Test!H220+Test!G239+Test!H240+Test!H241+Test!G248+Test!H249+Test!H250+Test!H251+Test!H252+Test!G253+Test!G260+Test!H261+Test!H262+Test!H266+Test!G267+Test!H268+Test!H272+Test!G273+Test!H274+Test!H284+Test!G285+Test!H286+Test!G287+Test!H288+Test!H289+Test!H302+Test!G303+Test!H304+Test!G305+Test!H306+Test!G307+Test!G311+Test!H312+Test!H313+Test!H344+Test!H345+Test!G346+Test!G362+Test!H363+Test!H364+Test!H368+Test!H369+Test!G370+Test!H374+Test!G375+Test!G376+Test!H383+Test!H384+Test!G385+Test!H395+Test!G396+Test!G397+Test!G413+Test!H414+Test!H415+Test!H419+Test!G420+Test!H421+Test!G422+Test!H423+Test!H424+Test!H443+Test!H444+Test!G445+Test!H452+Test!G453+Test!H454+Test!H455+Test!G456+Test!G457+Test!G461+Test!H462+Test!H463+Test!H467+Test!G468+Test!H469+Test!G470+Test!G471+Test!H472+Test!G476+Test!H477+Test!H478+Test!H482+Test!H483+Test!G484+Test!G485+Test!H486+Test!H487+Test!G488+Test!H489+Test!G490+Test!H491+Test!H492+Test!G493+Test!H509+Test!H510+Test!G511 -> 0 | D17: =IF($N$6=1,VLOOKUP(C17,$O$7:$Y$106,11),IF($N$6=2,VLOOKUP(C17,$Z$7:$AJ$106,11))) -> 0 | E17: =IF(D17<=24%,"Rendah",IF(D17<=74%,"Cukup",IF(D17<=100%,"Tinggi"))) -> Rendah | O17: 10 | P17: 0.01 | Q17: 0 | R17: 0.01 | S17: 0 | T17: 0.01 | U17: 0.05 | V17: 0.13 | W17: 0.42 | X17: 0.01 | Y17: 0 | Z17: 10 | AA17: 0.01 | AB17: 0.06 | AC17: 0.06 | AD17: 0.01 | AE17: 0.02 | AF17: 0.04 | AG17: 0.08 | AH17: 0.25 | AI17: 0.01 | AJ17: 0
O18: 11 | P18: 0.01 | Q18: 0.01 | R18: 0.01 | S18: 0 | T18: 0.01 | U18: 0.07 | V18: 0.16 | W18: 0.49 | X18: 0.01 | Y18: 0 | Z18: 11 | AA18: 0.02 | AB18: 0.07 | AC18: 0.09 | AD18: 0.01 | AE18: 0.02 | AF18: 0.05 | AG18: 0.1 | AH18: 0.3 | AI18: 0.01 | AJ18: 0
O19: 12 | P19: 0.01 | Q19: 0.01 | R19: 0.02 | S19: 0 | T19: 0.01 | U19: 0.1 | V19: 0.19 | W19: 0.54 | X19: 0.01 | Y19: 0 | Z19: 12 | AA19: 0.02 | AB19: 0.1 | AC19: 0.11 | AD19: 0.01 | AE19: 0.02 | AF19: 0.06 | AG19: 0.13 | AH19: 0.35 | AI19: 0.01 | AJ19: 0
O20: 13 | P20: 0.01 | Q20: 0.01 | R20: 0.03 | S20: 0 | T20: 0.01 | U20: 0.12 | V20: 0.23 | W20: 0.59 | X20: 0.01 | Y20: 0 | Z20: 13 | AA20: 0.03 | AB20: 0.12 | AC20: 0.14 | AD20: 0.01 | AE20: 0.02 | AF20: 0.08 | AG20: 0.18 | AH20: 0.4 | AI20: 0.01 | AJ20: 0
O21: 14 | P21: 0.01 | Q21: 0.02 | R21: 0.05 | S21: 0.01 | T21: 0.01 | U21: 0.15 | V21: 0.27 | W21: 0.65 | X21: 0.01 | Y21: 0 | Z21: 14 | AA21: 0.04 | AB21: 0.14 | AC21: 0.17 | AD21: 0.02 | AE21: 0.03 | AF21: 0.1 | AG21: 0.2 | AH21: 0.48 | AI21: 0.01 | AJ21: 0
O22: 15 | P22: 0.02 | Q22: 0.02 | R22: 0.07 | S22: 0.01 | T22: 0.02 | U22: 0.2 | V22: 0.35 | W22: 0.7 | X22: 0.01 | Y22: 0 | Z22: 15 | AA22: 0.06 | AB22: 0.17 | AC22: 0.19 | AD22: 0.03 | AE22: 0.04 | AF22: 0.12 | AG22: 0.25 | AH22: 0.51 | AI22: 0.01 | AJ22: 0
O23: 16 | P23: 0.02 | Q23: 0.03 | R23: 0.08 | S23: 0.01 | T23: 0.03 | U23: 0.24 | V23: 0.37 | W23: 0.73 | X23: 0.01 | Y23: 0 | Z23: 16 | AA23: 0.08 | AB23: 0.19 | AC23: 0.23 | AD23: 0.04 | AE23: 0.04 | AF23: 0.15 | AG23: 0.3 | AH23: 0.57 | AI23: 0.01 | AJ23: 0.01
O24: 17 | P24: 0.03 | Q24: 0.04 | R24: 0.1 | S24: 0.01 | T24: 0.04 | U24: 0.29 | V24: 0.4 | W24: 0.76 | X24: 0.02 | Y24: 0.01 | Z24: 17 | AA24: 0.1 | AB24: 0.21 | AC24: 0.26 | AD24: 0.06 | AE24: 0.05 | AF24: 0.18 | AG24: 0.35 | AH24: 0.63 | AI24: 0.01 | AJ24: 0.01
O25: 18 | P25: 0.04 | Q25: 0.05 | R25: 0.13 | S25: 0.01 | T25: 0.04 | U25: 0.32 | V25: 0.47 | W25: 0.8 | X25: 0.03 | Y25: 0.01 | Z25: 18 | AA25: 0.12 | AB25: 0.24 | AC25: 0.3 | AD25: 0.08 | AE25: 0.06 | AF25: 0.21 | AG25: 0.38 | AH25: 0.68 | AI25: 0.01 | AJ25: 0.01
O26: 19 | P26: 0.05 | Q26: 0.05 | R26: 0.15 | S26: 0.02 | T26: 0.05 | U26: 0.39 | V26: 0.5 | W26: 0.84 | X26: 0.03 | Y26: 0.01 | Z26: 19 | AA26: 0.14 | AB26: 0.27 | AC26: 0.36 | AD26: 0.09 | AE26: 0.08 | AF26: 0.25 | AG26: 0.44 | AH26: 0.73 | AI26: 0.02 | AJ26: 0.01
O27: 20 | P27: 0.06 | Q27: 0.06 | R27: 0.18 | S27: 0.03 | T27: 0.06 | U27: 0.42 | V27: 0.54 | W27: 0.86 | X27: 0.04 | Y27: 0.01 | Z27: 20 | AA27: 0.16 | AB27: 0.32 | AC27: 0.39 | AD27: 0.11 | AE27: 0.09 | AF27: 0.28 | AG27: 0.49 | AH27: 0.77 | AI27: 0.02 | AJ27: 0.01
O28: 21 | P28: 0.07 | Q28: 0.07 | R28: 0.21 | S28: 0.03 | T28: 0.07 | U28: 0.46 | V28: 0.58 | W28: 0.88 | X28: 0.05 | Y28: 0.01 | Z28: 21 | AA28: 0.18 | AB28: 0.35 | AC28: 0.43 | AD28: 0.13 | AE28: 0.1 | AF28: 0.32 | AG28: 0.51 | AH28: 0.81 | AI28: 0.02 | AJ28: 0.01
O29: 22 | P29: 0.08 | Q29: 0.07 | R29: 0.24 | S29: 0.04 | T29: 0.08 | U29: 0.51 | V29: 0.6 | W29: 0.91 | X29: 0.06 | Y29: 0.02 | Z29: 22 | AA29: 0.2 | AB29: 0.38 | AC29: 0.48 | AD29: 0.14 | AE29: 0.13 | AF29: 0.36 | AG29: 0.56 | AH29: 0.85 | AI29: 0.03 | AJ29: 0.01
... O106: 99 | P106: 1 | Q106: 1 | R106: 1 | S106: 1 | T106: 1 | U106: 1 | V106: 1 | W106: 1 | X106: 1 | Y106: 1 | Z106: 99 | AA106: 1 | AB106: 1 | AC106: 1 | AD106: 1 | AE106: 1 | AF106: 1 | AG106: 1 | AH106: 1 | AI106: 1 | AJ106: 1
