Workbook

Sheet Soal
C1: HOLLAND TEST (RIASEC)
D3: Nama | E3: :
D4: Jenis Kelamin | E4: : | F4: Laki-laki | H4: Laki-laki
D5: Tanggal Lahir | E5: : | H5: Perempuan
D6: Pendidikan | E6: :
C7: Bacalah setiap pernyataan di bawah ini. Jika Anda setuju dengan pernyataan tersebut, silakan berikan tanda silang "x" dikolom yang tersedia. Tidak ada jawaban yang benar atau salah.
A9: CODE | C9: NO | D9: SOAL | G9: YA | H9: TIDAK | J9: R | K9: I | L9: A | M9: S | N9: E | O9: C
A10: A8 | C10: 1 | D10: Senang menonton drama | J10: =IF(AND(LEFT($A10,1)="R",$G10="x"),1,0) -> 0 | K10: =IF(AND(LEFT($A10,1)="I",$G10="x"),1,0) -> 0 | L10: =IF(AND(LEFT($A10,1)="A",$G10="x"),1,0) -> 0 | M10: =IF(AND(LEFT($A10,1)="S",$G10="x"),1,0) -> 0 | N10: =IF(AND(LEFT($A10,1)="E",$G10="x"),1,0) -> 0 | O10: =IF(AND(LEFT($A10,1)="C",$G10="x"),1,0) -> 0 | P10: =IF(COUNTA(G10:H10)=2,"Pilih Satu Jawaban","") | Q10: =IF(COUNTA(G10)>0,IF(G10="x","","Isi dengan x"),"")
A11: S5 | C11: 2 | D11: Senang Melatih Orang | J11: =IF(AND(LEFT($A11,1)="R",$G11="x"),1,0) -> 0 | K11: =IF(AND(LEFT($A11,1)="I",$G11="x"),1,0) -> 0 | L11: =IF(AND(LEFT($A11,1)="A",$G11="x"),1,0) -> 0 | M11: =IF(AND(LEFT($A11,1)="S",$G11="x"),1,0) -> 0 | N11: =IF(AND(LEFT($A11,1)="E",$G11="x"),1,0) -> 0 | O11: =IF(AND(LEFT($A11,1)="C",$G11="x"),1,0) -> 0 | P11: =IF(COUNTA(G11:H11)=2,"Pilih Satu Jawaban","") | Q11: =IF(COUNTA(G11)>0,IF(G11="x","","Isi dengan x"),"")
A12: A11 | C12: 3 | D12: Mampu bermain dalam drama / berakting | J12: =IF(AND(LEFT($A12,1)="R",$G12="x"),1,0) -> 0 | K12: =IF(AND(LEFT($A12,1)="I",$G12="x"),1,0) -> 0 | L12: =IF(AND(LEFT($A12,1)="A",$G12="x"),1,0) -> 0 | M12: =IF(AND(LEFT($A12,1)="S",$G12="x"),1,0) -> 0 | N12: =IF(AND(LEFT($A12,1)="E",$G12="x"),1,0) -> 0 | O12: =IF(AND(LEFT($A12,1)="C",$G12="x"),1,0) -> 0 | P12: =IF(COUNTA(G12:H12)=2,"Pilih Satu Jawaban","") | Q12: =IF(COUNTA(G12)>0,IF(G12="x","","Isi dengan x"),"")
A13: I5 | C13: 4 | D13: Suka membaca mengenai topik-topik khusus atas keinginan sendiri | J13: =IF(AND(LEFT($A13,1)="R",$G13="x"),1,0) -> 0 | K13: =IF(AND(LEFT($A13,1)="I",$G13="x"),1,0) -> 0 | L13: =IF(AND(LEFT($A13,1)="A",$G13="x"),1,0) -> 0 | M13: =IF(AND(LEFT($A13,1)="S",$G13="x"),1,0) -> 0 | N13: =IF(AND(LEFT($A13,1)="E",$G13="x"),1,0) -> 0 | O13: =IF(AND(LEFT($A13,1)="C",$G13="x"),1,0) -> 0 | P13: =IF(COUNTA(G13:H13)=2,"Pilih Satu Jawaban","") | Q13: =IF(COUNTA(G13)>0,IF(G13="x","","Isi dengan x"),"")
A14: I7 | C14: 5 | D14: Mampu melakukan percobaan atau penelitian ilmiah | J14: =IF(AND(LEFT($A14,1)="R",$G14="x"),1,0) -> 0 | K14: =IF(AND(LEFT($A14,1)="I",$G14="x"),1,0) -> 0 | L14: =IF(AND(LEFT($A14,1)="A",$G14="x"),1,0) -> 0 | M14: =IF(AND(LEFT($A14,1)="S",$G14="x"),1,0) -> 0 | N14: =IF(AND(LEFT($A14,1)="E",$G14="x"),1,0) -> 0 | O14: =IF(AND(LEFT($A14,1)="C",$G14="x"),1,0) -> 0 | P14: =IF(COUNTA(G14:H14)=2,"Pilih Satu Jawaban","") | Q14: =IF(COUNTA(G14)>0,IF(G14="x","","Isi dengan x"),"")
A15: A15 | C15: 6 | D15: Artistik | J15: =IF(AND(LEFT($A15,1)="R",$G15="x"),1,0) -> 0 | K15: =IF(AND(LEFT($A15,1)="I",$G15="x"),1,0) -> 0 | L15: =IF(AND(LEFT($A15,1)="A",$G15="x"),1,0) -> 0 | M15: =IF(AND(LEFT($A15,1)="S",$G15="x"),1,0) -> 0 | N15: =IF(AND(LEFT($A15,1)="E",$G15="x"),1,0) -> 0 | O15: =IF(AND(LEFT($A15,1)="C",$G15="x"),1,0) -> 0 | P15: =IF(COUNTA(G15:H15)=2,"Pilih Satu Jawaban","") | Q15: =IF(COUNTA(G15)>0,IF(G15="x","","Isi dengan x"),"")
A16: I8 | C16: 7 | D16: Mampu memprogram komputer untuk mempelajari masalah ilmiah | J16: =IF(AND(LEFT($A16,1)="R",$G16="x"),1,0) -> 0 | K16: =IF(AND(LEFT($A16,1)="I",$G16="x"),1,0) -> 0 | L16: =IF(AND(LEFT($A16,1)="A",$G16="x"),1,0) -> 0 | M16: =IF(AND(LEFT($A16,1)="S",$G16="x"),1,0) -> 0 | N16: =IF(AND(LEFT($A16,1)="E",$G16="x"),1,0) -> 0 | O16: =IF(AND(LEFT($A16,1)="C",$G16="x"),1,0) -> 0 | P16: =IF(COUNTA(G16:H16)=2,"Pilih Satu Jawaban","") | Q16: =IF(COUNTA(G16)>0,IF(G16="x","","Isi dengan x"),"")
A17: R15 | C17: 8 | D17: Tertarik menjadi pengawas konstruksi bangunan | J17: =IF(AND(LEFT($A17,1)="R",$G17="x"),1,0) -> 0 | K17: =IF(AND(LEFT($A17,1)="I",$G17="x"),1,0) -> 0 | L17: =IF(AND(LEFT($A17,1)="A",$G17="x"),1,0) -> 0 | M17: =IF(AND(LEFT($A17,1)="S",$G17="x"),1,0) -> 0 | N17: =IF(AND(LEFT($A17,1)="E",$G17="x"),1,0) -> 0 | O17: =IF(AND(LEFT($A17,1)="C",$G17="x"),1,0) -> 0 | P17: =IF(COUNTA(G17:H17)=2,"Pilih Satu Jawaban","") | Q17: =IF(COUNTA(G17)>0,IF(G17="x","","Isi dengan x"),"")
A18: I15 | C18: 9 | D18: Suka dalam memecahkan soal eksak | J18: =IF(AND(LEFT($A18,1)="R",$G18="x"),1,0) -> 0 | K18: =IF(AND(LEFT($A18,1)="I",$G18="x"),1,0) -> 0 | L18: =IF(AND(LEFT($A18,1)="A",$G18="x"),1,0) -> 0 | M18: =IF(AND(LEFT($A18,1)="S",$G18="x"),1,0) -> 0 | N18: =IF(AND(LEFT($A18,1)="E",$G18="x"),1,0) -> 0 | O18: =IF(AND(LEFT($A18,1)="C",$G18="x"),1,0) -> 0 | P18: =IF(COUNTA(G18:H18)=2,"Pilih Satu Jawaban","") | Q18: =IF(COUNTA(G18)>0,IF(G18="x","","Isi dengan x"),"")
A19: C11 | C19: 10 | D19: Mampu melakukan dan menyukai tugas administratif | J19: =IF(AND(LEFT($A19,1)="R",$G19="x"),1,0) -> 0 | K19: =IF(AND(LEFT($A19,1)="I",$G19="x"),1,0) -> 0 | L19: =IF(AND(LEFT($A19,1)="A",$G19="x"),1,0) -> 0 | M19: =IF(AND(LEFT($A19,1)="S",$G19="x"),1,0) -> 0 | N19: =IF(AND(LEFT($A19,1)="E",$G19="x"),1,0) -> 0 | O19: =IF(AND(LEFT($A19,1)="C",$G19="x"),1,0) -> 0 | P19: =IF(COUNTA(G19:H19)=2,"Pilih Satu Jawaban","") | Q19: =IF(COUNTA(G19)>0,IF(G19="x","","Isi dengan x"),"")
A20: E1 | C20: 11 | D20: Bisa mempengaruhi dan membujuk orang lain | J20: =IF(AND(LEFT($A20,1)="R",$G20="x"),1,0) -> 0 | K20: =IF(AND(LEFT($A20,1)="I",$G20="x"),1,0) -> 0 | L20: =IF(AND(LEFT($A20,1)="A",$G20="x"),1,0) -> 0 | M20: =IF(AND(LEFT($A20,1)="S",$G20="x"),1,0) -> 0 | N20: =IF(AND(LEFT($A20,1)="E",$G20="x"),1,0) -> 0 | O20: =IF(AND(LEFT($A20,1)="C",$G20="x"),1,0) -> 0 | P20: =IF(COUNTA(G20:H20)=2,"Pilih Satu Jawaban","") | Q20: =IF(COUNTA(G20)>0,IF(G20="x","","Isi dengan x"),"")
A21: C9 | C21: 12 | D21: Prosedural (Mengikuti aturan) | J21: =IF(AND(LEFT($A21,1)="R",$G21="x"),1,0) -> 0 | K21: =IF(AND(LEFT($A21,1)="I",$G21="x"),1,0) -> 0 | L21: =IF(AND(LEFT($A21,1)="A",$G21="x"),1,0) -> 0 | M21: =IF(AND(LEFT($A21,1)="S",$G21="x"),1,0) -> 0 | N21: =IF(AND(LEFT($A21,1)="E",$G21="x"),1,0) -> 0 | O21: =IF(AND(LEFT($A21,1)="C",$G21="x"),1,0) -> 0 | P21: =IF(COUNTA(G21:H21)=2,"Pilih Satu Jawaban","") | Q21: =IF(COUNTA(G21)>0,IF(G21="x","","Isi dengan x"),"")
... A117: C4 | C117: 108 | D117: Suka menyusun sistem pengarsipan | J117: =IF(AND(LEFT($A117,1)="R",$G117="x"),1,0) -> 0 | K117: =IF(AND(LEFT($A117,1)="I",$G117="x"),1,0) -> 0 | L117: =IF(AND(LEFT($A117,1)="A",$G117="x"),1,0) -> 0 | M117: =IF(AND(LEFT($A117,1)="S",$G117="x"),1,0) -> 0 | N117: =IF(AND(LEFT($A117,1)="E",$G117="x"),1,0) -> 0 | O117: =IF(AND(LEFT($A117,1)="C",$G117="x"),1,0) -> 0 | P117: =IF(COUNTA(G117:H117)=2,"Pilih Satu Jawaban","") | Q117: =IF(COUNTA(G117)>0,IF(G117="x","","Isi dengan x"),"")
G118: =COUNTA(G10:G117) -> 0 | H118: =COUNTA(H10:H117) -> 0 | J118: =SUM(J10:J117) -> 0 | K118: =SUM(K10:K117) -> 0 | L118: =SUM(L10:L117) -> 0 | M118: =SUM(M10:M117) -> 0 | N118: =SUM(N10:N117) -> 0 | O118: =SUM(O10:O117) -> 0 | P118: =IF(COUNTA(G118:H118)=2,"Pilih Satu Jawaban","") -> Pilih Satu Jawaban
C119: JAWABAN | G119: =IF(G118+H118=108,"LENGKAP","TIDAK LENGKAP") -> TIDAK LENGKAP | J119: R | K119: I | L119: A | M119: S | N119: E | O119: C

Sheet Hasil
C3: REPORT HOLLAND TEST (RIASEC)
C6: Nama | E6: =": "&Soal!F3 -> : | H6: Tanggal Lahir | J6: =": "&TEXT(Soal!F5,"dd mmm yyy") -> : 00 Jan 1900
C7: Jenis Kelamin | E7: =": "&Soal!F4 -> : Laki-laki | H7: Pendidikan | J7: =": "&Soal!F6 -> :
C10: Skor Jawaban:
E12: R | F12: I | G12: A | H12: S | I12: E | J12: C
E13: Realistic | F13: Investigative | G13: Artistic | H13: Social | I13: Enterprising | J13: Conventional
E14: =IF(Soal!G119="LENGKAP",Soal!J118,"n/a") -> n/a | F14: =Soal!K118 -> 0 | G14: =Soal!L118 -> 0 | H14: =Soal!M118 -> 0 | I14: =Soal!N118 -> 0 | J14: =Soal!O118 -> 0
E18: =RANK(F18,$F$18:$G$23,1)+COUNTIF($F$18:F18,F18)-1 -> #VALUE! | F18: =RANK($E$14,$E$14:$J$14) -> #VALUE! | G18: R | H18: 1 | I18: =VLOOKUP(H18,$E$18:$G$23,3,0) -> #N/A | J18: =HLOOKUP(I18,$E$12:$J$13,2,0) -> #N/A
E19: =RANK(F19,$F$18:$G$23,1)+COUNTIF($F$18:F19,F19)-1 -> #VALUE! | F19: =RANK($F$14,$E$14:$J$14) -> 1 | G19: I | H19: 2 | I19: =VLOOKUP(H19,$E$18:$G$23,3,0) -> #N/A | J19: =HLOOKUP(I19,$E$12:$J$13,2,0) -> #N/A
E20: =RANK(F20,$F$18:$G$23,1)+COUNTIF($F$18:F20,F20)-1 -> #VALUE! | F20: =RANK($G$14,$E$14:$J$14) -> 1 | G20: A | H20: 3 | I20: =VLOOKUP(H20,$E$18:$G$23,3,0) -> #N/A | J20: =HLOOKUP(I20,$E$12:$J$13,2,0) -> #N/A
E21: =RANK(F21,$F$18:$G$23,1)+COUNTIF($F$18:F21,F21)-1 -> #VALUE! | F21: =RANK($H$14,$E$14:$J$14) -> 1 | G21: S | H21: 4 | I21: =VLOOKUP(H21,$E$18:$G$23,3,0) -> #N/A | J21: =HLOOKUP(I21,$E$12:$J$13,2,0) -> #N/A
E22: =RANK(F22,$F$18:$G$23,1)+COUNTIF($F$18:F22,F22)-1 -> #VALUE! | F22: =RANK($I$14,$E$14:$J$14) -> 1 | G22: E | H22: 5 | I22: =VLOOKUP(H22,$E$18:$G$23,3,0) -> #N/A | J22: =HLOOKUP(I22,$E$12:$J$13,2,0) -> #N/A
E23: =RANK(F23,$F$18:$G$23,1)+COUNTIF($F$18:F23,F23)-1 -> #VALUE! | F23: =RANK($J$14,$E$14:$J$14) -> 1 | G23: C | H23: 6 | I23: =VLOOKUP(H23,$E$18:$G$23,3,0) -> #N/A | J23: =HLOOKUP(I23,$E$12:$J$13,2,0) -> #N/A
C32: Interpretasi Umum:
F33: Kombinasi Tipe Minat Tertinggi
G34: =I18 -> #N/A
G35: =J18 -> #N/A
G36: =I19 -> #N/A | H36: =I20 -> #N/A
G37: Konsistensi :
G38: =VLOOKUP(G34&G36,referensi!B11:C40,2,0) -> #N/A
F39: =$I$18&$I$19 -> #N/A
C40: =IFERROR(VLOOKUP(G34&G36,referensi!B43:D57,3,0),VLOOKUP(G34,referensi!A2:B7,2,0)) -> #N/A
C42: Contoh Profesi Terkait:
C45: =IFERROR(VLOOKUP(G34&G36,referensi!B43:C57,2,0),"")&VLOOKUP(G34,referensi!A1:C7,3,0) -> #N/A
C46: Berdasarkan Kombinasi Tipe Minat*:
C47: =IFERROR(CHAR(10)&CHAR(10)&"Kombinasi "&G34&G36&H36&" = "&VLOOKUP(G34&G36&H36,referensi!B64:C176,2,0)&CHAR(10)&CHAR(10)&"Kombinasi "&G34&G36&" = "&VLOOKUP(G34&G36,referensi!B64:C176,2,0),"")
C48: *Konsistensi harus tinggi atau sedang

Sheet referensi
A1: Kode | B1: Deskripsi | C1: Pekerjaan
A2: R | B2: Profil ini menyukai pekerjaan yang mencakup masalah dan jawaban praktis dan langsung. Menyukai kegiatan yang melibatkan keterampilan motorik, peralatan, mesin Seringkali orang dengan minat Realistis tidak menyukai karier yang melibatkan dokumen atau bekerja sama dengan orang lain. | C2: Mekanik, Insinyur, pengawas bangunan, Petani /Peternak Modern, Atlet, Operator, Polisi, Pemadam Kebakaran, Koki
A3: I | B3: Profil ini menyukai pekerjaan yang berkaitan dengan ide dan pemikiran. memilih kegiatan penyelidikan yang observasional, simbolis, sistematis dan kreatif atas fenomena fisik, biologis dan kultural dalam usahanya untuk mengerti dan mengendalikan fenomena tersebut. Mereka berprestasi terutama dalam bidang akademik dan ilmiah, serta biasanya kurang menyukai aktivitas fisik atau memimpin orang. | C3: Ahli antropologi, astronomi, biologi, botani, kimia, editor penerbitan ilmiah, geologi, pekerjaan penelitian, dan pekerjaan lain yang sejenis
A4: A | B4: Profil ini menyukai pekerjaan dan aktivitas yang bebas, tidak sistematis, ambisius dalam usahanya memanipulasi material fisik, verbal dan humanistic untuk tujuan menciptakan bentuk-bentuk atau produk-produk seni. Kecenderungan ini mengantarkannya memiliki kompetensi artistik, bahasa, musik, drama, mengarang. Tetapi mengurangi kompetensi dibidang klerikal dan bisnis. | C4: Desainer, Penulis, Musisi, Arsitek, Wartawan, Penari, Translator, Artis dan pekerjaan lain yang sejenis.
A5: S | B5: Profil ini menyukai aktivitas yang melibatkan berelasi, berkomunikasi dan mengajar orang. Mereka dilambangkan dengan ketrampilan sosial dan kebutuhan untuk interaksi sosial. Pekerjaannya sering melibatkan membantu atau memberikan layanan kepada orang lain. Tetapi mengurangi kompetensi di bidang teknik dan manual. | C5: Guru, Terapis, Tour Guide, Perawat, Hakim, Konselor, Psikolog, Sejarawan, misionari, Pekerja Sosial, Ahli Patolog Bicara dan pekerjaan lain yang sejenis.
A6: E | B6: Profil ini menghasilkan preferensi yang mendorong individu untuk menikmati memanipulasi kegiatan orang lain dalam usahanya mencapai tujuan organisasi atau keuntungan ekonomi. Kecenderungan ini akan mengarah pada kompetensi kepemimpinan, hubungan timbal balik pribadi dan persuasif, tugas yang menitikberatkan kepada kemampuan verbal yang digunakan untuk mengarahkan dan mempengaruhi orang lain. Tetapi mengurangi kompetensi ilmiah. | C6: Pengacara, Pelobi, Politikus, Pegawai humas, Pelobi, Manajer penjualan, Staf penjualan, perwakilan dagang, dan pekerjaan lain yang sejenis.
A7: C | B7: Profil ini menghasilkan preferensi yang membawa individu untuk menyenangi aktivitas yang teratur dan sistematis seperti misalnya mengarsipkan sesuatu, mereproduksi material, mencatat data, mengolah data, menyukai pekerjaan yang mengikuti prosedur dan rutinitas yang ditetapkan. Kecenderungan ini me-ngantarkan individu memiliki kompetensi klerikal, menghitung / kompetensi Operasional bisnis. Tapi mengurangi kompetensi artistik. | C7: Akuntan, Aktuaris, Ahli Statistik, Analis Keuangan, Operator komputer, Pustakawan, Programer Bisnis, Pengarsip, dan pekerjaan yang berhubungan dengan administrasi.
B10: Tinggat Konsistensi
B11: RI | C11: Tinggi
B12: RC | C12: Tinggi
B13: IR | C13: Tinggi
B14: IA | C14: Tinggi
B15: AI | C15: Tinggi
B16: AS | C16: Tinggi
B17: SA | C17: Tinggi
B18: SE | C18: Tinggi
B19: ES | C19: Tinggi
B20: CE | C20: Tinggi
B21: EC | C21: Tinggi
B22: CR | C22: Tinggi
... B40: CA | C40: Rendah
B42: code | C42: job | D42: title
B43: AC | C43: Graphic Designer, Proofreader, Web/Mobile Design, UI Designer & Visual Designer, | D43: Profesi yang terkait dengan profil ini sering kali melibatkan pendekatan yang kreatif dan berorientasi pada proses. Jenis pekerjaan ini membutuhkan proses pemikiran artistik dan cara kerja yang sehat, andal, dan terstruktur.
B44: AS | C44: Guru, Translator, Nanny, Career Advisor & Interpreter, | D44: Profesi yang terkait dengan profil ini sering kali melibatkan pendekatan yang kreatif dan berorientasi pada manusia. Jenis pekerjaan ini membutuhkan pikiran artistik dan sosial.
B45: EC | C45: General manager, Air traffic controller, Branch Manager, Fundraiser, Recruiter & Shop Assistant, | D45: Profesi yang terkait dengan profil ini sering kali melibatkan pendekatan yang giat dan berbasis proses. Jenis pekerjaan ini membutuhkan banyak tanggung jawab pribadi dan cara kerja yang sehat, andal, dan terstruktur.
B46: IA | C46: Architect, Technical Writer, Animator & Desktop Publisher, | D46: Profesi yang terkait dengan profil ini sering kali melibatkan pendekatan yang berorientasi pada penelitian dan kreatif. Ini adalah jenis pekerjaan yang membutuhkan proses pemikiran analitis dan keingintahuan ilmiah. Pada saat yang sama, itu membutuhkan pola pikir yang unik dan artistik.
B47: IC | C47: Pengembang perangkat lunak , UX Designer, Paralegal, Data Analyst & Quality Controller, | D47: Profesi yang terkait dengan profil ini sering kali melibatkan penelitian dan pendekatan berbasis proses. Jenis pekerjaan ini membutuhkan proses pemikiran analitis dan cara kerja yang sehat, andal, dan terstruktur.
B48: IE | C48: Consultant,Detektif, Solicitor, Market Researcher, Business Controller & Online marketer, | D48: Profesi yang terkait dengan profil ini sering kali melibatkan pendekatan yang berorientasi pada penelitian dan giat. Jenis pekerjaan ini membutuhkan proses pemikiran analitis, semangat giat dan rasa kepemimpinan dan tanggung jawab.
B49: IS | C49: Dokter, Physics Teacher, Nurse, Physiotherapist & Coach, | D49: Profesi yang terkait dengan profil ini sering kali melibatkan penelitian dan pendekatan yang berorientasi pada manusia. Jenis pekerjaan ini membutuhkan proses pemikiran analitis dan pola pikir sosial.
B50: RA | C50: Photographer, Tailor, Artist, Pastry Chef & Furniture Designer, | D50: Profesi yang terkait dengan profil ini sering kali mencakup aktivitas yang melibatkan pendekatan fisik dan kreatif. Jenis pekerjaan ini membutuhkan tenaga kerja manual di satu sisi dan pola pikir imajinatif di sisi lain.
B51: RE | C51: Koki, Engineering Manager, Police Officer, Process Operator & Taxi Driver, | D51: profesi yang terkait dengan profil ini sering kali melibatkan pendekatan fisik dan giat. Jenis pekerjaan ini membutuhkan tenaga kerja manual, mengambil inisiatif dan rasa tanggung jawab.
B52: AE | C52: Design Interior, Illustrator, Entrepreneur, Journalist, Producer, Art director, Copywriter & Actor, | D52: Profesi yang terkait dengan profil ini sering kali melibatkan pendekatan yang kreatif dan giat. Jenis pekerjaan ini membutuhkan pikiran artistik, rasa tanggung jawab atau kadang-kadang bahkan kepemimpinan.
B53: RI | C53: Network Engineer, Mechanical Engineer, Automotive Engineer, Electronic Enginer, Building Insulation Installer, Pilot, Laboratory Technician, Fruit and Vegetable Factory Worker, Product Assembler, | D53: Profil ini terkait dengan profesi yang melibatkan banyak pekerjaan manual, pekerjaan di luar ruangan atau berhubungan dengan alat, mesin, benda, binatang atau tanaman. Pada saat yang sama, jenis profesi ini membutuhkan pemikiran yang cermat dan pendekatan yang lebih analitis.
... B57: SE | C57: HR Manager, Account Manager, Customer Service Advisor & Waiter / Waitress, | D57: Profesi yang terkait dengan profil ini sering kali melibatkan pendekatan yang berorientasi pada orang dan giat. Jenis pekerjaan ini membutuhkan membantu orang lain di satu sisi dan mengambil kepemimpinan dan tanggung jawab di sisi lain.
B63: code | C63: Title
B64: AE | C64: Actors, Art Directors, Interior Designers, Video Game Designers,
B65: AEC | C65: Editors,
B66: AEI | C66: Film and Video Editors, News Analysts, Reporters, and Journalists,
B67: AER | C67: Commercial and Industrial Designers, Fashion Designers, Floral Designers, Merchandise Displayers and Window Trimmers, Models,
B68: AES | C68: Broadcast Announcers and Radio Disc Jockeys, Hairdressers, Hairstylists, and Cosmetologists, Music Directors and Composers, Musicians and Singers,
...
