Workbook

Sheet Soal
C1: HOLLAND TEST (RIASEC)
D3: Nama | E3: : | F3: Dina
D4: Jenis Kelamin | E4: : | F4: Laki-laki | H4: Laki-laki
D5: Tanggal Lahir | E5: : | F5: 32866 | H5: Perempuan
D6: Pendidikan | E6: : | F6: S1 - Akuntansi
C7: Bacalah setiap pernyataan di bawah ini. Jika Anda setuju dengan pernyataan tersebut, silakan berikan tanda silang "x" dikolom yang tersedia. Tidak ada jawaban yang benar atau salah.
A9: CODE | C9: NO | D9: SOAL | G9: YA | H9: TIDAK | J9: R | K9: I | L9: A | M9: S | N9: E | O9: C
A10: A8 | C10: 1 | D10: Senang menonton drama | H10: x | J10: =IF(AND(LEFT($A10,1)="R",$G10="x"),1,0) -> 0 | K10: =IF(AND(LEFT($A10,1)="I",$G10="x"),1,0) -> 0 | L10: =IF(AND(LEFT($A10,1)="A",$G10="x"),1,0) -> 0 | M10: =IF(AND(LEFT($A10,1)="S",$G10="x"),1,0) -> 0 | N10: =IF(AND(LEFT($A10,1)="E",$G10="x"),1,0) -> 0 | O10: =IF(AND(LEFT($A10,1)="C",$G10="x"),1,0) -> 0 | P10: =IF(COUNTA(G10:H10)=2,"Pilih Satu Jawaban","")
A11: S5 | C11: 2 | D11: Senang Melatih Orang | H11: x | J11: =IF(AND(LEFT($A11,1)="R",$G11="x"),1,0) -> 0 | K11: =IF(AND(LEFT($A11,1)="I",$G11="x"),1,0) -> 0 | L11: =IF(AND(LEFT($A11,1)="A",$G11="x"),1,0) -> 0 | M11: =IF(AND(LEFT($A11,1)="S",$G11="x"),1,0) -> 0 | N11: =IF(AND(LEFT($A11,1)="E",$G11="x"),1,0) -> 0 | O11: =IF(AND(LEFT($A11,1)="C",$G11="x"),1,0) -> 0 | P11: =IF(COUNTA(G11:H11)=2,"Pilih Satu Jawaban","")
A12: A11 | C12: 3 | D12: Mampu bermain dalam drama / berakting | H12: x | J12: =IF(AND(LEFT($A12,1)="R",$G12="x"),1,0) -> 0 | K12: =IF(AND(LEFT($A12,1)="I",$G12="x"),1,0) -> 0 | L12: =IF(AND(LEFT($A12,1)="A",$G12="x"),1,0) -> 0 | M12: =IF(AND(LEFT($A12,1)="S",$G12="x"),1,0) -> 0 | N12: =IF(AND(LEFT($A12,1)="E",$G12="x"),1,0) -> 0 | O12: =IF(AND(LEFT($A12,1)="C",$G12="x"),1,0) -> 0 | P12: =IF(COUNTA(G12:H12)=2,"Pilih Satu Jawaban","")
A13: I5 | C13: 4 | D13: Suka membaca mengenai topik-topik khusus atas keinginan sendiri | G13: x | J13: =IF(AND(LEFT($A13,1)="R",$G13="x"),1,0) -> 0 | K13: =IF(AND(LEFT($A13,1)="I",$G13="x"),1,0) -> 1 | L13: =IF(AND(LEFT($A13,1)="A",$G13="x"),1,0) -> 0 | M13: =IF(AND(LEFT($A13,1)="S",$G13="x"),1,0) -> 0 | N13: =IF(AND(LEFT($A13,1)="E",$G13="x"),1,0) -> 0 | O13: =IF(AND(LEFT($A13,1)="C",$G13="x"),1,0) -> 0 | P13: =IF(COUNTA(G13:H13)=2,"Pilih Satu Jawaban","")
A14: I7 | C14: 5 | D14: Mampu melakukan percobaan atau penelitian ilmiah | G14: x | J14: =IF(AND(LEFT($A14,1)="R",$G14="x"),1,0) -> 0 | K14: =IF(AND(LEFT($A14,1)="I",$G14="x"),1,0) -> 1 | L14: =IF(AND(LEFT($A14,1)="A",$G14="x"),1,0) -> 0 | M14: =IF(AND(LEFT($A14,1)="S",$G14="x"),1,0) -> 0 | N14: =IF(AND(LEFT($A14,1)="E",$G14="x"),1,0) -> 0 | O14: =IF(AND(LEFT($A14,1)="C",$G14="x"),1,0) -> 0 | P14: =IF(COUNTA(G14:H14)=2,"Pilih Satu Jawaban","")
A15: A15 | C15: 6 | D15: Artistik | H15: x | J15: =IF(AND(LEFT($A15,1)="R",$G15="x"),1,0) -> 0 | K15: =IF(AND(LEFT($A15,1)="I",$G15="x"),1,0) -> 0 | L15: =IF(AND(LEFT($A15,1)="A",$G15="x"),1,0) -> 0 | M15: =IF(AND(LEFT($A15,1)="S",$G15="x"),1,0) -> 0 | N15: =IF(AND(LEFT($A15,1)="E",$G15="x"),1,0) -> 0 | O15: =IF(AND(LEFT($A15,1)="C",$G15="x"),1,0) -> 0 | P15: =IF(COUNTA(G15:H15)=2,"Pilih Satu Jawaban","")
A16: I8 | C16: 7 | D16: Mampu memprogram komputer untuk mempelajari masalah ilmiah | G16: x | J16: =IF(AND(LEFT($A16,1)="R",$G16="x"),1,0) -> 0 | K16: =IF(AND(LEFT($A16,1)="I",$G16="x"),1,0) -> 1 | L16: =IF(AND(LEFT($A16,1)="A",$G16="x"),1,0) -> 0 | M16: =IF(AND(LEFT($A16,1)="S",$G16="x"),1,0) -> 0 | N16: =IF(AND(LEFT($A16,1)="E",$G16="x"),1,0) -> 0 | O16: =IF(AND(LEFT($A16,1)="C",$G16="x"),1,0) -> 0 | P16: =IF(COUNTA(G16:H16)=2,"Pilih Satu Jawaban","")
A17: R15 | C17: 8 | D17: Tertarik menjadi pengawas konstruksi bangunan | H17: x | J17: =IF(AND(LEFT($A17,1)="R",$G17="x"),1,0) -> 0 | K17: =IF(AND(LEFT($A17,1)="I",$G17="x"),1,0) -> 0 | L17: =IF(AND(LEFT($A17,1)="A",$G17="x"),1,0) -> 0 | M17: =IF(AND(LEFT($A17,1)="S",$G17="x"),1,0) -> 0 | N17: =IF(AND(LEFT($A17,1)="E",$G17="x"),1,0) -> 0 | O17: =IF(AND(LEFT($A17,1)="C",$G17="x"),1,0) -> 0 | P17: =IF(COUNTA(G17:H17)=2,"Pilih Satu Jawaban","")
A18: I15 | C18: 9 | D18: Suka dalam memecahkan soal eksak | G18: x | J18: =IF(AND(LEFT($A18,1)="R",$G18="x"),1,0) -> 0 | K18: =IF(AND(LEFT($A18,1)="I",$G18="x"),1,0) -> 1 | L18: =IF(AND(LEFT($A18,1)="A",$G18="x"),1,0) -> 0 | M18: =IF(AND(LEFT($A18,1)="S",$G18="x"),1,0) -> 0 | N18: =IF(AND(LEFT($A18,1)="E",$G18="x"),1,0) -> 0 | O18: =IF(AND(LEFT($A18,1)="C",$G18="x"),1,0) -> 0 | P18: =IF(COUNTA(G18:H18)=2,"Pilih Satu Jawaban","")
A19: C11 | C19: 10 | D19: Mampu melakukan dan menyukai tugas administratif | G19: x | J19: =IF(AND(LEFT($A19,1)="R",$G19="x"),1,0) -> 0 | K19: =IF(AND(LEFT($A19,1)="I",$G19="x"),1,0) -> 0 | L19: =IF(AND(LEFT($A19,1)="A",$G19="x"),1,0) -> 0 | M19: =IF(AND(LEFT($A19,1)="S",$G19="x"),1,0) -> 0 | N19: =IF(AND(LEFT($A19,1)="E",$G19="x"),1,0) -> 0 | O19: =IF(AND(LEFT($A19,1)="C",$G19="x"),1,0) -> 1 | P19: =IF(COUNTA(G19:H19)=2,"Pilih Satu Jawaban","")
A20: E1 | C20: 11 | D20: Bisa mempengaruhi dan membujuk orang lain | H20: x | J20: =IF(AND(LEFT($A20,1)="R",$G20="x"),1,0) -> 0 | K20: =IF(AND(LEFT($A20,1)="I",$G20="x"),1,0) -> 0 | L20: =IF(AND(LEFT($A20,1)="A",$G20="x"),1,0) -> 0 | M20: =IF(AND(LEFT($A20,1)="S",$G20="x"),1,0) -> 0 | N20: =IF(AND(LEFT($A20,1)="E",$G20="x"),1,0) -> 0 | O20: =IF(AND(LEFT($A20,1)="C",$G20="x"),1,0) -> 0 | P20: =IF(COUNTA(G20:H20)=2,"Pilih Satu Jawaban","")
A21: C9 | C21: 12 | D21: Prosedural (Mengikuti aturan) | G21: x | J21: =IF(AND(LEFT($A21,1)="R",$G21="x"),1,0) -> 0 | K21: =IF(AND(LEFT($A21,1)="I",$G21="x"),1,0) -> 0 | L21: =IF(AND(LEFT($A21,1)="A",$G21="x"),1,0) -> 0 | M21: =IF(AND(LEFT($A21,1)="S",$G21="x"),1,0) -> 0 | N21: =IF(AND(LEFT($A21,1)="E",$G21="x"),1,0) -> 0 | O21: =IF(AND(LEFT($A21,1)="C",$G21="x"),1,0) -> 1 | P21: =IF(COUNTA(G21:H21)=2,"Pilih Satu Jawaban","")
A22: C10 | C22: 13 | D22: Suka menggunakan aplikasi pencatatan keuangan | G22: x | J22: =IF(AND(LEFT($A22,1)="R",$G22="x"),1,0) -> 0 | K22: =IF(AND(LEFT($A22,1)="I",$G22="x"),1,0) -> 0 | L22: =IF(AND(LEFT($A22,1)="A",$G22="x"),1,0) -> 0 | M22: =IF(AND(LEFT($A22,1)="S",$G22="x"),1,0) -> 0 | N22: =IF(AND(LEFT($A22,1)="E",$G22="x"),1,0) -> 0 | O22: =IF(AND(LEFT($A22,1)="C",$G22="x"),1,0) -> 1 | P22: =IF(COUNTA(G22:H22)=2,"Pilih Satu Jawaban","")
A23: R2 | C23: 14 | D23: Suka memperbaiki motor | H23: x | J23: =IF(AND(LEFT($A23,1)="R",$G23="x"),1,0) -> 0 | K23: =IF(AND(LEFT($A23,1)="I",$G23="x"),1,0) -> 0 | L23: =IF(AND(LEFT($A23,1)="A",$G23="x"),1,0) -> 0 | M23: =IF(AND(LEFT($A23,1)="S",$G23="x"),1,0) -> 0 | N23: =IF(AND(LEFT($A23,1)="E",$G23="x"),1,0) -> 0 | O23: =IF(AND(LEFT($A23,1)="C",$G23="x"),1,0) -> 0 | P23: =IF(COUNTA(G23:H23)=2,"Pilih Satu Jawaban","")
A24: A18 | C24: 15 | D24: Bisa mengekspresikan diri secara kreatif | H24: x | J24: =IF(AND(LEFT($A24,1)="R",$G24="x"),1,0) -> 0 | K24: =IF(AND(LEFT($A24,1)="I",$G24="x"),1,0) -> 0 | L24: =IF(AND(LEFT($A24,1)="A",$G24="x"),1,0) -> 0 | M24: =IF(AND(LEFT($A24,1)="S",$G24="x"),1,0) -> 0 | N24: =IF(AND(LEFT($A24,1)="E",$G24="x"),1,0) -> 0 | O24: =IF(AND(LEFT($A24,1)="C",$G24="x"),1,0) -> 0 | P24: =IF(COUNTA(G24:H24)=2,"Pilih Satu Jawaban","")
A25: C17 | C25: 16 | D25: Ingin bekerja dibagian Staff keuangan | G25: x | J25: =IF(AND(LEFT($A25,1)="R",$G25="x"),1,0) -> 0 | K25: =IF(AND(LEFT($A25,1)="I",$G25="x"),1,0) -> 0 | L25: =IF(AND(LEFT($A25,1)="A",$G25="x"),1,0) -> 0 | M25: =IF(AND(LEFT($A25,1)="S",$G25="x"),1,0) -> 0 | N25: =IF(AND(LEFT($A25,1)="E",$G25="x"),1,0) -> 0 | O25: =IF(AND(LEFT($A25,1)="C",$G25="x"),1,0) -> 1 | P25: =IF(COUNTA(G25:H25)=2,"Pilih Satu Jawaban","")
A26: I11 | C26: 17 | D26: Mampu menyebutkan makanan yang memiliki protein tinggi | H26: x | J26: =IF(AND(LEFT($A26,1)="R",$G26="x"),1,0) -> 0 | K26: =IF(AND(LEFT($A26,1)="I",$G26="x"),1,0) -> 0 | L26: =IF(AND(LEFT($A26,1)="A",$G26="x"),1,0) -> 0 | M26: =IF(AND(LEFT($A26,1)="S",$G26="x"),1,0) -> 0 | N26: =IF(AND(LEFT($A26,1)="E",$G26="x"),1,0) -> 0 | O26: =IF(AND(LEFT($A26,1)="C",$G26="x"),1,0) -> 0 | P26: =IF(COUNTA(G26:H26)=2,"Pilih Satu Jawaban","")
A27: S12 | C27: 18 | D27: Suka melakukan pekerjaan social | H27: x | J27: =IF(AND(LEFT($A27,1)="R",$G27="x"),1,0) -> 0 | K27: =IF(AND(LEFT($A27,1)="I",$G27="x"),1,0) -> 0 | L27: =IF(AND(LEFT($A27,1)="A",$G27="x"),1,0) -> 0 | M27: =IF(AND(LEFT($A27,1)="S",$G27="x"),1,0) -> 0 | N27: =IF(AND(LEFT($A27,1)="E",$G27="x"),1,0) -> 0 | O27: =IF(AND(LEFT($A27,1)="C",$G27="x"),1,0) -> 0 | P27: =IF(COUNTA(G27:H27)=2,"Pilih Satu Jawaban","")
A28: E7 | C28: 19 | D28: Mampu mengetahui bagaimana menjadi pemimpin yang baik/ berhasil | H28: x | J28: =IF(AND(LEFT($A28,1)="R",$G28="x"),1,0) -> 0 | K28: =IF(AND(LEFT($A28,1)="I",$G28="x"),1,0) -> 0 | L28: =IF(AND(LEFT($A28,1)="A",$G28="x"),1,0) -> 0 | M28: =IF(AND(LEFT($A28,1)="S",$G28="x"),1,0) -> 0 | N28: =IF(AND(LEFT($A28,1)="E",$G28="x"),1,0) -> 0 | O28: =IF(AND(LEFT($A28,1)="C",$G28="x"),1,0) -> 0 | P28: =IF(COUNTA(G28:H28)=2,"Pilih Satu Jawaban","")
A29: R14 | C29: 20 | D29: Tidak suka menyatakan perasaan | G29: x | J29: =IF(AND(LEFT($A29,1)="R",$G29="x"),1,0) -> 1 | K29: =IF(AND(LEFT($A29,1)="I",$G29="x"),1,0) -> 0 | L29: =IF(AND(LEFT($A29,1)="A",$G29="x"),1,0) -> 0 | M29: =IF(AND(LEFT($A29,1)="S",$G29="x"),1,0) -> 0 | N29: =IF(AND(LEFT($A29,1)="E",$G29="x"),1,0) -> 0 | O29: =IF(AND(LEFT($A29,1)="C",$G29="x"),1,0) -> 0 | P29: =IF(COUNTA(G29:H29)=2,"Pilih Satu Jawaban","")
A30: E17 | C30: 21 | D30: Percaya diri | H30: x | J30: =IF(AND(LEFT($A30,1)="R",$G30="x"),1,0) -> 0 | K30: =IF(AND(LEFT($A30,1)="I",$G30="x"),1,0) -> 0 | L30: =IF(AND(LEFT($A30,1)="A",$G30="x"),1,0) -> 0 | M30: =IF(AND(LEFT($A30,1)="S",$G30="x"),1,0) -> 0 | N30: =IF(AND(LEFT($A30,1)="E",$G30="x"),1,0) -> 0 | O30: =IF(AND(LEFT($A30,1)="C",$G30="x"),1,0) -> 0 | P30: =IF(COUNTA(G30:H30)=2,"Pilih Satu Jawaban","")
A31: I6 | C31: 22 | D31: Suka menerapkan matematika dalam masalah praktis | G31: x | J31: =IF(AND(LEFT($A31,1)="R",$G31="x"),1,0) -> 0 | K31: =IF(AND(LEFT($A31,1)="I",$G31="x"),1,0) -> 1 | L31: =IF(AND(LEFT($A31,1)="A",$G31="x"),1,0) -> 0 | M31: =IF(AND(LEFT($A31,1)="S",$G31="x"),1,0) -> 0 | N31: =IF(AND(LEFT($A31,1)="E",$G31="x"),1,0) -> 0 | O31: =IF(AND(LEFT($A31,1)="C",$G31="x"),1,0) -> 0 | P31: =IF(COUNTA(G31:H31)=2,"Pilih Satu Jawaban","")
A32: A4 | C32: 23 | D32: Emosional | H32: x | J32: =IF(AND(LEFT($A32,1)="R",$G32="x"),1,0) -> 0 | K32: =IF(AND(LEFT($A32,1)="I",$G32="x"),1,0) -> 0 | L32: =IF(AND(LEFT($A32,1)="A",$G32="x"),1,0) -> 0 | M32: =IF(AND(LEFT($A32,1)="S",$G32="x"),1,0) -> 0 | N32: =IF(AND(LEFT($A32,1)="E",$G32="x"),1,0) -> 0 | O32: =IF(AND(LEFT($A32,1)="C",$G32="x"),1,0) -> 0 | P32: =IF(COUNTA(G32:H32)=2,"Pilih Satu Jawaban","")
A33: R3 | C33: 24 | D33: Menyukai memperbaiki peralatan mekanik | H33: x | J33: =IF(AND(LEFT($A33,1)="R",$G33="x"),1,0) -> 0 | K33: =IF(AND(LEFT($A33,1)="I",$G33="x"),1,0) -> 0 | L33: =IF(AND(LEFT($A33,1)="A",$G33="x"),1,0) -> 0 | M33: =IF(AND(LEFT($A33,1)="S",$G33="x"),1,0) -> 0 | N33: =IF(AND(LEFT($A33,1)="E",$G33="x"),1,0) -> 0 | O33: =IF(AND(LEFT($A33,1)="C",$G33="x"),1,0) -> 0 | P33: =IF(COUNTA(G33:H33)=2,"Pilih Satu Jawaban","")
A34: S13 | C34: 25 | D34: Mampu menghibur dan menemani orang yang lebih tua dari saya | H34: x | J34: =IF(AND(LEFT($A34,1)="R",$G34="x"),1,0) -> 0 | K34: =IF(AND(LEFT($A34,1)="I",$G34="x"),1,0) -> 0 | L34: =IF(AND(LEFT($A34,1)="A",$G34="x"),1,0) -> 0 | M34: =IF(AND(LEFT($A34,1)="S",$G34="x"),1,0) -> 0 | N34: =IF(AND(LEFT($A34,1)="E",$G34="x"),1,0) -> 0 | O34: =IF(AND(LEFT($A34,1)="C",$G34="x"),1,0) -> 0 | P34: =IF(COUNTA(G34:H34)=2,"Pilih Satu Jawaban","")
A35: E11 | C35: 26 | D35: Senang memulai proyek baru | H35: x | J35: =IF(AND(LEFT($A35,1)="R",$G35="x"),1,0) -> 0 | K35: =IF(AND(LEFT($A35,1)="I",$G35="x"),1,0) -> 0 | L35: =IF(AND(LEFT($A35,1)="A",$G35="x"),1,0) -> 0 | M35: =IF(AND(LEFT($A35,1)="S",$G35="x"),1,0) -> 0 | N35: =IF(AND(LEFT($A35,1)="E",$G35="x"),1,0) -> 0 | O35: =IF(AND(LEFT($A35,1)="C",$G35="x"),1,0) -> 0 | P35: =IF(COUNTA(G35:H35)=2,"Pilih Satu Jawaban","")
A36: I10 | C36: 27 | D36: Suka kegiatan akademis | G36: x | J36: =IF(AND(LEFT($A36,1)="R",$G36="x"),1,0) -> 0 | K36: =IF(AND(LEFT($A36,1)="I",$G36="x"),1,0) -> 1 | L36: =IF(AND(LEFT($A36,1)="A",$G36="x"),1,0) -> 0 | M36: =IF(AND(LEFT($A36,1)="S",$G36="x"),1,0) -> 0 | N36: =IF(AND(LEFT($A36,1)="E",$G36="x"),1,0) -> 0 | O36: =IF(AND(LEFT($A36,1)="C",$G36="x"),1,0) -> 0 | P36: =IF(COUNTA(G36:H36)=2,"Pilih Satu Jawaban","")
A37: S2 | C37: 28 | D37: Ramah | H37: x | J37: =IF(AND(LEFT($A37,1)="R",$G37="x"),1,0) -> 0 | K37: =IF(AND(LEFT($A37,1)="I",$G37="x"),1,0) -> 0 | L37: =IF(AND(LEFT($A37,1)="A",$G37="x"),1,0) -> 0 | M37: =IF(AND(LEFT($A37,1)="S",$G37="x"),1,0) -> 0 | N37: =IF(AND(LEFT($A37,1)="E",$G37="x"),1,0) -> 0 | O37: =IF(AND(LEFT($A37,1)="C",$G37="x"),1,0) -> 0 | P37: =IF(COUNTA(G37:H37)=2,"Pilih Satu Jawaban","")
A38: C16 | C38: 29 | D38: Efisien dan Terstruktur | G38: x | J38: =IF(AND(LEFT($A38,1)="R",$G38="x"),1,0) -> 0 | K38: =IF(AND(LEFT($A38,1)="I",$G38="x"),1,0) -> 0 | L38: =IF(AND(LEFT($A38,1)="A",$G38="x"),1,0) -> 0 | M38: =IF(AND(LEFT($A38,1)="S",$G38="x"),1,0) -> 0 | N38: =IF(AND(LEFT($A38,1)="E",$G38="x"),1,0) -> 0 | O38: =IF(AND(LEFT($A38,1)="C",$G38="x"),1,0) -> 1 | P38: =IF(COUNTA(G38:H38)=2,"Pilih Satu Jawaban","")
A39: R4 | C39: 30 | D39: Suka menggunakan perkakas bengkel dan mesin | H39: x | J39: =IF(AND(LEFT($A39,1)="R",$G39="x"),1,0) -> 0 | K39: =IF(AND(LEFT($A39,1)="I",$G39="x"),1,0) -> 0 | L39: =IF(AND(LEFT($A39,1)="A",$G39="x"),1,0) -> 0 | M39: =IF(AND(LEFT($A39,1)="S",$G39="x"),1,0) -> 0 | N39: =IF(AND(LEFT($A39,1)="E",$G39="x"),1,0) -> 0 | O39: =IF(AND(LEFT($A39,1)="C",$G39="x"),1,0) -> 0 | P39: =IF(COUNTA(G39:H39)=2,"Pilih Satu Jawaban","")
A40: S4 | C40: 31 | D40: Suka menjaga / mengurus mengawasi anak-anak | H40: x | J40: =IF(AND(LEFT($A40,1)="R",$G40="x"),1,0) -> 0 | K40: =IF(AND(LEFT($A40,1)="I",$G40="x"),1,0) -> 0 | L40: =IF(AND(LEFT($A40,1)="A",$G40="x"),1,0) -> 0 | M40: =IF(AND(LEFT($A40,1)="S",$G40="x"),1,0) -> 0 | N40: =IF(AND(LEFT($A40,1)="E",$G40="x"),1,0) -> 0 | O40: =IF(AND(LEFT($A40,1)="C",$G40="x"),1,0) -> 0 | P40: =IF(COUNTA(G40:H40)=2,"Pilih Satu Jawaban","")
A41: I2 | C41: 32 | D41: Senang menganalisa dan mengevaluasi | G41: x | J41: =IF(AND(LEFT($A41,1)="R",$G41="x"),1,0) -> 0 | K41: =IF(AND(LEFT($A41,1)="I",$G41="x"),1,0) -> 1 | L41: =IF(AND(LEFT($A41,1)="A",$G41="x"),1,0) -> 0 | M41: =IF(AND(LEFT($A41,1)="S",$G41="x"),1,0) -> 0 | N41: =IF(AND(LEFT($A41,1)="E",$G41="x"),1,0) -> 0 | O41: =IF(AND(LEFT($A41,1)="C",$G41="x"),1,0) -> 0 | P41: =IF(COUNTA(G41:H41)=2,"Pilih Satu Jawaban","")
A42: R7 | C42: 33 | D42: Senang melatih binatang | H42: x | J42: =IF(AND(LEFT($A42,1)="R",$G42="x"),1,0) -> 0 | K42: =IF(AND(LEFT($A42,1)="I",$G42="x"),1,0) -> 0 | L42: =IF(AND(LEFT($A42,1)="A",$G42="x"),1,0) -> 0 | M42: =IF(AND(LEFT($A42,1)="S",$G42="x"),1,0) -> 0 | N42: =IF(AND(LEFT($A42,1)="E",$G42="x"),1,0) -> 0 | O42: =IF(AND(LEFT($A42,1)="C",$G42="x"),1,0) -> 0 | P42: =IF(COUNTA(G42:H42)=2,"Pilih Satu Jawaban","")
...

Sheet Hasil
C3: REPORT HOLLAND TEST (RIASEC)
C6: Nama | E6: =": "&Soal!F3 -> : Dina | H6: Tanggal Lahir | J6: =": "&TEXT(Soal!F5,"dd mmm yyy") -> : 24 Des 1989
C7: Jenis Kelamin | E7: =": "&Soal!F4 -> : Laki-laki | H7: Pendidikan | J7: =": "&Soal!F6 -> : S1 - Akuntansi
C10: Skor Jawaban:
E12: R | F12: I | G12: A | H12: S | I12: E | J12: C
E13: Realistic | F13: Investigative | G13: Artistic | H13: Social | I13: Enterprising | J13: Conventional
E14: =Soal!J118 -> 4 | F14: =Soal!K118 -> 10 | G14: =Soal!L118 -> 2 | H14: =Soal!M118 -> 1 | I14: =Soal!N118 -> 2 | J14: =Soal!O118 -> 18
E18: =RANK(F18,$F$18:$G$23,1)+COUNTIF($F$18:F18,F18)-1 -> 3 | F18: =RANK($E$14,$E$14:$J$14) -> 3 | G18: R | H18: 1 | I18: =VLOOKUP(H18,$E$18:$G$23,3,0) -> C | J18: =HLOOKUP(I18,$E$12:$J$13,2,0) -> Conventional
E19: =RANK(F19,$F$18:$G$23,1)+COUNTIF($F$18:F19,F19)-1 -> 2 | F19: =RANK($F$14,$E$14:$J$14) -> 2 | G19: I | H19: 2 | I19: =VLOOKUP(H19,$E$18:$G$23,3,0) -> I | J19: =HLOOKUP(I19,$E$12:$J$13,2,0) -> Investigative
E20: =RANK(F20,$F$18:$G$23,1)+COUNTIF($F$18:F20,F20)-1 -> 4 | F20: =RANK($G$14,$E$14:$J$14) -> 4 | G20: A | H20: 3 | I20: =VLOOKUP(H20,$E$18:$G$23,3,0) -> R | J20: =HLOOKUP(I20,$E$12:$J$13,2,0) -> Realistic
E21: =RANK(F21,$F$18:$G$23,1)+COUNTIF($F$18:F21,F21)-1 -> 6 | F21: =RANK($H$14,$E$14:$J$14) -> 6 | G21: S | H21: 4 | I21: =VLOOKUP(H21,$E$18:$G$23,3,0) -> A | J21: =HLOOKUP(I21,$E$12:$J$13,2,0) -> Artistic
E22: =RANK(F22,$F$18:$G$23,1)+COUNTIF($F$18:F22,F22)-1 -> 5 | F22: =RANK($I$14,$E$14:$J$14) -> 4 | G22: E | H22: 5 | I22: =VLOOKUP(H22,$E$18:$G$23,3,0) -> E | J22: =HLOOKUP(I22,$E$12:$J$13,2,0) -> Enterprising
E23: =RANK(F23,$F$18:$G$23,1)+COUNTIF($F$18:F23,F23)-1 -> 1 | F23: =RANK($J$14,$E$14:$J$14) -> 1 | G23: C | H23: 6 | I23: =VLOOKUP(H23,$E$18:$G$23,3,0) -> S | J23: =HLOOKUP(I23,$E$12:$J$13,2,0) -> Social
C32: Interpretasi Umum:
F33: Kombinasi Tipe Minat Tertinggi
G34: =I18 -> C
G35: =J18 -> Conventional
G36: =I19 -> I | H36: =I20 -> R
G37: Konsistensi :
G38: =VLOOKUP(G34&G36,referensi!B11:C40,2,0) -> Sedang
F39: =$I$18&$I$19 -> CI
C40: =VLOOKUP(G34,referensi!A2:B7,2,0) -> Orang dengan minat Convensial menghasilkan preferensi yang membawa individu untuk menyenangi aktivitas yang teratur dan sistematis seperti misalnya mengarsipkan sesuatu, mereproduksi material, mencatat data, mengolah data, menyukai pekerjaan yang mengikuti prosedur dan rutinitas yang ditetapkan. Kecenderungan ini me-ngantarkan individu memiliki kompetensi klerikal, menghitung dan kompetensi bisnis. Tapi mengurangi kompetensi artistik.
C42: Contoh Profesi Terkait:
C45: =VLOOKUP(G34,referensi!A1:C7,3,0) -> Akuntan, Aktuaris, Ahli Statistik, Analis Keuangan, Operator komputer, Pustakawan, Programer Bisnis, Pengarsip, dan pekerjaan yang berhubungan dengan administrasi.

Sheet referensi
A1: Kode | B1: Deskripsi | C1: Pekerjaan
A2: R | B2: Orang dengan minat Realistis menyukai pekerjaan yang mencakup masalah dan jawaban praktis dan langsung. Menyukai kegiatan yang melibatkan keterampilan motorik, peralatan, mesin Seringkali orang dengan minat Realistis tidak menyukai karier yang melibatkan dokumen atau bekerja sama dengan orang lain. | C2: Atlet, Operator, Pilot, Koki, Mekanik, Polisi, Perawat, Insinyur, pengawas bangunan, Petani, Peternak
A3: I | B3: Orang dengan minat Investigasi menyukai pekerjaan yang berkaitan dengan ide dan pemikiran. memilih kegiatan penyelidikan yang observasional, simbolis, sistematis dan kreatif atas fenomena fisik, biologis dan kultural dalam usahanya untuk mengerti dan mengendalikan fenomena tersebut. Mereka berprestasi terutama dalam bidang akademik dan ilmiah, serta biasanya kurang menyukai aktivitas fisik atau memimpin orang. | C3: Ahli antropologi, astronomi, biologi, botani, kimia, editor penerbitan ilmiah, geologi, pekerjaan penelitian, dan pekerjaan lain yang sejenis
A4: A | B4: Orang dengan minat Artistik menyukai pekerjaan dan aktivitas yang bebas, tidak sistematis, ambisius dalam usahanya memanipulasi material fisik, verbal dan humanistic untuk tujuan menciptakan bentuk-bentuk atau produk-produk seni. Kecenderungan ini mengantarkannya memiliki kompetensi artistik, bahasa, musik, drama, mengarang. Tetapi mengurangi kompetensi dibidang klerikal dan bisnis. | C4: Desainer, Penulis, Musisi, Arsitek, Wartawan, Penari, Translator, Artis dan pekerjaan lain yang sejenis.
A5: S | B5: Orang dengan minat Sosial menyukai aktivitas yang melibatkan berelasi, berkomunikasi dan mengajar orang.Mereka dilambangkan dengan ketrampilan sosial dan kebutuhan untuk interaksi sosial. Pekerjaannya sering melibatkan membantu atau memberikan layanan kepada orang lain. Tetapi mengurangi kompetensi di bidang teknik dan manual. | C5: Guru, Terapis, Tour Guide, Perawat, Hakim, Konselor, Psikolog, Sejarawan, misionari, Pekerja Sosial, Ahli Patolog Bicara dan pekerjaan lain yang sejenis.
A6: E | B6: Orang dengan minat Enterprising menghasilkan preferensi yang mendorong individu untuk menikmati memanipulasi kegiatan orang lain dalam usahanya mencapai tujuan organisasi atau keuntungan ekonomi. Kecenderungan ini akan mengarah pada kompetensi kepemimpinan, hubungan timbal balik pribadi dan persuasif, tugas yang menitikberatkan kepada kemampuan verbal yang digunakan untuk mengarahkan dan mempengaruhi orang lain. Tetapi mengurangi kompetensi ilmiah. | C6: Pengacara, Pelobi, Politikus, Pegawai humas, Pelobi, Manajer penjualan, Staf penjualan, perwakilan dagang, dan pekerjaan lain yang sejenis.
A7: C | B7: Orang dengan minat Convensial menghasilkan preferensi yang membawa individu untuk menyenangi aktivitas yang teratur dan sistematis seperti misalnya mengarsipkan sesuatu, mereproduksi material, mencatat data, mengolah data, menyukai pekerjaan yang mengikuti prosedur dan rutinitas yang ditetapkan. Kecenderungan ini me-ngantarkan individu memiliki kompetensi klerikal, menghitung dan kompetensi bisnis. Tapi mengurangi kompetensi artistik. | C7: Akuntan, Aktuaris, Ahli Statistik, Analis Keuangan, Operator komputer, Pustakawan, Programer Bisnis, Pengarsip, dan pekerjaan yang berhubungan dengan administrasi.
B10: Tinggat Konsistensi
B11: RI | C11: Tinggi
B12: RC | C12: Tinggi
B13: IR | C13: Tinggi
B14: IA | C14: Tinggi
B15: AI | C15: Tinggi
B16: AS | C16: Tinggi
B17: SA | C17: Tinggi
B18: SE | C18: Tinggi
B19: ES | C19: Tinggi
B20: CE | C20: Tinggi
B21: EC | C21: Tinggi
B22: CR | C22: Tinggi
... B40: CA | C40: Rendah
