Workbook

Sheet Instruksi & Isi Data
B2: TES GAYA BELAJAR (VAK) | D2: Nama
D3: Usia
D4: Pendidikan
D5: Jenis kelamin
D6: Tanggal
B7: rvra.consultant@gmail.com
B9: Bacalah setiap pernyataan dari 36 nomor berikut
B10: Ketiklah angka "1" (satu) pada kolom jawaban "Ya" apabila pernyataan tersebut sesuai dengan diri Anda
B11: Ketiklah angka "1" (satu) pada kolom jawaban "Tidak" apabila pernyataan tersebut tidak sesuai dengan diri Anda
B12: Setiap pertanyataan hanya dapat dijawab salah satu pilihan saja antara jawaban "Ya" atau "Tidak"
B14: contoh :
B15: No | C15: Pernyataan | D15: Kolom Jawaban
D16: Ya | E16: Tidak
B17: 1 | C17: Saya biasanya berbicara dengan perlahan. | E17: 1
B18: 2 | C18: Saya lebih suka berbicara daripada menulis. | D18: 1

Sheet Lembar Soal & Jawaban
B2: TES GAYA BELAJAR (VAK) | D2: Nama
D3: Usia
D4: Pendidikan
D5: Jenis kelamin
D6: Tanggal
B7: rvra.consultant@gmail.com
B9: Bacalah setiap pernyataan dari 36 nomor berikut
B10: Ketiklah angka "1" (satu) pada kolom jawaban "Ya" apabila pernyataan tersebut sesuai dengan diri Anda
B11: Ketiklah angka "1" (satu) pada kolom jawaban "Tidak" apabila pernyataan tersebut tidak sesuai dengan diri Anda.
B12: Setiap pertanyataan hanya dapat dijawab salah salah satu saja antara jawaban "Ya" atau "Tidak"
B14: contoh :
B15: No | C15: Pernyataan | D15: Kolom Jawaban
D16: Ya | E16: Tidak
B17: 1 | C17: Saya biasanya berbicara dengan perlahan. | E17: 1
B18: 2 | C18: Saya lebih suka berbicara daripada menulis. | D18: 1
D20: rvra.consultant@gmail.com
B21: No | C21: Pernyataan | D21: Kolom Jawaban
D22: Ya | E22: Tidak | G22: Status Isian | H22: Kriteria | I22: Hasil
B23: 1 | C23: Saya lebih suka mendengarkan suatu buku dati tape recorder daripada membacanya. | F23: =SUM(D23:E23) -> 0 | G23: =IF(F23=1,"OK","CEK ULANG") -> CEK ULANG | H23: A | I23: =IF(D23=1,"A","0") -> 0 | K23: V | L23: =COUNTIF($I$23:$I$58,K23) -> 0 | M23: =COUNTIF($H$23:$H$58,K23) -> 12
B24: 2 | C24: Ketika saya memasang sesuatu secara bersama-sama, pertama-tama saya selalu membaca petunjuknya. | F24: =SUM(D24:E24) -> 0 | G24: =IF(F24=1,"OK","CEK ULANG") -> CEK ULANG | H24: V | I24: =IF(D24=1,"V","0") -> 0 | K24: A | L24: =COUNTIF($I$23:$I$58,K24) -> 0 | M24: =COUNTIF($H$23:$H$58,K24) -> 12
B25: 3 | C25: Saya lebih suka membaca daripada mendengarkan ceramah | F25: =SUM(D25:E25) -> 0 | G25: =IF(F25=1,"OK","CEK ULANG") -> CEK ULANG | H25: V | I25: =IF(D25=1,"V","0") -> 0 | K25: K | L25: =COUNTIF($I$23:$I$58,K25) -> 0 | M25: =COUNTIF($H$23:$H$58,K25) -> 12
B26: 4 | C26: Bila saya sedang sendirian, saya selalu bermain musik, bersenandung, atau bernyanyi. | F26: =SUM(D26:E26) -> 0 | G26: =IF(F26=1,"OK","CEK ULANG") -> CEK ULANG | H26: A | I26: =IF(D26=1,"A","0") -> 0
B27: 5 | C27: Saya lebih suka bermain olahraga daripada membaca buku. | F27: =SUM(D27:E27) -> 0 | G27: =IF(F27=1,"OK","CEK ULANG") -> CEK ULANG | H27: K | I27: =IF(D27=1,"K","0") -> 0
B28: 6 | C28: Saya selalu bisa mengatakan/ menunjukkan seperti utara dan selatan tanpa alat di mana saja saya berada. | F28: =SUM(D28:E28) -> 0 | G28: =IF(F28=1,"OK","CEK ULANG") -> CEK ULANG | H28: V | I28: =IF(D28=1,"V","0") -> 0
B29: 7 | C29: Saya suka menulis surat/sastra atau jurnal. | F29: =SUM(D29:E29) -> 0 | G29: =IF(F29=1,"OK","CEK ULANG") -> CEK ULANG | H29: V | I29: =IF(D29=1,"V","0") -> 0
B30: 8 | C30: Ketika saya berbicara saya suka mengatakan sesuatu seperti, “aku dengar ya, bahwa suara itu bagus atau itu dering bel”. | F30: =SUM(D30:E30) -> 0 | G30: =IF(F30=1,"OK","CEK ULANG") -> CEK ULANG | H30: A | I30: =IF(D30=1,"A","0") -> 0
B31: 9 | C31: Kamarku, meja belajar, mobil, atau rumah selalu tak teratur. | F31: =SUM(D31:E31) -> 0 | G31: =IF(F31=1,"OK","CEK ULANG") -> CEK ULANG | H31: K | I31: =IF(D31=1,"K","0") -> 0
B32: 10 | C32: Saya suka bekerja dengan tanganku dan membangun, atau membuat sesuatu | F32: =SUM(D32:E32) -> 0 | G32: =IF(F32=1,"OK","CEK ULANG") -> CEK ULANG | H32: K | I32: =IF(D32=1,"K","0") -> 0
B33: 11 | C33: Saya sangat tahu tentang kata-kata suatu nyanyian yang aku dengarkan | F33: =SUM(D33:E33) -> 0 | G33: =IF(F33=1,"OK","CEK ULANG") -> CEK ULANG | H33: A | I33: =IF(D33=1,"A","0") -> 0
B34: 12 | C34: Ketika orang lain berbicara, saya selalu menggambarkan di pikiran saya tentang apa yang sedang mereka katakan. | F34: =SUM(D34:E34) -> 0 | G34: =IF(F34=1,"OK","CEK ULANG") -> CEK ULANG | H34: V | I34: =IF(D34=1,"V","0") -> 0
B35: 13 | C35: Saya menyukai olahraga dan saya berpendapat bahwa saya seorang atlet yang baik. | F35: =SUM(D35:E35) -> 0 | G35: =IF(F35=1,"OK","CEK ULANG") -> CEK ULANG | H35: K | I35: =IF(D35=1,"K","0") -> 0
B36: 14 | C36: Enteng/ mudah saja berbicara panjang lebar di telepon dengan teman-teman saya. | F36: =SUM(D36:E36) -> 0 | G36: =IF(F36=1,"OK","CEK ULANG") -> CEK ULANG | H36: A | I36: =IF(D36=1,"A","0") -> 0
B37: 15 | C37: Tanpa musik, hidup ini tidaklah menyenangkan | F37: =SUM(D37:E37) -> 0 | G37: =IF(F37=1,"OK","CEK ULANG") -> CEK ULANG | H37: A | I37: =IF(D37=1,"A","0") -> 0
B38: 16 | C38: Saya sangat senang ada di organisasi-organisasi sosial dan selalu memiliki inisiatif pembicaraan dengan banyak orang. | F38: =SUM(D38:E38) -> 0 | G38: =IF(F38=1,"OK","CEK ULANG") -> CEK ULANG | H38: A | I38: =IF(D38=1,"A","0") -> 0
B39: 17 | C39: Ketika saya melihat suatu objek-objek di kertas, saya dapat dengan mudah apakah objek-objek itu sama tanpa menggunakan alat bantu. | F39: =SUM(D39:E39) -> 0 | G39: =IF(F39=1,"OK","CEK ULANG") -> CEK ULANG | H39: V | I39: =IF(D39=1,"V","0") -> 0
B40: 18 | C40: Saya selalu mengatakan sesuatu seperti, “Aku merasa perlu menangani suatu keluhannya, atau menemukan suatu keluhan. | F40: =SUM(D40:E40) -> 0 | G40: =IF(F40=1,"OK","CEK ULANG") -> CEK ULANG | H40: K | I40: =IF(D40=1,"K","0") -> 0
B41: 19 | C41: Ketika saya ingat kembali suatu pengalaman, saya sering melihat gambaran tentang pengalaman itu di pikiran saya. | F41: =SUM(D41:E41) -> 0 | G41: =IF(F41=1,"OK","CEK ULANG") -> CEK ULANG | H41: V | I41: =IF(D41=1,"V","0") -> 0
B42: 20 | C42: Ketika saya ingat suatu pengalaman, saya kebanyakan mendengar suara itu dan mengatakan pada diri saya sendiri tentang pengalaman itu. | F42: =SUM(D42:E42) -> 0 | G42: =IF(F42=1,"OK","CEK ULANG") -> CEK ULANG | H42: A | I42: =IF(D42=1,"A","0") -> 0
B43: 21 | C43: Bila saya ingat suatu pengalaman, saya sering ingat bagaimana saya meraba-raba tentangnya. | F43: =SUM(D43:E43) -> 0 | G43: =IF(F43=1,"OK","CEK ULANG") -> CEK ULANG | H43: K | I43: =IF(D43=1,"K","0") -> 0
B44: 22 | C44: Saya lebih suka music daripada lukisan | F44: =SUM(D44:E44) -> 0 | G44: =IF(F44=1,"OK","CEK ULANG") -> CEK ULANG | H44: A | I44: =IF(D44=1,"A","0") -> 0
...

Sheet Hasil
B2: RESUME
B3: TES GAYA BELAJAR (VAK)
L4: rvra.consultant@gmail.com
B5: ='Instruksi & Isi Data'!D2 -> Nama | C5: ='Instruksi & Isi Data'!E2 -> 0
B6: ='Instruksi & Isi Data'!D3 -> Usia | C6: ='Instruksi & Isi Data'!E3 -> 0
B7: ='Instruksi & Isi Data'!D4 -> Pendidikan | C7: ='Instruksi & Isi Data'!E4 -> 0
B8: ='Instruksi & Isi Data'!D5 -> Jenis kelamin | C8: ='Instruksi & Isi Data'!E5 -> 0
B9: ='Instruksi & Isi Data'!D6 -> Tanggal | C9: ='Instruksi & Isi Data'!E6 -> 0
B11: TIPE GAYA BELAJAR | C11: INTERPRETASI | N11: NILAI SKOR
B13: VISUAL | C13: Individu dengan tipe ini akan lebih memahami melalui apa yang mereka lihat. Warna, hubungan ruang, potret mental dan gambar menonjol dalam modalitas ini. Adapun beberapa ciri orang dengan tipe belajar visual, yaitu : Rapi, teratur, memperhatikan segala sesuatu dan menjaga penampilan, Berbicara dengan cepat, Perencana dan pengatur jangka panjang yang baik, Pengeja yang baik dan dapat melihat kata-kata yang sebenarnya dalam pikiran mereka, Lebih mengingat apa yang dilihat daripada yang didengar, Mengingat dengan asosiasi visual, Mempunyai masalah untuk mengingat instruksi verbal kecuali jika ditulis dan sering meminta orang lain untuk mengulangi ucapannya. Lebih suka membaca daripada dibacakan dan pembaca yang cepat, Mencoret-coret tanpa arti selama berbicara di telepon atau dalam rapat, Lebih suka melakukan demonstrasi daripada berpidato, Lebih menyukai seni gambar daripada musik, Sering menjawab pertanyaan dengan jawaban yang singkat ya atau tidak, Mengetahui apa yang harus dikatakan, tetapi tidak pandai memilih kata-kata yang tepat, Biasanya tidak terganggu dengan keributan | N13: ='Lembar Soal & Jawaban'!L23 -> 0
B25: AUDITORI | C25: Individu dengan tipe ini akan lebih memahami sesuatu melalui apa yang mereka dengar. Modalitas ini mengakses segala jenis bunyi dan kata. Musik, irama, dialog internal dan suara menonjol pada tipe auditori. Seseorang yang sangat auditori memiliki ciri-ciri sebagai berikut : Suka berbicara kepada diri sendiri saat bekerja, Perhatiannya mudah terpecah dan mudah terganggu oleh keributan, Menggerakkan bibir mereka dan mengucapkan tulisan di buku ketika membaca, Senang membaca dengan keras dan mendengarkan, Dapat mengulangi kembali dan menirukan nada, perubahan dan warna suara, Merasa kesulitan untuk menulis dan lebih suka mengucapkan secara lisan, Berbicara dalam irama yang terpola, Lebih suka musik daripada seni gambar, Belajar dengan mendengarkan dan mengingat apa yang didiskusikan daripada yang dilihat, Suka berbicara, suka berdiskusi dan menjelaskan sesuatu dengan panjang lebar, Lebih suka gurauan lisan daripada membaca komik, Mempunyai masalah dengan pekerjaan-pekerjaan yang melibatkan visualisasi, seperti memotong bagian-bagian hingga sesuai satu sama lain, Lebih pandai mengeja dengan keras daripada menuliskannya, Biasanya pembicara yang fasih | N25: ='Lembar Soal & Jawaban'!L24 -> 0
B37: KINESTETIK | C37: Individu dengan tipe ini belajar melalui gerak, emosi dan sentuhan. Modalitas ini mengakses pada gerakan, koordinasi, irama, tanggapan emosional, dan kenyamanan fisik. Ciri-ciri orang dengan tipe belajar kinestetik yaitu : Berbicara dengan perlahan, Menyentuh orang untuk mendapatkan perhatian mereka saat berbicara, Berdiri berdekatan saat berbicara dengan orang, Selalu berorientasi pada fisik dan banyak bergerak, Belajar melalui memanipulasi dan praktik, Menghafal dengan cara berjalan dan melihat, Menggunakan jari sebagai penunjuk ketika membaca, Banyak menggunakan isyarat tubuh, Tidak dapat diam untuk waktu yang lama, Tidak dapat mengingat geografis, kecuali jika mereka memang telah pernah berada di tempat itu.Menyukai permainan yang menyibukkan, Mencerminkan aksi dengan gerakan tubuh saat membaca, suka mengetuk-ngetuk pena, jari, atau kaki saat mendengarkan, Ingin melakukan segala sesuatu, Kemungkinan tulisannya kurang bagus | N37: ='Lembar Soal & Jawaban'!L25 -> 0
