Workbook

Sheet Skoring
A1: SKORING BIG FIVE INVENTORY
A4: Nama Lengkap | C4: : | D4: DWI AGUNG PRASETYO
A5: Jabatan | C5: : | D5: SPV GA
A6: Usia | C6: : | D6: 35 | E6: tahun
A9: No. | B9: Sangat Sesuai | C9: Sesuai | D9: Netral | E9: Tidak Sesuai | F9: Sangat Tidak Sesuai
A12: 1 | C12: X | G12: =IF(B12="x",5,IF(C12="x",4,IF(D12="x",3,IF(E12="x",2,IF(F12="x",1,0))))) -> 4 | I12: 1
A13: 2 | E13: X | G13: =IF(B13="x",1,IF(C13="x",2,IF(D13="x",3,IF(E13="x",4,IF(F13="x",5,0))))) -> 4 | H13: R | I13: 2
A14: 3 | B14: X | G14: =IF(B14="x",5,IF(C14="x",4,IF(D14="x",3,IF(E14="x",2,IF(F14="x",1,0))))) -> 5 | I14: 3
A15: 4 | D15: X | G15: =IF(B15="x",5,IF(C15="x",4,IF(D15="x",3,IF(E15="x",2,IF(F15="x",1,0))))) -> 3 | I15: 4
A16: 5 | C16: X | G16: =IF(B16="x",5,IF(C16="x",4,IF(D16="x",3,IF(E16="x",2,IF(F16="x",1,0))))) -> 4 | I16: 5
A17: 6 | D17: X | G17: =IF(B17="x",1,IF(C17="x",2,IF(D17="x",3,IF(E17="x",4,IF(F17="x",5,0))))) -> 3 | H17: R | I17: 6
A18: 7 | B18: X | G18: =IF(B18="x",5,IF(C18="x",4,IF(D18="x",3,IF(E18="x",2,IF(F18="x",1,0))))) -> 5 | I18: 7
A19: 8 | E19: X | G19: =IF(B19="x",1,IF(C19="x",2,IF(D19="x",3,IF(E19="x",4,IF(F19="x",5,0))))) -> 4 | H19: R | I19: 8
A20: 9 | C20: X | G20: =IF(B20="x",1,IF(C20="x",2,IF(D20="x",3,IF(E20="x",4,IF(F20="x",5,0))))) -> 2 | H20: R | I20: 9
A21: 10 | C21: X | G21: =IF(B21="x",5,IF(C21="x",4,IF(D21="x",3,IF(E21="x",2,IF(F21="x",1,0))))) -> 4 | I21: 10
A22: 11 | C22: X | G22: =IF(B22="x",5,IF(C22="x",4,IF(D22="x",3,IF(E22="x",2,IF(F22="x",1,0))))) -> 4 | I22: 11
A23: 12 | E23: X | G23: =IF(B23="x",1,IF(C23="x",2,IF(D23="x",3,IF(E23="x",4,IF(F23="x",5,0))))) -> 4 | H23: R | I23: 12
A24: 13 | B24: X | G24: =IF(B24="x",5,IF(C24="x",4,IF(D24="x",3,IF(E24="x",2,IF(F24="x",1,0))))) -> 5 | I24: 13
A25: 14 | D25: X | G25: =IF(B25="x",5,IF(C25="x",4,IF(D25="x",3,IF(E25="x",2,IF(F25="x",1,0))))) -> 3 | I25: 14
A26: 15 | C26: X | G26: =IF(B26="x",5,IF(C26="x",4,IF(D26="x",3,IF(E26="x",2,IF(F26="x",1,0))))) -> 4 | I26: 15
A27: 16 | C27: X | G27: =IF(B27="x",5,IF(C27="x",4,IF(D27="x",3,IF(E27="x",2,IF(F27="x",1,0))))) -> 4 | I27: 16
A28: 17 | B28: X | G28: =IF(B28="x",5,IF(C28="x",4,IF(D28="x",3,IF(E28="x",2,IF(F28="x",1,0))))) -> 5 | I28: 17
A29: 18 | E29: X | G29: =IF(B29="x",1,IF(C29="x",2,IF(D29="x",3,IF(E29="x",4,IF(F29="x",5,0))))) -> 4 | H29: R | I29: 18
A30: 19 | D30: X | G30: =IF(B30="x",5,IF(C30="x",4,IF(D30="x",3,IF(E30="x",2,IF(F30="x",1,0))))) -> 3 | I30: 19
A31: 20 | C31: X | G31: =IF(B31="x",5,IF(C31="x",4,IF(D31="x",3,IF(E31="x",2,IF(F31="x",1,0))))) -> 4 | I31: 20
A32: 21 | E32: X | G32: =IF(B32="x",1,IF(C32="x",2,IF(D32="x",3,IF(E32="x",4,IF(F32="x",5,0))))) -> 4 | H32: R | I32: 21
A33: 22 | B33: X | G33: =IF(B33="x",5,IF(C33="x",4,IF(D33="x",3,IF(E33="x",2,IF(F33="x",1,0))))) -> 5 | I33: 22
A34: 23 | E34: X | G34: =IF(B34="x",1,IF(C34="x",2,IF(D34="x",3,IF(E34="x",4,IF(F34="x",5,0))))) -> 4 | H34: R | I34: 23
A35: 24 | C35: X | G35: =IF(B35="x",1,IF(C35="x",2,IF(D35="x",3,IF(E35="x",4,IF(F35="x",5,0))))) -> 2 | H35: R | I35: 24
A36: 25 | C36: X | G36: =IF(B36="x",5,IF(C36="x",4,IF(D36="x",3,IF(E36="x",2,IF(F36="x",1,0))))) -> 4 | I36: 25
A37: 26 | B37: X | G37: =IF(B37="x",5,IF(C37="x",4,IF(D37="x",3,IF(E37="x",2,IF(F37="x",1,0))))) -> 5 | I37: 26
A38: 27 | E38: X | G38: =IF(B38="x",1,IF(C38="x",2,IF(D38="x",3,IF(E38="x",4,IF(F38="x",5,0))))) -> 4 | H38: R | I38: 27
A39: 28 | B39: X | G39: =IF(B39="x",5,IF(C39="x",4,IF(D39="x",3,IF(E39="x",2,IF(F39="x",1,0))))) -> 5 | I39: 28
A40: 29 | E40: X | G40: =IF(B40="x",5,IF(C40="x",4,IF(D40="x",3,IF(E40="x",2,IF(F40="x",1,0))))) -> 2 | I40: 29
A41: 30 | C41: X | G41: =IF(B41="x",5,IF(C41="x",4,IF(D41="x",3,IF(E41="x",2,IF(F41="x",1,0))))) -> 4 | I41: 30
A42: 31 | D42: X | G42: =IF(B42="x",1,IF(C42="x",2,IF(D42="x",3,IF(E42="x",4,IF(F42="x",5,0))))) -> 3 | H42: R | I42: 31
A43: 32 | B43: X | G43: =IF(B43="x",5,IF(C43="x",4,IF(D43="x",3,IF(E43="x",2,IF(F43="x",1,0))))) -> 5 | I43: 32
A44: 33 | B44: X | G44: =IF(B44="x",5,IF(C44="x",4,IF(D44="x",3,IF(E44="x",2,IF(F44="x",1,0))))) -> 5 | I44: 33
A45: 34 | C45: X | G45: =IF(B45="x",1,IF(C45="x",2,IF(D45="x",3,IF(E45="x",4,IF(F45="x",5,0))))) -> 2 | H45: R | I45: 34
A46: 35 | D46: X | G46: =IF(B46="x",1,IF(C46="x",2,IF(D46="x",3,IF(E46="x",4,IF(F46="x",5,0))))) -> 3 | H46: R | I46: 35
...

Sheet Interpretasi Skor
A1: Interpretasi Skor BFI
A3: Nama Lengkap | C3: : | D3: =Skoring!D4 -> DWI AGUNG PRASETYO
A4: Fak. / Jur. | C4: : | D4: =Skoring!D5 -> SPV GA
A5: Usia | C5: : | D5: =Skoring!D6 -> 35 | E5: tahun
A8: Trait | C8: Skor | D8: Tingkat Skor
A9: Ekstraversion | B9: =Skoring!G58 -> 32 | C9: =Skoring!H58 -> 80 | D9: =IF(C9<=33,"Rendah",IF(C9<=66,"Sedang","Tinggi")) -> Tinggi | F9: =A13 -> Openness | G9: : | H9: =D13 -> Tinggi
A10: Agreeableness | B10: =Skoring!G59 -> 41 | C10: =Skoring!H59 -> 91.111111 | D10: =IF(C10<=33,"Rendah",IF(C10<=66,"Sedang","Tinggi")) -> Tinggi
A11: Conscientiousness | B11: =Skoring!G60 -> 39 | C11: =Skoring!H60 -> 86.666667 | D11: =IF(C11<=33,"Rendah",IF(C11<=66,"Sedang","Tinggi")) -> Tinggi | F11: =A12 -> Neuroticism | G11: : | H11: =D12 -> Sedang
A12: Neuroticism | B12: =Skoring!G61 -> 20 | C12: =Skoring!H61 -> 50 | D12: =IF(C12<=33,"Rendah",IF(C12<=66,"Sedang","Tinggi")) -> Sedang
A13: Openness | B13: =Skoring!G62 -> 37 | C13: =Skoring!H62 -> 74 | D13: =IF(C13<=33,"Rendah",IF(C13<=66,"Sedang","Tinggi")) -> Tinggi | F13: =A11 -> Conscientiousness | G13: : | H13: =D11 -> Tinggi
F15: =A10 -> Agreeableness | G15: : | H15: =D10 -> Tinggi
F17: =A9 -> Ekstraversion | G17: : | H17: =D9 -> Tinggi
A20: Interpretasi :
A21: =IF(D9="Tinggi","- Memiliki tingkat motivasi yang tinggi dalam bergaul, menjalin hubungan dengan sesama dan dominan dalam lingkungannya .",IF(D9="Rendah","- Cenderung bersikap tenang dan menarik diri dari lingkungannya.","- Tidak terlalu menonjol dalam menjalin hubungan dengan sesama meskipun tidak menarik diri dari lingkungannya.")) -> - Memiliki tingkat motivasi yang tinggi dalam bergaul, menjalin hubungan dengan sesama dan dominan dalam lingkungannya .
A22: =IF(D10="Tinggi","- Ramah, memiliki kepribadian yang selalu mengalah, menghindari konflik dan memiliki kecenderungan untuk mengikuti orang lain.",IF(D10="Rendah","- Cenderung untuk lebih agresif dan kurang kooperatif.","- Tidak terlalu agresif meskipun tidak selalu mengalah pada orang lain.")) -> - Ramah, memiliki kepribadian yang selalu mengalah, menghindari konflik dan memiliki kecenderungan untuk mengikuti orang lain.
A23: =IF(D11="Tinggi","- Memiliki kontrol terhadap lingkungan sosial, berpikir sebelum bertindak, menunda kepuasan, mengikuti peraturan dan norma, terencana, terorganisir, dan memprioritaskan tugas.",IF(D11="Rendah","- Ceroboh, tidak terarah serta mudah teralih perhatiannya.","- Terkadang ceroboh, namun dapat mengikuti peraturan dan norma.")) -> - Memiliki kontrol terhadap lingkungan sosial, berpikir sebelum bertindak, menunda kepuasan, mengikuti peraturan dan norma, terencana, terorganisir, dan memprioritaskan tugas.
A24: =IF(D12="Tinggi","- Memiliki kesulitan dalam menjalin hubungan dan berkomitmen, juga memiliki tingkat self esteem yang rendah.",IF(D12="Rendah","- Cenderung lebih gembira dan puas terhadap hidup.","- Dapat mengendalikan diri meskipun pada saat cemas.")) -> - Dapat mengendalikan diri meskipun pada saat cemas.
A25: =IF(D13="Tinggi","- Mudah bertoleransi, memiliki kapasitas untuk menyerap informasi, menjadi sangat fokus dan mampu untuk waspada pada berbagai perasaan, pemikiran dan impulsivitas.",IF(D13="Rendah","- Mempunyai pemikiran yang sempit, konservatif dan tidak menyukai adanya perubahan.","- Memiliki pemikiran yang cukup terbuka dan tidak bermasalah terhadap perubahan.")) -> - Mudah bertoleransi, memiliki kapasitas untuk menyerap informasi, menjadi sangat fokus dan mampu untuk waspada pada berbagai perasaan, pemikiran dan impulsivitas.
A29: Standar Kompetensi Psikologis :
A31: Trait | D31: Ekspektasi | E31: Skoring
A32: =F9 -> Openness | D32: Tinggi | E32: =H9 -> Tinggi | F32: =IF(AND(D32="Tinggi",E32="Tinggi"),"Oke","-") -> Oke
A34: =F11 -> Neuroticism | D34: Sedang | E34: =H11 -> Sedang | F34: =IF(AND(D34="Sedang",E34="Sedang"),"Oke",IF(AND(D34="Sedang",E34="Rendah"),"Oke","-")) -> Oke
A36: =F13 -> Conscientiousness | D36: Sedang | E36: =H13 -> Tinggi | F36: =IF(AND(D36="Sedang",E36="Sedang"),"Oke",IF(AND(D36="Sedang",E36="Tinggi"),"Oke","-")) -> Oke
A38: =F15 -> Agreeableness | D38: Tinggi | E38: =H15 -> Tinggi | F38: =IF(AND(D38="Tinggi",E38="Tinggi"),"Oke","-") -> Oke
A40: =F17 -> Ekstraversion | D40: Sedang | E40: =H17 -> Tinggi | F40: =IF(AND(D40="Sedang",E40="Sedang"),"Oke",IF(AND(D40="Sedang",E40="Tinggi"),"Oke","-")) -> Oke
