Workbook

Sheet Soal
B1: Counterproductive Behavior Index (CBI)
B3: Tanggal isi | C3: : | D3: 44606
B4: Nama | C4: : | D4: TES
B5: Jenis Kelamin | C5: : | D5: LAKI
B6: Tanggal Lahir | C6: : | D6: 36533
B7: Usia | C7: : | D7: 22
B8: Pendidikan | C8: : | D8: smu
B10: PEDOMAN :
B12: Pada buku ini tersedia 140 pernyataan tentang tindakan yang mungkin anda lakukan dalam tugas anda di perusahaan.
B13: Tugas anda adalah menjawab seluruh pernyataan (tidak ada yang dilewat) dengan cara memberi tanda silang (x) di lembar jawaban :
B14: - Huruf B (Benar) jika pernyataan tersebut sesuai dengan apa yang anda pikirkan atau rasakan.
B15: - Huruf S (Salah) jika pernyataan tersebut tidak sesuai dengan apa yang anda pikirkan atau rasakan.
B16: Waktu yang disediakan hanya 15 menit. Tidak ada penambahan waktu jika belum selesai. Karena itu bekerjalah seefisien mungkin.
B17: lni bukan suatu Tes. Apapun yang anda pilih, hendaknya sungguh - sungguh menggambarkan diri Anda.
B19: PERNYATAAN: | M19: B | N19: S
A20: 1 | B20: 1. Biasanya saya mencoba menyusun sebuah rencana untuk menyelesaikan pekerjaan saya. | N20: x | P20: =IF(M20="X",1,"0") -> 0 | Q20: =IF(N20="X",1,"0") -> 1
A21: =A20+1 -> 2 | B21: 2. Saya bekerja dengan sangat hati – hati. | N21: x | P21: =IF(M21="X",1,"0") -> 0 | Q21: =IF(N21="X",1,"0") -> 1
A22: =A21+1 -> 3 | B22: 3. Ketika saya sedang marah, tak seorang pun yang dapat menebak apa yang akan saya lakukan. | N22: x | P22: =IF(M22="X",1,"0") -> 0 | Q22: =IF(N22="X",1,"0") -> 1
A23: =A22+1 -> 4 | B23: 4. Saya sulit untuk mengendalikan emosi ketika terjebak dalam kemacetan lalulintas. | N23: x | P23: =IF(M23="X",1,"0") -> 0 | Q23: =IF(N23="X",1,"0") -> 1
A24: =A23+1 -> 5 | B24: 5. Setidaknya sekali dalam hidup saya, pernah meminum minuman beralkohol hingga mengganggu pekerjaan saya di tempat kerja. | N24: x | P24: =IF(M24="X",1,"0") -> 0 | Q24: =IF(N24="X",1,"0") -> 1
A25: =A24+1 -> 6 | B25: 6. Saya menggunakan narkoba akhir akhir ini. | N25: x | P25: =IF(M25="X",1,"0") -> 0 | Q25: =IF(N25="X",1,"0") -> 1
A26: =A25+1 -> 7 | B26: 7. Kebanyakan orang mempunyai alasan yang dapat diterima untuk dapat kembali dipekerjakan di perusahaan. | N26: x | P26: =IF(M26="X",1,"0") -> 0 | Q26: =IF(N26="X",1,"0") -> 1
A27: =A26+1 -> 8 | B27: 8. Kebanyakan orang menggunakan ijin sakit untuk bisa keluar dari tempat kerja atau dengan tujuan lain. | N27: x | P27: =IF(M27="X",1,"0") -> 0 | Q27: =IF(N27="X",1,"0") -> 1
A28: =A27+1 -> 9 | B28: 9. Saya tidak akan menggunakan komputer kantor untuk mengirim dan menerima email jika hal tersebut melanggar peraturan perusahan. | N28: x | P28: =IF(M28="X",1,"0") -> 0 | Q28: =IF(N28="X",1,"0") -> 1
A29: =A28+1 -> 10 | B29: 10. Saya secara teratur mengunjungi situs – situs yang mengandung pornografi di kantor. | N29: x | P29: =IF(M29="X",1,"0") -> 0 | Q29: =IF(N29="X",1,"0") -> 1
A30: =A29+1 -> 11 | B30: 11. Saya sering memeluk teman (lawan jenis) sekantor yang dekat dengan saya. | N30: x | P30: =IF(M30="X",1,"0") -> 0 | Q30: =IF(N30="X",1,"0") -> 1
A31: =A30+1 -> 12 | B31: 12. Saya sering menceritakan lelucon yang menyinggung soal seksualitas di kantor. | N31: x | P31: =IF(M31="X",1,"0") -> 0 | Q31: =IF(N31="X",1,"0") -> 1
A32: =A31+1 -> 13 | B32: 13. Saya tidak pernah bertindak tanpa berpikir sebelumnya. | N32: x | P32: =IF(M32="X",1,"0") -> 0 | Q32: =IF(N32="X",1,"0") -> 1
... A159: =A158+1 -> 140 | B159: 140. Saya tidak pernah mendengarkan lelucon yang berbau seks. | N159: x | P159: =IF(M159="X",1,"0") -> 0 | Q159: =IF(N159="X",1,"0") -> 1
L160: Harus pass di 140 | N160: =Q160 -> 140 | Q160: =SUM(P20:Q159) -> 140
L161: =IF(AND(N160=140),"Wah hebat, pass 140","Waduh cek lagi, tidak sama 140 !!") -> Wah hebat, pass 140
B162: ===>>> TERIMA KASIH <<<===

Sheet Psikogram
B1: COUNTERPRODUCTIVE BEHAVIOR INDEX (CBI) PROFILE | R1: “RAHASIA”
B3: =Interpretasi!A3 -> Tanggal isi | C3: =Interpretasi!B3 -> : | D3: =Interpretasi!C3 -> 44606
B4: =Interpretasi!A4 -> Nama | C4: =Interpretasi!B4 -> : | D4: =Interpretasi!C4 -> TES
B5: =Interpretasi!A5 -> Jenis Kelamin | C5: =Interpretasi!B5 -> : | D5: =Interpretasi!C5 -> LAKI
B6: =Interpretasi!A6 -> Tanggal Lahir | C6: =Interpretasi!B6 -> : | D6: =Interpretasi!C6 -> 36533
B7: =Interpretasi!A7 -> Usia | C7: =Interpretasi!B7 -> : | D7: =Interpretasi!C7 -> 22
B8: =Interpretasi!A8 -> Pendidikan | C8: =Interpretasi!B8 -> : | D8: =Interpretasi!C8 -> smu
B10: Test Validity Concerns | C10: 0 | E10: =C10+1 -> 1 | G10: =E10+1 -> 2 | I10: =G10+1 -> 3 | K10: =I10+1 -> 4 | M10: =K10+1 -> 5 | O10: =M10+1 -> 6 | Q10: =O10+1 -> 7 | S10: =Q10+1 -> 8 | U10: =S10+1 -> 9 | W10: =U10+1 -> 10 | Y10: =W10+1 -> 11 | AA10: =Y10+1 -> 12 | AC10: =AA10+1 -> 13 | AE10: =AC10+1 -> 14 | AG10: =AE10+1 -> 15 | AI10: =AG10+1 -> 16 | AK10: =AI10+1 -> 17 | AM10: =AK10+1 -> 18 | AO10: =AM10+1 -> 19 | AQ10: =AO10+1 -> 20 | AS10: Test Validity Concerns
B11: Good Impression GI Score | C11: =IF(Interpretasi!K52=0,"X","-") -> - | E11: =IF(Interpretasi!K52=1,"X","-") -> - | G11: =IF(Interpretasi!K52=2,"X","-") -> - | I11: =IF(Interpretasi!K52=3,"X","-") -> - | K11: =IF(Interpretasi!K52=4,"X","-") -> - | M11: =IF(Interpretasi!K52=5,"X","-") -> X | O11: =IF(Interpretasi!K52=6,"X","-") -> - | Q11: =IF(Interpretasi!K52=7,"X","-") -> - | S11: =IF(Interpretasi!K52=8,"X","-") -> - | U11: =IF(Interpretasi!K52=9,"X","-") -> - | W11: =IF(Interpretasi!K52=10,"X","-") -> - | Y11: =IF(Interpretasi!K52=11,"X","-") -> - | AA11: =IF(Interpretasi!K52=12,"X","-") -> - | AC11: =IF(Interpretasi!K52=13,"X","-") -> - | AE11: =IF(Interpretasi!K52=14,"X","-") -> - | AG11: =IF(Interpretasi!K52=15,"X","-") -> - | AI11: =IF(Interpretasi!K52=16,"X","-") -> - | AK11: =IF(Interpretasi!K52=17,"X","-") -> - | AM11: =IF(Interpretasi!K52=18,"X","-") -> - | AO11: =IF(Interpretasi!K52=19,"X","-") -> - | AQ11: =IF(Interpretasi!K52=20,"X","-") -> - | AS11: Good Impression GI Score
B13: Scale | C13: Dependability (Dp) Concerns | I13: Aggression (Ag) Concerns | O13: Substance Abuse(SA) Concerns | U13: Honesty (Hn) Concerns | AC13: Computer Abuse(CA) Concerns | AK13: Sexual Harrassment(SH) Concerns | AS13: Scale
B14: Score | AS14: Score
B15: 20 | C15: =IF(Interpretasi!K46=20,"X","-") -> - | I15: =IF(Interpretasi!K47=20,"X","-") -> - | O15: =IF(Interpretasi!K48=20,"X","-") -> - | U15: =IF(Interpretasi!K49=20,"X","-") -> - | AC15: =IF(Interpretasi!K50=20,"X","-") -> - | AK15: =IF(Interpretasi!K51=20,"X","-") -> - | AS15: 20
B16: =B15-1 -> 19 | C16: =IF(Interpretasi!K46=19,"X","-") -> - | I16: =IF(Interpretasi!K47=19,"X","-") -> - | O16: =IF(Interpretasi!K48=19,"X","-") -> - | U16: =IF(Interpretasi!K49=19,"X","-") -> - | AC16: =IF(Interpretasi!K50=19,"X","-") -> - | AK16: =IF(Interpretasi!K51=19,"X","-") -> - | AS16: =AS15-1 -> 19
B17: =B16-1 -> 18 | C17: =IF(Interpretasi!K46=18,"X","-") -> - | I17: =IF(Interpretasi!K47=18,"X","-") -> - | O17: =IF(Interpretasi!K48=18,"X","-") -> - | U17: =IF(Interpretasi!K49=18,"X","-") -> - | AC17: =IF(Interpretasi!K50=18,"X","-") -> - | AK17: =IF(Interpretasi!K51=18,"X","-") -> - | AS17: =AS16-1 -> 18
B18: =B17-1 -> 17 | C18: =IF(Interpretasi!K46=17,"X","-") -> - | I18: =IF(Interpretasi!K47=17,"X","-") -> - | O18: =IF(Interpretasi!K48=17,"X","-") -> - | U18: =IF(Interpretasi!K49=17,"X","-") -> - | AC18: =IF(Interpretasi!K50=17,"X","-") -> - | AK18: =IF(Interpretasi!K51=17,"X","-") -> - | AS18: =AS17-1 -> 17
B19: =B18-1 -> 16 | C19: =IF(Interpretasi!K46=16,"X","-") -> - | I19: =IF(Interpretasi!K47=16,"X","-") -> - | O19: =IF(Interpretasi!K48=16,"X","-") -> - | U19: =IF(Interpretasi!K49=16,"X","-") -> - | AC19: =IF(Interpretasi!K50=16,"X","-") -> - | AK19: =IF(Interpretasi!K51=16,"X","-") -> - | AS19: =AS18-1 -> 16
B20: =B19-1 -> 15 | C20: =IF(Interpretasi!K46=15,"X","-") -> X | I20: =IF(Interpretasi!K47=15,"X","-") -> - | O20: =IF(Interpretasi!K48=15,"X","-") -> - | U20: =IF(Interpretasi!K49=15,"X","-") -> - | AC20: =IF(Interpretasi!K50=15,"X","-") -> - | AK20: =IF(Interpretasi!K51=15,"X","-") -> - | AS20: =AS19-1 -> 15
B21: =B20-1 -> 14 | C21: =IF(Interpretasi!K46=14,"X","-") -> - | I21: =IF(Interpretasi!K47=14,"X","-") -> - | O21: =IF(Interpretasi!K48=14,"X","-") -> - | U21: =IF(Interpretasi!K49=14,"X","-") -> - | AC21: =IF(Interpretasi!K50=14,"X","-") -> - | AK21: =IF(Interpretasi!K51=14,"X","-") -> - | AS21: =AS20-1 -> 14
B22: =B21-1 -> 13 | C22: =IF(Interpretasi!K46=13,"X","-") -> - | I22: =IF(Interpretasi!K47=13,"X","-") -> - | O22: =IF(Interpretasi!K48=13,"X","-") -> - | U22: =IF(Interpretasi!K49=13,"X","-") -> - | AC22: =IF(Interpretasi!K50=13,"X","-") -> - | AK22: =IF(Interpretasi!K51=13,"X","-") -> - | AS22: =AS21-1 -> 13
B23: =B22-1 -> 12 | C23: =IF(Interpretasi!K46=12,"X","-") -> - | I23: =IF(Interpretasi!K47=12,"X","-") -> - | O23: =IF(Interpretasi!K48=12,"X","-") -> - | U23: =IF(Interpretasi!K49=12,"X","-") -> - | AC23: =IF(Interpretasi!K50=12,"X","-") -> - | AK23: =IF(Interpretasi!K51=12,"X","-") -> - | AS23: =AS22-1 -> 12
B24: =B23-1 -> 11 | C24: =IF(Interpretasi!K46=11,"X","-") -> - | I24: =IF(Interpretasi!K47=11,"X","-") -> - | O24: =IF(Interpretasi!K48=11,"X","-") -> - | U24: =IF(Interpretasi!K49=11,"X","-") -> - | AC24: =IF(Interpretasi!K50=11,"X","-") -> - | AK24: =IF(Interpretasi!K51=11,"X","-") -> - | AS24: =AS23-1 -> 11
B25: =B24-1 -> 10 | C25: =IF(Interpretasi!K46=10,"X","-") -> - | I25: =IF(Interpretasi!K47=10,"X","-") -> - | O25: =IF(Interpretasi!K48=10,"X","-") -> - | U25: =IF(Interpretasi!K49=10,"X","-") -> - | AC25: =IF(Interpretasi!K50=10,"X","-") -> - | AK25: =IF(Interpretasi!K51=10,"X","-") -> - | AS25: =AS24-1 -> 10
B26: =B25-1 -> 9 | C26: =IF(Interpretasi!K46=9,"X","-") -> - | I26: =IF(Interpretasi!K47=9,"X","-") -> - | O26: =IF(Interpretasi!K48=9,"X","-") -> - | U26: =IF(Interpretasi!K49=9,"X","-") -> - | AC26: =IF(Interpretasi!K50=9,"X","-") -> - | AK26: =IF(Interpretasi!K51=9,"X","-") -> - | AS26: =AS25-1 -> 9
B27: =B26-1 -> 8 | C27: =IF(Interpretasi!K46=8,"X","-") -> - | I27: =IF(Interpretasi!K47=8,"X","-") -> - | O27: =IF(Interpretasi!K48=8,"X","-") -> X | U27: =IF(Interpretasi!K49=8,"X","-") -> - | AC27: =IF(Interpretasi!K50=8,"X","-") -> - | AK27: =IF(Interpretasi!K51=8,"X","-") -> - | AS27: =AS26-1 -> 8
B28: =B27-1 -> 7 | C28: =IF(Interpretasi!K46=7,"X","-") -> - | I28: =IF(Interpretasi!K47=7,"X","-") -> - | O28: =IF(Interpretasi!K48=7,"X","-") -> - | U28: =IF(Interpretasi!K49=7,"X","-") -> - | AC28: =IF(Interpretasi!K50=7,"X","-") -> - | AK28: =IF(Interpretasi!K51=7,"X","-") -> - | AS28: =AS27-1 -> 7
B29: =B28-1 -> 6 | C29: =IF(Interpretasi!K46=6,"X","-") -> - | I29: =IF(Interpretasi!K47=6,"X","-") -> - | O29: =IF(Interpretasi!K48=6,"X","-") -> - | U29: =IF(Interpretasi!K49=6,"X","-") -> - | AC29: =IF(Interpretasi!K50=6,"X","-") -> - | AK29: =IF(Interpretasi!K51=6,"X","-") -> - | AS29: =AS28-1 -> 6
B30: =B29-1 -> 5 | C30: =IF(Interpretasi!K46=5,"X","-") -> - | I30: =IF(Interpretasi!K47=5,"X","-") -> - | O30: =IF(Interpretasi!K48=5,"X","-") -> - | U30: =IF(Interpretasi!K49=5,"X","-") -> - | AC30: =IF(Interpretasi!K50=5,"X","-") -> X | AK30: =IF(Interpretasi!K51=5,"X","-") -> - | AS30: =AS29-1 -> 5
B31: =B30-1 -> 4 | C31: =IF(Interpretasi!K46=4,"X","-") -> - | I31: =IF(Interpretasi!K47=4,"X","-") -> - | O31: =IF(Interpretasi!K48=4,"X","-") -> - | U31: =IF(Interpretasi!K49=4,"X","-") -> - | AC31: =IF(Interpretasi!K50=4,"X","-") -> - | AK31: =IF(Interpretasi!K51=4,"X","-") -> - | AS31: =AS30-1 -> 4
B32: =B31-1 -> 3 | C32: =IF(Interpretasi!K46=3,"X","-") -> - | I32: =IF(Interpretasi!K47=3,"X","-") -> - | O32: =IF(Interpretasi!K48=3,"X","-") -> - | U32: =IF(Interpretasi!K49=3,"X","-") -> - | AC32: =IF(Interpretasi!K50=3,"X","-") -> - | AK32: =IF(Interpretasi!K51=3,"X","-") -> - | AS32: =AS31-1 -> 3
B33: =B32-1 -> 2 | C33: =IF(Interpretasi!K46=2,"X","-") -> - | I33: =IF(Interpretasi!K47=2,"X","-") -> - | O33: =IF(Interpretasi!K48=2,"X","-") -> - | U33: =IF(Interpretasi!K49=2,"X","-") -> - | AC33: =IF(Interpretasi!K50=2,"X","-") -> - | AK33: =IF(Interpretasi!K51=2,"X","-") -> - | AS33: =AS32-1 -> 2
B34: =B33-1 -> 1 | C34: =IF(Interpretasi!K46=1,"X","-") -> - | I34: =IF(Interpretasi!K47=1,"X","-") -> - | O34: =IF(Interpretasi!K48=1,"X","-") -> - | U34: =IF(Interpretasi!K49=1,"X","-") -> X | AC34: =IF(Interpretasi!K50=1,"X","-") -> - | AK34: =IF(Interpretasi!K51=1,"X","-") -> - | AS34: =AS33-1 -> 1
B35: =B34-1 -> 0 | C35: =IF(Interpretasi!K46=0,"X","-") -> - | I35: =IF(Interpretasi!K47=0,"X","-") -> X | O35: =IF(Interpretasi!K48=0,"X","-") -> - | U35: =IF(Interpretasi!K49=0,"X","-") -> - | AC35: =IF(Interpretasi!K50=0,"X","-") -> - | AK35: =IF(Interpretasi!K51=0,"X","-") -> X | AS35: =AS34-1 -> 0
B36: Scale | C36: Dependability (Dp) Concerns | I36: Aggression (Ag) Concerns | O36: Substance Abuse(SA) Concerns | U36: Honesty (Hn) Concerns | AC36: Computer Abuse(CA) Concerns | AK36: Sexual Harrassment(SH) Concerns | AS36: Scale
B37: Score | AS37: Score
B40: Overall | C40: 0-38 | I40: 39-59 | O40: 60-120 | U40: Overall
B41: Concerns Score | C41: =IF(AND(Interpretasi!K53>=0,Interpretasi!K53<=38),"X","-") -> X | I41: =IF(AND(Interpretasi!K53>=39,Interpretasi!K53<=59),"X","-") -> - | O41: =IF(AND(Interpretasi!K53>=60,Interpretasi!K53<=120),"X","-") -> - | U41: Concerns Score

Sheet Interpretasi
A1: =Psikogram!B1 -> COUNTERPRODUCTIVE BEHAVIOR INDEX (CBI) PROFILE | R1: “RAHASIA”
A3: =Soal!B3 -> Tanggal isi | B3: =Soal!C3 -> : | C3: =Soal!D3 -> 44606
A4: =Soal!B4 -> Nama | B4: =Soal!C4 -> : | C4: =Soal!D4 -> TES
A5: =Soal!B5 -> Jenis Kelamin | B5: =Soal!C5 -> : | C5: =Soal!D5 -> LAKI | AT5: 1 | AU5: =Soal!M20 -> 0 | AV5: =Soal!N20 -> x
A6: =Soal!B6 -> Tanggal Lahir | B6: =Soal!C6 -> : | C6: =Soal!D6 -> 36533 | AT6: =AT5+1 -> 2 | AU6: =Soal!M21 -> 0 | AV6: =Soal!N21 -> x
A7: =Soal!B7 -> Usia | B7: =Soal!C7 -> : | C7: =Soal!D7 -> 22 | AT7: =AT6+1 -> 3 | AU7: =Soal!M22 -> 0 | AV7: =Soal!N22 -> x
A8: =Soal!B8 -> Pendidikan | B8: =Soal!C8 -> : | C8: =Soal!D8 -> smu | AT8: =AT7+1 -> 4 | AU8: =Soal!M23 -> 0 | AV8: =Soal!N23 -> x
AT9: =AT8+1 -> 5 | AU9: =Soal!M24 -> 0 | AV9: =Soal!N24 -> x
B10: No | C10: B | D10: S | F10: No | G10: B | H10: S | J10: No | K10: B | L10: S | N10: No | O10: B | P10: S | R10: No | S10: B | T10: S | V10: No | W10: B | X10: S | Z10: No | AA10: B | AB10: S | AD10: No | AE10: B | AF10: S | AH10: No | AI10: B | AJ10: S | AL10: No | AM10: B | AN10: S | AT10: =AT9+1 -> 6 | AU10: =Soal!M25 -> 0 | AV10: =Soal!N25 -> x
B11: 1 | C11: =IF(C28="X",1,"0") -> 0 | D11: =IF(D28="X",1,"0") -> 1 | F11: 15 | G11: =IF(G28="X",1,"0") -> 0 | H11: =IF(H28="X",1,"0") -> 1 | J11: 29 | K11: =IF(K28="X",1,"0") -> 0 | L11: =IF(L28="X",1,"0") -> 1 | N11: 43 | O11: =IF(O28="X",1,"0") -> 0 | P11: =IF(P28="X",1,"0") -> 1 | R11: 57 | S11: =IF(S28="X",1,"0") -> 0 | T11: =IF(T28="X",1,"0") -> 1 | V11: 71 | W11: =IF(W28="X",1,"0") -> 0 | X11: =IF(X28="X",1,"0") -> 1 | Z11: 85 | AA11: =IF(AA28="X",1,"0") -> 0 | AB11: =IF(AB28="X",1,"0") -> 1 | AD11: 99 | AE11: =IF(AE28="X",1,"0") -> 0 | AF11: =IF(AF28="X",1,"0") -> 1 | AH11: 113 | AI11: =IF(AI28="X",1,"0") -> 0 | AJ11: =IF(AJ28="X",1,"0") -> 1 | AL11: 127 | AM11: =IF(AM28="X",1,"0") -> 0 | AN11: =IF(AN28="X",1,"0") -> 1 | AP11: Dp | AQ11: =D11+H11+L11+O11+T11+W11+AB11+AF11+AI11+AN11+D12+H12+K12+O12+T12+X12+AB12+AF12+AJ12+AN12 -> 15 | AT11: =AT10+1 -> 7 | AU11: =Soal!M26 -> 0 | AV11: =Soal!N26 -> x
B12: =B11+1 -> 2 | C12: =IF(C29="X",1,"0") -> 0 | D12: =IF(D29="X",1,"0") -> 1 | F12: =F11+1 -> 16 | G12: =IF(G29="X",1,"0") -> 0 | H12: =IF(H29="X",1,"0") -> 1 | J12: =J11+1 -> 30 | K12: =IF(K29="X",1,"0") -> 0 | L12: =IF(L29="X",1,"0") -> 1 | N12: =N11+1 -> 44 | O12: =IF(O29="X",1,"0") -> 0 | P12: =IF(P29="X",1,"0") -> 1 | R12: =R11+1 -> 58 | S12: =IF(S29="X",1,"0") -> 0 | T12: =IF(T29="X",1,"0") -> 1 | V12: =V11+1 -> 72 | W12: =IF(W29="X",1,"0") -> 0 | X12: =IF(X29="X",1,"0") -> 1 | Z12: =Z11+1 -> 86 | AA12: =IF(AA29="X",1,"0") -> 0 | AB12: =IF(AB29="X",1,"0") -> 1 | AD12: =AD11+1 -> 100 | AE12: =IF(AE29="X",1,"0") -> 0 | AF12: =IF(AF29="X",1,"0") -> 1 | AH12: =AH11+1 -> 114 | AI12: =IF(AI29="X",1,"0") -> 0 | AJ12: =IF(AJ29="X",1,"0") -> 1 | AL12: =AL11+1 -> 128 | AM12: =IF(AM29="X",1,"0") -> 0 | AN12: =IF(AN29="X",1,"0") -> 1 | AT12: =AT11+1 -> 8 | AU12: =Soal!M27 -> 0 | AV12: =Soal!N27 -> x
B13: =B12+1 -> 3 | C13: =IF(C30="X",1,"0") -> 0 | D13: =IF(D30="X",1,"0") -> 1 | F13: =F12+1 -> 17 | G13: =IF(G30="X",1,"0") -> 0 | H13: =IF(H30="X",1,"0") -> 1 | J13: =J12+1 -> 31 | K13: =IF(K30="X",1,"0") -> 0 | L13: =IF(L30="X",1,"0") -> 1 | N13: =N12+1 -> 45 | O13: =IF(O30="X",1,"0") -> 0 | P13: =IF(P30="X",1,"0") -> 1 | R13: =R12+1 -> 59 | S13: =IF(S30="X",1,"0") -> 0 | T13: =IF(T30="X",1,"0") -> 1 | V13: =V12+1 -> 73 | W13: =IF(W30="X",1,"0") -> 0 | X13: =IF(X30="X",1,"0") -> 1 | Z13: =Z12+1 -> 87 | AA13: =IF(AA30="X",1,"0") -> 0 | AB13: =IF(AB30="X",1,"0") -> 1 | AD13: =AD12+1 -> 101 | AE13: =IF(AE30="X",1,"0") -> 0 | AF13: =IF(AF30="X",1,"0") -> 1 | AH13: =AH12+1 -> 115 | AI13: =IF(AI30="X",1,"0") -> 0 | AJ13: =IF(AJ30="X",1,"0") -> 1 | AL13: =AL12+1 -> 129 | AM13: =IF(AM30="X",1,"0") -> 0 | AN13: =IF(AN30="X",1,"0") -> 1 | AP13: Ag | AQ13: =C13+C14+G13+G14+K13+K14+O13+O14+S13+S14+W13+W14+AA13+AA14+AE13+AE14+AI13+AI14+AM13+AM14 -> 0 | AT13: =AT12+1 -> 9 | AU13: =Soal!M28 -> 0 | AV13: =Soal!N28 -> x
B14: =B13+1 -> 4 | C14: =IF(C31="X",1,"0") -> 0 | D14: =IF(D31="X",1,"0") -> 1 | F14: =F13+1 -> 18 | G14: =IF(G31="X",1,"0") -> 0 | H14: =IF(H31="X",1,"0") -> 1 | J14: =J13+1 -> 32 | K14: =IF(K31="X",1,"0") -> 0 | L14: =IF(L31="X",1,"0") -> 1 | N14: =N13+1 -> 46 | O14: =IF(O31="X",1,"0") -> 0 | P14: =IF(P31="X",1,"0") -> 1 | R14: =R13+1 -> 60 | S14: =IF(S31="X",1,"0") -> 0 | T14: =IF(T31="X",1,"0") -> 1 | V14: =V13+1 -> 74 | W14: =IF(W31="X",1,"0") -> 0 | X14: =IF(X31="X",1,"0") -> 1 | Z14: =Z13+1 -> 88 | AA14: =IF(AA31="X",1,"0") -> 0 | AB14: =IF(AB31="X",1,"0") -> 1 | AD14: =AD13+1 -> 102 | AE14: =IF(AE31="X",1,"0") -> 0 | AF14: =IF(AF31="X",1,"0") -> 1 | AH14: =AH13+1 -> 116 | AI14: =IF(AI31="X",1,"0") -> 0 | AJ14: =IF(AJ31="X",1,"0") -> 1 | AL14: =AL13+1 -> 130 | AM14: =IF(AM31="X",1,"0") -> 0 | AN14: =IF(AN31="X",1,"0") -> 1 | AT14: =AT13+1 -> 10 | AU14: =Soal!M29 -> 0 | AV14: =Soal!N29 -> x
B15: =B14+1 -> 5 | C15: =IF(C32="X",1,"0") -> 0 | D15: =IF(D32="X",1,"0") -> 1 | F15: =F14+1 -> 19 | G15: =IF(G32="X",1,"0") -> 0 | H15: =IF(H32="X",1,"0") -> 1 | J15: =J14+1 -> 33 | K15: =IF(K32="X",1,"0") -> 0 | L15: =IF(L32="X",1,"0") -> 1 | N15: =N14+1 -> 47 | O15: =IF(O32="X",1,"0") -> 0 | P15: =IF(P32="X",1,"0") -> 1 | R15: =R14+1 -> 61 | S15: =IF(S32="X",1,"0") -> 0 | T15: =IF(T32="X",1,"0") -> 1 | V15: =V14+1 -> 75 | W15: =IF(W32="X",1,"0") -> 0 | X15: =IF(X32="X",1,"0") -> 1 | Z15: =Z14+1 -> 89 | AA15: =IF(AA32="X",1,"0") -> 0 | AB15: =IF(AB32="X",1,"0") -> 1 | AD15: =AD14+1 -> 103 | AE15: =IF(AE32="X",1,"0") -> 0 | AF15: =IF(AF32="X",1,"0") -> 1 | AH15: =AH14+1 -> 117 | AI15: =IF(AI32="X",1,"0") -> 0 | AJ15: =IF(AJ32="X",1,"0") -> 1 | AL15: =AL14+1 -> 131 | AM15: =IF(AM32="X",1,"0") -> 0 | AN15: =IF(AN32="X",1,"0") -> 1 | AP15: Sa | AQ15: =C15+C16+H15+G16+K15+K16+O15+O16+T15+T16+X15+W16+AA15+AB16+AF15+AF16+AJ15+AI16+AM15+AM16 -> 8 | AT15: =AT14+1 -> 11 | AU15: =Soal!M30 -> 0 | AV15: =Soal!N30 -> x
B16: =B15+1 -> 6 | C16: =IF(C33="X",1,"0") -> 0 | D16: =IF(D33="X",1,"0") -> 1 | F16: =F15+1 -> 20 | G16: =IF(G33="X",1,"0") -> 0 | H16: =IF(H33="X",1,"0") -> 1 | J16: =J15+1 -> 34 | K16: =IF(K33="X",1,"0") -> 0 | L16: =IF(L33="X",1,"0") -> 1 | N16: =N15+1 -> 48 | O16: =IF(O33="X",1,"0") -> 0 | P16: =IF(P33="X",1,"0") -> 1 | R16: =R15+1 -> 62 | S16: =IF(S33="X",1,"0") -> 0 | T16: =IF(T33="X",1,"0") -> 1 | V16: =V15+1 -> 76 | W16: =IF(W33="X",1,"0") -> 0 | X16: =IF(X33="X",1,"0") -> 1 | Z16: =Z15+1 -> 90 | AA16: =IF(AA33="X",1,"0") -> 0 | AB16: =IF(AB33="X",1,"0") -> 1 | AD16: =AD15+1 -> 104 | AE16: =IF(AE33="X",1,"0") -> 0 | AF16: =IF(AF33="X",1,"0") -> 1 | AH16: =AH15+1 -> 118 | AI16: =IF(AI33="X",1,"0") -> 0 | AJ16: =IF(AJ33="X",1,"0") -> 1 | AL16: =AL15+1 -> 132 | AM16: =IF(AM33="X",1,"0") -> 0 | AN16: =IF(AN33="X",1,"0") -> 1 | AT16: =AT15+1 -> 12 | AU16: =Soal!M31 -> 0 | AV16: =Soal!N31 -> x
B17: =B16+1 -> 7 | C17: =IF(C34="X",1,"0") -> 0 | D17: =IF(D34="X",1,"0") -> 1 | F17: =F16+1 -> 21 | G17: =IF(G34="X",1,"0") -> 0 | H17: =IF(H34="X",1,"0") -> 1 | J17: =J16+1 -> 35 | K17: =IF(K34="X",1,"0") -> 0 | L17: =IF(L34="X",1,"0") -> 1 | N17: =N16+1 -> 49 | O17: =IF(O34="X",1,"0") -> 0 | P17: =IF(P34="X",1,"0") -> 1 | R17: =R16+1 -> 63 | S17: =IF(S34="X",1,"0") -> 0 | T17: =IF(T34="X",1,"0") -> 1 | V17: =V16+1 -> 77 | W17: =IF(W34="X",1,"0") -> 0 | X17: =IF(X34="X",1,"0") -> 1 | Z17: =Z16+1 -> 91 | AA17: =IF(AA34="X",1,"0") -> 0 | AB17: =IF(AB34="X",1,"0") -> 1 | AD17: =AD16+1 -> 105 | AE17: =IF(AE34="X",1,"0") -> 0 | AF17: =IF(AF34="X",1,"0") -> 1 | AH17: =AH16+1 -> 119 | AI17: =IF(AI34="X",1,"0") -> 0 | AJ17: =IF(AJ34="X",1,"0") -> 1 | AL17: =AL16+1 -> 133 | AM17: =IF(AM34="X",1,"0") -> 0 | AN17: =IF(AN34="X",1,"0") -> 1 | AP17: Hn | AQ17: =C18+D17+G17+G18+K17+K18+O17+O18+S17+S18+W17+W18+AA17+AA18+AE17+AE18+AI17+AI18+AM17+AM18 -> 1 | AT17: =AT16+1 -> 13 | AU17: =Soal!M32 -> 0 | AV17: =Soal!N32 -> x
B18: =B17+1 -> 8 | C18: =IF(C35="X",1,"0") -> 0 | D18: =IF(D35="X",1,"0") -> 1 | F18: =F17+1 -> 22 | G18: =IF(G35="X",1,"0") -> 0 | H18: =IF(H35="X",1,"0") -> 1 | J18: =J17+1 -> 36 | K18: =IF(K35="X",1,"0") -> 0 | L18: =IF(L35="X",1,"0") -> 1 | N18: =N17+1 -> 50 | O18: =IF(O35="X",1,"0") -> 0 | P18: =IF(P35="X",1,"0") -> 1 | R18: =R17+1 -> 64 | S18: =IF(S35="X",1,"0") -> 0 | T18: =IF(T35="X",1,"0") -> 1 | V18: =V17+1 -> 78 | W18: =IF(W35="X",1,"0") -> 0 | X18: =IF(X35="X",1,"0") -> 1 | Z18: =Z17+1 -> 92 | AA18: =IF(AA35="X",1,"0") -> 0 | AB18: =IF(AB35="X",1,"0") -> 1 | AD18: =AD17+1 -> 106 | AE18: =IF(AE35="X",1,"0") -> 0 | AF18: =IF(AF35="X",1,"0") -> 1 | AH18: =AH17+1 -> 120 | AI18: =IF(AI35="X",1,"0") -> 0 | AJ18: =IF(AJ35="X",1,"0") -> 1 | AL18: =AL17+1 -> 134 | AM18: =IF(AM35="X",1,"0") -> 0 | AN18: =IF(AN35="X",1,"0") -> 1 | AT18: =AT17+1 -> 14 | AU18: =Soal!M33 -> 0 | AV18: =Soal!N33 -> x
B19: =B18+1 -> 9 | C19: =IF(C36="X",1,"0") -> 0 | D19: =IF(D36="X",1,"0") -> 1 | F19: =F18+1 -> 23 | G19: =IF(G36="X",1,"0") -> 0 | H19: =IF(H36="X",1,"0") -> 1 | J19: =J18+1 -> 37 | K19: =IF(K36="X",1,"0") -> 0 | L19: =IF(L36="X",1,"0") -> 1 | N19: =N18+1 -> 51 | O19: =IF(O36="X",1,"0") -> 0 | P19: =IF(P36="X",1,"0") -> 1 | R19: =R18+1 -> 65 | S19: =IF(S36="X",1,"0") -> 0 | T19: =IF(T36="X",1,"0") -> 1 | V19: =V18+1 -> 79 | W19: =IF(W36="X",1,"0") -> 0 | X19: =IF(X36="X",1,"0") -> 1 | Z19: =Z18+1 -> 93 | AA19: =IF(AA36="X",1,"0") -> 0 | AB19: =IF(AB36="X",1,"0") -> 1 | AD19: =AD18+1 -> 107 | AE19: =IF(AE36="X",1,"0") -> 0 | AF19: =IF(AF36="X",1,"0") -> 1 | AH19: =AH18+1 -> 121 | AI19: =IF(AI36="X",1,"0") -> 0 | AJ19: =IF(AJ36="X",1,"0") -> 1 | AL19: =AL18+1 -> 135 | AM19: =IF(AM36="X",1,"0") -> 0 | AN19: =IF(AN36="X",1,"0") -> 1 | AP19: Ca | AQ19: =C20+D19+G19+G20+K19+K20+P19+O20+S19+T20+W19+W20+AA19+AA20+AF19+AE20+AI19+AI20+AN19+AM20 -> 5 | AT19: =AT18+1 -> 15 | AU19: =Soal!M34 -> 0 | AV19: =Soal!N34 -> x
B20: =B19+1 -> 10 | C20: =IF(C37="X",1,"0") -> 0 | D20: =IF(D37="X",1,"0") -> 1 | F20: =F19+1 -> 24 | G20: =IF(G37="X",1,"0") -> 0 | H20: =IF(H37="X",1,"0") -> 1 | J20: =J19+1 -> 38 | K20: =IF(K37="X",1,"0") -> 0 | L20: =IF(L37="X",1,"0") -> 1 | N20: =N19+1 -> 52 | O20: =IF(O37="X",1,"0") -> 0 | P20: =IF(P37="X",1,"0") -> 1 | R20: =R19+1 -> 66 | S20: =IF(S37="X",1,"0") -> 0 | T20: =IF(T37="X",1,"0") -> 1 | V20: =V19+1 -> 80 | W20: =IF(W37="X",1,"0") -> 0 | X20: =IF(X37="X",1,"0") -> 1 | Z20: =Z19+1 -> 94 | AA20: =IF(AA37="X",1,"0") -> 0 | AB20: =IF(AB37="X",1,"0") -> 1 | AD20: =AD19+1 -> 108 | AE20: =IF(AE37="X",1,"0") -> 0 | AF20: =IF(AF37="X",1,"0") -> 1 | AH20: =AH19+1 -> 122 | AI20: =IF(AI37="X",1,"0") -> 0 | AJ20: =IF(AJ37="X",1,"0") -> 1 | AL20: =AL19+1 -> 136 | AM20: =IF(AM37="X",1,"0") -> 0 | AN20: =IF(AN37="X",1,"0") -> 1 | AT20: =AT19+1 -> 16 | AU20: =Soal!M35 -> 0 | AV20: =Soal!N35 -> x
B21: =B20+1 -> 11 | C21: =IF(C38="X",1,"0") -> 0 | D21: =IF(D38="X",1,"0") -> 1 | F21: =F20+1 -> 25 | G21: =IF(G38="X",1,"0") -> 0 | H21: =IF(H38="X",1,"0") -> 1 | J21: =J20+1 -> 39 | K21: =IF(K38="X",1,"0") -> 0 | L21: =IF(L38="X",1,"0") -> 1 | N21: =N20+1 -> 53 | O21: =IF(O38="X",1,"0") -> 0 | P21: =IF(P38="X",1,"0") -> 1 | R21: =R20+1 -> 67 | S21: =IF(S38="X",1,"0") -> 0 | T21: =IF(T38="X",1,"0") -> 1 | V21: =V20+1 -> 81 | W21: =IF(W38="X",1,"0") -> 0 | X21: =IF(X38="X",1,"0") -> 1 | Z21: =Z20+1 -> 95 | AA21: =IF(AA38="X",1,"0") -> 0 | AB21: =IF(AB38="X",1,"0") -> 1 | AD21: =AD20+1 -> 109 | AE21: =IF(AE38="X",1,"0") -> 0 | AF21: =IF(AF38="X",1,"0") -> 1 | AH21: =AH20+1 -> 123 | AI21: =IF(AI38="X",1,"0") -> 0 | AJ21: =IF(AJ38="X",1,"0") -> 1 | AL21: =AL20+1 -> 137 | AM21: =IF(AM38="X",1,"0") -> 0 | AN21: =IF(AN38="X",1,"0") -> 1 | AP21: Sh | AQ21: =C21+C22+G21+G22+K21+K22+O21+O22+S21+S22+W21+W22+AA21+AA22+AE21+AE22+AI21+AI22+AM21+AM22 -> 0 | AT21: =AT20+1 -> 17 | AU21: =Soal!M36 -> 0 | AV21: =Soal!N36 -> x
B22: =B21+1 -> 12 | C22: =IF(C39="X",1,"0") -> 0 | D22: =IF(D39="X",1,"0") -> 1 | F22: =F21+1 -> 26 | G22: =IF(G39="X",1,"0") -> 0 | H22: =IF(H39="X",1,"0") -> 1 | J22: =J21+1 -> 40 | K22: =IF(K39="X",1,"0") -> 0 | L22: =IF(L39="X",1,"0") -> 1 | N22: =N21+1 -> 54 | O22: =IF(O39="X",1,"0") -> 0 | P22: =IF(P39="X",1,"0") -> 1 | R22: =R21+1 -> 68 | S22: =IF(S39="X",1,"0") -> 0 | T22: =IF(T39="X",1,"0") -> 1 | V22: =V21+1 -> 82 | W22: =IF(W39="X",1,"0") -> 0 | X22: =IF(X39="X",1,"0") -> 1 | Z22: =Z21+1 -> 96 | AA22: =IF(AA39="X",1,"0") -> 0 | AB22: =IF(AB39="X",1,"0") -> 1 | AD22: =AD21+1 -> 110 | AE22: =IF(AE39="X",1,"0") -> 0 | AF22: =IF(AF39="X",1,"0") -> 1 | AH22: =AH21+1 -> 124 | AI22: =IF(AI39="X",1,"0") -> 0 | AJ22: =IF(AJ39="X",1,"0") -> 1 | AL22: =AL21+1 -> 138 | AM22: =IF(AM39="X",1,"0") -> 0 | AN22: =IF(AN39="X",1,"0") -> 1 | AT22: =AT21+1 -> 18 | AU22: =Soal!M37 -> 0 | AV22: =Soal!N37 -> x
B23: =B22+1 -> 13 | C23: =IF(C40="X",1,"0") -> 0 | D23: =IF(D40="X",1,"0") -> 1 | F23: =F22+1 -> 27 | G23: =IF(G40="X",1,"0") -> 0 | H23: =IF(H40="X",1,"0") -> 1 | J23: =J22+1 -> 41 | K23: =IF(K40="X",1,"0") -> 0 | L23: =IF(L40="X",1,"0") -> 1 | N23: =N22+1 -> 55 | O23: =IF(O40="X",1,"0") -> 0 | P23: =IF(P40="X",1,"0") -> 1 | R23: =R22+1 -> 69 | S23: =IF(S40="X",1,"0") -> 0 | T23: =IF(T40="X",1,"0") -> 1 | V23: =V22+1 -> 83 | W23: =IF(W40="X",1,"0") -> 0 | X23: =IF(X40="X",1,"0") -> 1 | Z23: =Z22+1 -> 97 | AA23: =IF(AA40="X",1,"0") -> 0 | AB23: =IF(AB40="X",1,"0") -> 1 | AD23: =AD22+1 -> 111 | AE23: =IF(AE40="X",1,"0") -> 0 | AF23: =IF(AF40="X",1,"0") -> 1 | AH23: =AH22+1 -> 125 | AI23: =IF(AI40="X",1,"0") -> 0 | AJ23: =IF(AJ40="X",1,"0") -> 1 | AL23: =AL22+1 -> 139 | AM23: =IF(AM40="X",1,"0") -> 0 | AN23: =IF(AN40="X",1,"0") -> 1 | AP23: Gi | AQ23: =C23+D24+G23+G24+K23+L24+P23+O24+S23+S24+W23+X24+AA23+AA24+AE23+AF24+AI23+AI24+AM23+AM24 -> 5 | AT23: =AT22+1 -> 19 | AU23: =Soal!M38 -> 0 | AV23: =Soal!N38 -> x
B24: =B23+1 -> 14 | C24: =IF(C41="X",1,"0") -> 0 | D24: =IF(D41="X",1,"0") -> 1 | F24: =F23+1 -> 28 | G24: =IF(G41="X",1,"0") -> 0 | H24: =IF(H41="X",1,"0") -> 1 | J24: =J23+1 -> 42 | K24: =IF(K41="X",1,"0") -> 0 | L24: =IF(L41="X",1,"0") -> 1 | N24: =N23+1 -> 56 | O24: =IF(O41="X",1,"0") -> 0 | P24: =IF(P41="X",1,"0") -> 1 | R24: =R23+1 -> 70 | S24: =IF(S41="X",1,"0") -> 0 | T24: =IF(T41="X",1,"0") -> 1 | V24: =V23+1 -> 84 | W24: =IF(W41="X",1,"0") -> 0 | X24: =IF(X41="X",1,"0") -> 1 | Z24: =Z23+1 -> 98 | AA24: =IF(AA41="X",1,"0") -> 0 | AB24: =IF(AB41="X",1,"0") -> 1 | AD24: =AD23+1 -> 112 | AE24: =IF(AE41="X",1,"0") -> 0 | AF24: =IF(AF41="X",1,"0") -> 1 | AH24: =AH23+1 -> 126 | AI24: =IF(AI41="X",1,"0") -> 0 | AJ24: =IF(AJ41="X",1,"0") -> 1 | AL24: =AL23+1 -> 140 | AM24: =IF(AM41="X",1,"0") -> 0 | AN24: =IF(AN41="X",1,"0") -> 1 | AT24: =AT23+1 -> 20 | AU24: =Soal!M39 -> 0 | AV24: =Soal!N39 -> x
D25: =SUM(C11:D24) -> 14 | H25: =SUM(G11:H24) -> 14 | L25: =SUM(K11:L24) -> 14 | P25: =SUM(O11:P24) -> 14 | T25: =SUM(S11:T24) -> 14 | X25: =SUM(W11:X24) -> 14 | AB25: =SUM(AA11:AB24) -> 14 | AF25: =SUM(AE11:AF24) -> 14 | AJ25: =SUM(AI11:AJ24) -> 14 | AN25: =SUM(AM11:AN24) -> 14 | AP25: =SUM(D25:AN25) -> 140 | AQ25: =SUM(AQ11:AQ24) -> 34 | AT25: =AT24+1 -> 21 | AU25: =Soal!M40 -> 0 | AV25: =Soal!N40 -> x
AT26: =AT25+1 -> 22 | AU26: =Soal!M41 -> 0 | AV26: =Soal!N41 -> x
B27: No | C27: B | D27: S | F27: No | G27: B | H27: S | J27: No | K27: B | L27: S | N27: No | O27: B | P27: S | R27: No | S27: B | T27: S | V27: No | W27: B | X27: S | Z27: No | AA27: B | AB27: S | AD27: No | AE27: B | AF27: S | AH27: No | AI27: B | AJ27: S | AL27: No | AM27: B | AN27: S | AT27: =AT26+1 -> 23 | AU27: =Soal!M42 -> 0 | AV27: =Soal!N42 -> x
B28: 1 | C28: =AU5 -> 0 | D28: =AV5 -> x | F28: 15 | G28: =AU19 -> 0 | H28: =AV19 -> x | J28: 29 | K28: =AU33 -> 0 | L28: =AV33 -> x | N28: 43 | O28: =AU47 -> 0 | P28: =AV47 -> x | R28: 57 | S28: =AU61 -> 0 | T28: =AV61 -> x | V28: 71 | W28: =AU75 -> 0 | X28: =AV75 -> x | Z28: 85 | AA28: =AU89 -> 0 | AB28: =AV89 -> x | AD28: 99 | AE28: =AU103 -> 0 | AF28: =AV103 -> x | AH28: 113 | AI28: =AU117 -> 0 | AJ28: =AV117 -> x | AL28: 127 | AM28: =AU131 -> 0 | AN28: =AV131 -> x | AT28: =AT27+1 -> 24 | AU28: =Soal!M43 -> 0 | AV28: =Soal!N43 -> x
B29: =B28+1 -> 2 | C29: =AU6 -> 0 | D29: =AV6 -> x | F29: =F28+1 -> 16 | G29: =AU20 -> 0 | H29: =AV20 -> x | J29: =J28+1 -> 30 | K29: =AU34 -> 0 | L29: =AV34 -> x | N29: =N28+1 -> 44 | O29: =AU48 -> 0 | P29: =AV48 -> x | R29: =R28+1 -> 58 | S29: =AU62 -> 0 | T29: =AV62 -> x | V29: =V28+1 -> 72 | W29: =AU76 -> 0 | X29: =AV76 -> x | Z29: =Z28+1 -> 86 | AA29: =AU90 -> 0 | AB29: =AV90 -> x | AD29: =AD28+1 -> 100 | AE29: =AU104 -> 0 | AF29: =AV104 -> x | AH29: =AH28+1 -> 114 | AI29: =AU118 -> 0 | AJ29: =AV118 -> x | AL29: =AL28+1 -> 128 | AM29: =AU132 -> 0 | AN29: =AV132 -> x | AT29: =AT28+1 -> 25 | AU29: =Soal!M44 -> 0 | AV29: =Soal!N44 -> x
B30: =B29+1 -> 3 | C30: =AU7 -> 0 | D30: =AV7 -> x | F30: =F29+1 -> 17 | G30: =AU21 -> 0 | H30: =AV21 -> x | J30: =J29+1 -> 31 | K30: =AU35 -> 0 | L30: =AV35 -> x | N30: =N29+1 -> 45 | O30: =AU49 -> 0 | P30: =AV49 -> x | R30: =R29+1 -> 59 | S30: =AU63 -> 0 | T30: =AV63 -> x | V30: =V29+1 -> 73 | W30: =AU77 -> 0 | X30: =AV77 -> x | Z30: =Z29+1 -> 87 | AA30: =AU91 -> 0 | AB30: =AV91 -> x | AD30: =AD29+1 -> 101 | AE30: =AU105 -> 0 | AF30: =AV105 -> x | AH30: =AH29+1 -> 115 | AI30: =AU119 -> 0 | AJ30: =AV119 -> x | AL30: =AL29+1 -> 129 | AM30: =AU133 -> 0 | AN30: =AV133 -> x | AT30: =AT29+1 -> 26 | AU30: =Soal!M45 -> 0 | AV30: =Soal!N45 -> x
B31: =B30+1 -> 4 | C31: =AU8 -> 0 | D31: =AV8 -> x | F31: =F30+1 -> 18 | G31: =AU22 -> 0 | H31: =AV22 -> x | J31: =J30+1 -> 32 | K31: =AU36 -> 0 | L31: =AV36 -> x | N31: =N30+1 -> 46 | O31: =AU50 -> 0 | P31: =AV50 -> x | R31: =R30+1 -> 60 | S31: =AU64 -> 0 | T31: =AV64 -> x | V31: =V30+1 -> 74 | W31: =AU78 -> 0 | X31: =AV78 -> x | Z31: =Z30+1 -> 88 | AA31: =AU92 -> 0 | AB31: =AV92 -> x | AD31: =AD30+1 -> 102 | AE31: =AU106 -> 0 | AF31: =AV106 -> x | AH31: =AH30+1 -> 116 | AI31: =AU120 -> 0 | AJ31: =AV120 -> x | AL31: =AL30+1 -> 130 | AM31: =AU134 -> 0 | AN31: =AV134 -> x | AT31: =AT30+1 -> 27 | AU31: =Soal!M46 -> 0 | AV31: =Soal!N46 -> x
B32: =B31+1 -> 5 | C32: =AU9 -> 0 | D32: =AV9 -> x | F32: =F31+1 -> 19 | G32: =AU23 -> 0 | H32: =AV23 -> x | J32: =J31+1 -> 33 | K32: =AU37 -> 0 | L32: =AV37 -> x | N32: =N31+1 -> 47 | O32: =AU51 -> 0 | P32: =AV51 -> x | R32: =R31+1 -> 61 | S32: =AU65 -> 0 | T32: =AV65 -> x | V32: =V31+1 -> 75 | W32: =AU79 -> 0 | X32: =AV79 -> x | Z32: =Z31+1 -> 89 | AA32: =AU93 -> 0 | AB32: =AV93 -> x | AD32: =AD31+1 -> 103 | AE32: =AU107 -> 0 | AF32: =AV107 -> x | AH32: =AH31+1 -> 117 | AI32: =AU121 -> 0 | AJ32: =AV121 -> x | AL32: =AL31+1 -> 131 | AM32: =AU135 -> 0 | AN32: =AV135 -> x | AT32: =AT31+1 -> 28 | AU32: =Soal!M47 -> 0 | AV32: =Soal!N47 -> x
B33: =B32+1 -> 6 | C33: =AU10 -> 0 | D33: =AV10 -> x | F33: =F32+1 -> 20 | G33: =AU24 -> 0 | H33: =AV24 -> x | J33: =J32+1 -> 34 | K33: =AU38 -> 0 | L33: =AV38 -> x | N33: =N32+1 -> 48 | O33: =AU52 -> 0 | P33: =AV52 -> x | R33: =R32+1 -> 62 | S33: =AU66 -> 0 | T33: =AV66 -> x | V33: =V32+1 -> 76 | W33: =AU80 -> 0 | X33: =AV80 -> x | Z33: =Z32+1 -> 90 | AA33: =AU94 -> 0 | AB33: =AV94 -> x | AD33: =AD32+1 -> 104 | AE33: =AU108 -> 0 | AF33: =AV108 -> x | AH33: =AH32+1 -> 118 | AI33: =AU122 -> 0 | AJ33: =AV122 -> x | AL33: =AL32+1 -> 132 | AM33: =AU136 -> 0 | AN33: =AV136 -> x | AT33: =AT32+1 -> 29 | AU33: =Soal!M48 -> 0 | AV33: =Soal!N48 -> x
B34: =B33+1 -> 7 | C34: =AU11 -> 0 | D34: =AV11 -> x | F34: =F33+1 -> 21 | G34: =AU25 -> 0 | H34: =AV25 -> x | J34: =J33+1 -> 35 | K34: =AU39 -> 0 | L34: =AV39 -> x | N34: =N33+1 -> 49 | O34: =AU53 -> 0 | P34: =AV53 -> x | R34: =R33+1 -> 63 | S34: =AU67 -> 0 | T34: =AV67 -> x | V34: =V33+1 -> 77 | W34: =AU81 -> 0 | X34: =AV81 -> x | Z34: =Z33+1 -> 91 | AA34: =AU95 -> 0 | AB34: =AV95 -> x | AD34: =AD33+1 -> 105 | AE34: =AU109 -> 0 | AF34: =AV109 -> x | AH34: =AH33+1 -> 119 | AI34: =AU123 -> 0 | AJ34: =AV123 -> x | AL34: =AL33+1 -> 133 | AM34: =AU137 -> 0 | AN34: =AV137 -> x | AT34: =AT33+1 -> 30 | AU34: =Soal!M49 -> 0 | AV34: =Soal!N49 -> x
B35: =B34+1 -> 8 | C35: =AU12 -> 0 | D35: =AV12 -> x | F35: =F34+1 -> 22 | G35: =AU26 -> 0 | H35: =AV26 -> x | J35: =J34+1 -> 36 | K35: =AU40 -> 0 | L35: =AV40 -> x | N35: =N34+1 -> 50 | O35: =AU54 -> 0 | P35: =AV54 -> x | R35: =R34+1 -> 64 | S35: =AU68 -> 0 | T35: =AV68 -> x | V35: =V34+1 -> 78 | W35: =AU82 -> 0 | X35: =AV82 -> x | Z35: =Z34+1 -> 92 | AA35: =AU96 -> 0 | AB35: =AV96 -> x | AD35: =AD34+1 -> 106 | AE35: =AU110 -> 0 | AF35: =AV110 -> x | AH35: =AH34+1 -> 120 | AI35: =AU124 -> 0 | AJ35: =AV124 -> x | AL35: =AL34+1 -> 134 | AM35: =AU138 -> 0 | AN35: =AV138 -> x | AT35: =AT34+1 -> 31 | AU35: =Soal!M50 -> 0 | AV35: =Soal!N50 -> x
B36: =B35+1 -> 9 | C36: =AU13 -> 0 | D36: =AV13 -> x | F36: =F35+1 -> 23 | G36: =AU27 -> 0 | H36: =AV27 -> x | J36: =J35+1 -> 37 | K36: =AU41 -> 0 | L36: =AV41 -> x | N36: =N35+1 -> 51 | O36: =AU55 -> 0 | P36: =AV55 -> x | R36: =R35+1 -> 65 | S36: =AU69 -> 0 | T36: =AV69 -> x | V36: =V35+1 -> 79 | W36: =AU83 -> 0 | X36: =AV83 -> x | Z36: =Z35+1 -> 93 | AA36: =AU97 -> 0 | AB36: =AV97 -> x | AD36: =AD35+1 -> 107 | AE36: =AU111 -> 0 | AF36: =AV111 -> x | AH36: =AH35+1 -> 121 | AI36: =AU125 -> 0 | AJ36: =AV125 -> x | AL36: =AL35+1 -> 135 | AM36: =AU139 -> 0 | AN36: =AV139 -> x | AT36: =AT35+1 -> 32 | AU36: =Soal!M51 -> 0 | AV36: =Soal!N51 -> x
B37: =B36+1 -> 10 | C37: =AU14 -> 0 | D37: =AV14 -> x | F37: =F36+1 -> 24 | G37: =AU28 -> 0 | H37: =AV28 -> x | J37: =J36+1 -> 38 | K37: =AU42 -> 0 | L37: =AV42 -> x | N37: =N36+1 -> 52 | O37: =AU56 -> 0 | P37: =AV56 -> x | R37: =R36+1 -> 66 | S37: =AU70 -> 0 | T37: =AV70 -> x | V37: =V36+1 -> 80 | W37: =AU84 -> 0 | X37: =AV84 -> x | Z37: =Z36+1 -> 94 | AA37: =AU98 -> 0 | AB37: =AV98 -> x | AD37: =AD36+1 -> 108 | AE37: =AU112 -> 0 | AF37: =AV112 -> x | AH37: =AH36+1 -> 122 | AI37: =AU126 -> 0 | AJ37: =AV126 -> x | AL37: =AL36+1 -> 136 | AM37: =AU140 -> 0 | AN37: =AV140 -> x | AT37: =AT36+1 -> 33 | AU37: =Soal!M52 -> 0 | AV37: =Soal!N52 -> x
B38: =B37+1 -> 11 | C38: =AU15 -> 0 | D38: =AV15 -> x | F38: =F37+1 -> 25 | G38: =AU29 -> 0 | H38: =AV29 -> x | J38: =J37+1 -> 39 | K38: =AU43 -> 0 | L38: =AV43 -> x | N38: =N37+1 -> 53 | O38: =AU57 -> 0 | P38: =AV57 -> x | R38: =R37+1 -> 67 | S38: =AU71 -> 0 | T38: =AV71 -> x | V38: =V37+1 -> 81 | W38: =AU85 -> 0 | X38: =AV85 -> x | Z38: =Z37+1 -> 95 | AA38: =AU99 -> 0 | AB38: =AV99 -> x | AD38: =AD37+1 -> 109 | AE38: =AU113 -> 0 | AF38: =AV113 -> x | AH38: =AH37+1 -> 123 | AI38: =AU127 -> 0 | AJ38: =AV127 -> x | AL38: =AL37+1 -> 137 | AM38: =AU141 -> 0 | AN38: =AV141 -> x | AT38: =AT37+1 -> 34 | AU38: =Soal!M53 -> 0 | AV38: =Soal!N53 -> x
B39: =B38+1 -> 12 | C39: =AU16 -> 0 | D39: =AV16 -> x | F39: =F38+1 -> 26 | G39: =AU30 -> 0 | H39: =AV30 -> x | J39: =J38+1 -> 40 | K39: =AU44 -> 0 | L39: =AV44 -> x | N39: =N38+1 -> 54 | O39: =AU58 -> 0 | P39: =AV58 -> x | R39: =R38+1 -> 68 | S39: =AU72 -> 0 | T39: =AV72 -> x | V39: =V38+1 -> 82 | W39: =AU86 -> 0 | X39: =AV86 -> x | Z39: =Z38+1 -> 96 | AA39: =AU100 -> 0 | AB39: =AV100 -> x | AD39: =AD38+1 -> 110 | AE39: =AU114 -> 0 | AF39: =AV114 -> x | AH39: =AH38+1 -> 124 | AI39: =AU128 -> 0 | AJ39: =AV128 -> x | AL39: =AL38+1 -> 138 | AM39: =AU142 -> 0 | AN39: =AV142 -> x | AT39: =AT38+1 -> 35 | AU39: =Soal!M54 -> 0 | AV39: =Soal!N54 -> x
B40: =B39+1 -> 13 | C40: =AU17 -> 0 | D40: =AV17 -> x | F40: =F39+1 -> 27 | G40: =AU31 -> 0 | H40: =AV31 -> x | J40: =J39+1 -> 41 | K40: =AU45 -> 0 | L40: =AV45 -> x | N40: =N39+1 -> 55 | O40: =AU59 -> 0 | P40: =AV59 -> x | R40: =R39+1 -> 69 | S40: =AU73 -> 0 | T40: =AV73 -> x | V40: =V39+1 -> 83 | W40: =AU87 -> 0 | X40: =AV87 -> x | Z40: =Z39+1 -> 97 | AA40: =AU101 -> 0 | AB40: =AV101 -> x | AD40: =AD39+1 -> 111 | AE40: =AU115 -> 0 | AF40: =AV115 -> x | AH40: =AH39+1 -> 125 | AI40: =AU129 -> 0 | AJ40: =AV129 -> x | AL40: =AL39+1 -> 139 | AM40: =AU143 -> 0 | AN40: =AV143 -> x | AT40: =AT39+1 -> 36 | AU40: =Soal!M55 -> 0 | AV40: =Soal!N55 -> x
B41: =B40+1 -> 14 | C41: =AU18 -> 0 | D41: =AV18 -> x | F41: =F40+1 -> 28 | G41: =AU32 -> 0 | H41: =AV32 -> x | J41: =J40+1 -> 42 | K41: =AU46 -> 0 | L41: =AV46 -> x | N41: =N40+1 -> 56 | O41: =AU60 -> 0 | P41: =AV60 -> x | R41: =R40+1 -> 70 | S41: =AU74 -> 0 | T41: =AV74 -> x | V41: =V40+1 -> 84 | W41: =AU88 -> 0 | X41: =AV88 -> x | Z41: =Z40+1 -> 98 | AA41: =AU102 -> 0 | AB41: =AV102 -> x | AD41: =AD40+1 -> 112 | AE41: =AU116 -> 0 | AF41: =AV116 -> x | AH41: =AH40+1 -> 126 | AI41: =AU130 -> 0 | AJ41: =AV130 -> x | AL41: =AL40+1 -> 140 | AM41: =AU144 -> 0 | AN41: =AV144 -> x | AT41: =AT40+1 -> 37 | AU41: =Soal!M56 -> 0 | AV41: =Soal!N56 -> x
...

Sheet Lembar Jawaban
A1: Counterproductive Behavior Index (CBI)
A3: Tanggal isi | D3: :
A4: Nama | D4: :
A5: Jenis Kelamin | D5: :
A6: Tanggal Lahir | D6: :
A7: Usia | D7: :
A8: Pendidikan | D8: :
B11: B | C11: S | F11: B | G11: S | J11: B | K11: S | N11: B | O11: S | R11: B | S11: S | V11: B | W11: S | Z11: B | AA11: S | AD11: B | AE11: S | AH11: B | AI11: S | AL11: B | AM11: S
A12: 1 | E12: 15 | I12: 29 | M12: 43 | Q12: 57 | U12: 71 | Y12: 85 | AC12: 99 | AG12: 113 | AK12: 127
B13: B | C13: S | F13: B | G13: S | J13: B | K13: S | N13: B | O13: S | R13: B | S13: S | V13: B | W13: S | Z13: B | AA13: S | AD13: B | AE13: S | AH13: B | AI13: S | AL13: B | AM13: S
A14: =A12+1 -> 2 | E14: =E12+1 -> 16 | I14: =I12+1 -> 30 | M14: =M12+1 -> 44 | Q14: =Q12+1 -> 58 | U14: =U12+1 -> 72 | Y14: =Y12+1 -> 86 | AC14: =AC12+1 -> 100 | AG14: =AG12+1 -> 114 | AK14: =AK12+1 -> 128
B15: B | C15: S | F15: B | G15: S | J15: B | K15: S | N15: B | O15: S | R15: B | S15: S | V15: B | W15: S | Z15: B | AA15: S | AD15: B | AE15: S | AH15: B | AI15: S | AL15: B | AM15: S
A16: =A14+1 -> 3 | E16: =E14+1 -> 17 | I16: =I14+1 -> 31 | M16: =M14+1 -> 45 | Q16: =Q14+1 -> 59 | U16: =U14+1 -> 73 | Y16: =Y14+1 -> 87 | AC16: =AC14+1 -> 101 | AG16: =AG14+1 -> 115 | AK16: =AK14+1 -> 129
B17: B | C17: S | F17: B | G17: S | J17: B | K17: S | N17: B | O17: S | R17: B | S17: S | V17: B | W17: S | Z17: B | AA17: S | AD17: B | AE17: S | AH17: B | AI17: S | AL17: B | AM17: S
A18: =A16+1 -> 4 | E18: =E16+1 -> 18 | I18: =I16+1 -> 32 | M18: =M16+1 -> 46 | Q18: =Q16+1 -> 60 | U18: =U16+1 -> 74 | Y18: =Y16+1 -> 88 | AC18: =AC16+1 -> 102 | AG18: =AG16+1 -> 116 | AK18: =AK16+1 -> 130
B19: B | C19: S | F19: B | G19: S | J19: B | K19: S | N19: B | O19: S | R19: B | S19: S | V19: B | W19: S | Z19: B | AA19: S | AD19: B | AE19: S | AH19: B | AI19: S | AL19: B | AM19: S
A20: =A18+1 -> 5 | E20: =E18+1 -> 19 | I20: =I18+1 -> 33 | M20: =M18+1 -> 47 | Q20: =Q18+1 -> 61 | U20: =U18+1 -> 75 | Y20: =Y18+1 -> 89 | AC20: =AC18+1 -> 103 | AG20: =AG18+1 -> 117 | AK20: =AK18+1 -> 131
B21: B | C21: S | F21: B | G21: S | J21: B | K21: S | N21: B | O21: S | R21: B | S21: S | V21: B | W21: S | Z21: B | AA21: S | AD21: B | AE21: S | AH21: B | AI21: S | AL21: B | AM21: S
A22: =A20+1 -> 6 | E22: =E20+1 -> 20 | I22: =I20+1 -> 34 | M22: =M20+1 -> 48 | Q22: =Q20+1 -> 62 | U22: =U20+1 -> 76 | Y22: =Y20+1 -> 90 | AC22: =AC20+1 -> 104 | AG22: =AG20+1 -> 118 | AK22: =AK20+1 -> 132
B23: B | C23: S | F23: B | G23: S | J23: B | K23: S | N23: B | O23: S | R23: B | S23: S | V23: B | W23: S | Z23: B | AA23: S | AD23: B | AE23: S | AH23: B | AI23: S | AL23: B | AM23: S
A24: =A22+1 -> 7 | E24: =E22+1 -> 21 | I24: =I22+1 -> 35 | M24: =M22+1 -> 49 | Q24: =Q22+1 -> 63 | U24: =U22+1 -> 77 | Y24: =Y22+1 -> 91 | AC24: =AC22+1 -> 105 | AG24: =AG22+1 -> 119 | AK24: =AK22+1 -> 133
B25: B | C25: S | F25: B | G25: S | J25: B | K25: S | N25: B | O25: S | R25: B | S25: S | V25: B | W25: S | Z25: B | AA25: S | AD25: B | AE25: S | AH25: B | AI25: S | AL25: B | AM25: S
A26: =A24+1 -> 8 | E26: =E24+1 -> 22 | I26: =I24+1 -> 36 | M26: =M24+1 -> 50 | Q26: =Q24+1 -> 64 | U26: =U24+1 -> 78 | Y26: =Y24+1 -> 92 | AC26: =AC24+1 -> 106 | AG26: =AG24+1 -> 120 | AK26: =AK24+1 -> 134
B27: B | C27: S | F27: B | G27: S | J27: B | K27: S | N27: B | O27: S | R27: B | S27: S | V27: B | W27: S | Z27: B | AA27: S | AD27: B | AE27: S | AH27: B | AI27: S | AL27: B | AM27: S
A28: =A26+1 -> 9 | E28: =E26+1 -> 23 | I28: =I26+1 -> 37 | M28: =M26+1 -> 51 | Q28: =Q26+1 -> 65 | U28: =U26+1 -> 79 | Y28: =Y26+1 -> 93 | AC28: =AC26+1 -> 107 | AG28: =AG26+1 -> 121 | AK28: =AK26+1 -> 135
B29: B | C29: S | F29: B | G29: S | J29: B | K29: S | N29: B | O29: S | R29: B | S29: S | V29: B | W29: S | Z29: B | AA29: S | AD29: B | AE29: S | AH29: B | AI29: S | AL29: B | AM29: S
A30: =A28+1 -> 10 | E30: =E28+1 -> 24 | I30: =I28+1 -> 38 | M30: =M28+1 -> 52 | Q30: =Q28+1 -> 66 | U30: =U28+1 -> 80 | Y30: =Y28+1 -> 94 | AC30: =AC28+1 -> 108 | AG30: =AG28+1 -> 122 | AK30: =AK28+1 -> 136
B31: B | C31: S | F31: B | G31: S | J31: B | K31: S | N31: B | O31: S | R31: B | S31: S | V31: B | W31: S | Z31: B | AA31: S | AD31: B | AE31: S | AH31: B | AI31: S | AL31: B | AM31: S
A32: =A30+1 -> 11 | E32: =E30+1 -> 25 | I32: =I30+1 -> 39 | M32: =M30+1 -> 53 | Q32: =Q30+1 -> 67 | U32: =U30+1 -> 81 | Y32: =Y30+1 -> 95 | AC32: =AC30+1 -> 109 | AG32: =AG30+1 -> 123 | AK32: =AK30+1 -> 137
B33: B | C33: S | F33: B | G33: S | J33: B | K33: S | N33: B | O33: S | R33: B | S33: S | V33: B | W33: S | Z33: B | AA33: S | AD33: B | AE33: S | AH33: B | AI33: S | AL33: B | AM33: S
A34: =A32+1 -> 12 | E34: =E32+1 -> 26 | I34: =I32+1 -> 40 | M34: =M32+1 -> 54 | Q34: =Q32+1 -> 68 | U34: =U32+1 -> 82 | Y34: =Y32+1 -> 96 | AC34: =AC32+1 -> 110 | AG34: =AG32+1 -> 124 | AK34: =AK32+1 -> 138
B35: B | C35: S | F35: B | G35: S | J35: B | K35: S | N35: B | O35: S | R35: B | S35: S | V35: B | W35: S | Z35: B | AA35: S | AD35: B | AE35: S | AH35: B | AI35: S | AL35: B | AM35: S
A36: =A34+1 -> 13 | E36: =E34+1 -> 27 | I36: =I34+1 -> 41 | M36: =M34+1 -> 55 | Q36: =Q34+1 -> 69 | U36: =U34+1 -> 83 | Y36: =Y34+1 -> 97 | AC36: =AC34+1 -> 111 | AG36: =AG34+1 -> 125 | AK36: =AK34+1 -> 139
B37: B | C37: S | F37: B | G37: S | J37: B | K37: S | N37: B | O37: S | R37: B | S37: S | V37: B | W37: S | Z37: B | AA37: S | AD37: B | AE37: S | AH37: B | AI37: S | AL37: B | AM37: S
A38: =A36+1 -> 14 | E38: =E36+1 -> 28 | I38: =I36+1 -> 42 | M38: =M36+1 -> 56 | Q38: =Q36+1 -> 70 | U38: =U36+1 -> 84 | Y38: =Y36+1 -> 98 | AC38: =AC36+1 -> 112 | AG38: =AG36+1 -> 126 | AK38: =AK36+1 -> 140
