Workbook

Sheet Ardhi rendra tama
A1: SKORING MSDT
B4: b | C4: a | D4: a | E4: a | F4: a | G4: b | H4: a | I4: b
B5: b | C5: b | D5: b | E5: a | F5: b | G5: a | H5: b | I5: b
B6: a | C6: b | D6: b | E6: b | F6: a | G6: b | H6: b | I6: b
B7: b | C7: b | D7: a | E7: a | F7: a | G7: b | H7: b | I7: b
B8: b | C8: a | D8: b | E8: b | F8: a | G8: b | H8: b | I8: b
B9: b | C9: b | D9: b | E9: a | F9: a | G9: a | H9: b | I9: a
B10: b | C10: a | D10: a | E10: a | F10: a | G10: b | H10: a | I10: a
B11: a | C11: a | D11: b | E11: b | F11: a | G11: a | H11: a | I11: b
A12: A | B12: 4 | C12: 2 | D12: 3 | E12: 1 | F12: 4 | G12: 4 | H12: 3 | I12: 3
A13: B | B13: 4 | C13: 5 | D13: 4 | E13: 4 | F13: 4 | G13: 7 | H13: 4 | I13: 8
A14: KOREKSI | B14: 1 | C14: 2 | D14: 1 | E14: 0 | F14: 3 | G14: -1 | H14: 0 | I14: -4
A15: JUMLAH | B15: =+B12+B13+B14 -> 9 | C15: =+C12+C13+C14 -> 9 | D15: =+D12+D13+D14 -> 8 | E15: =+E12+E13+E14 -> 5 | F15: =+F12+F13+F14 -> 11 | G15: =+G12+G13+G14 -> 10 | H15: =+H12+H13+H14 -> 7 | I15: =+I12+I13+I14 -> 7
C16: TO | E16: RO | G16: E | I16: O
A18: Ds ---- A | I18: =B15 -> 9
A20: Mi ---- B | E20: =C15 -> 9
A22: Au ---- C | C22: =D15 -> 8
A24: Co ---- D | C24: =E15 -> 5 | E24: =E15 -> 5
A26: Bu ---- E | G26: =F15 -> 11
A28: Dv ---- F | E28: =G15 -> 10 | G28: =G15 -> 10
A30: Ba ---- G | C30: =H15 -> 7 | G30: =H15 -> 7
A32: E ---- H | C32: =I15 -> 7 | E32: =I15 -> 7 | G32: =I15 -> 7
C34: =+C22+C24+C30+C32 -> 27 | E34: =+E20+E24+E28+E32 -> 31 | G34: =+G26+G28+G30+G32 -> 35 | I34: =I18 -> 9 | L34: Hasil Developer

Sheet Ujang Widi Wasmoto
A1: SKORING MSDT
B4: b | C4: a | D4: a | E4: a | F4: b | G4: b | H4: a | I4: b
B5: a | C5: a | D5: b | E5: b | F5: a | G5: a | H5: b | I5: a
B6: a | C6: a | D6: a | E6: b | F6: b | G6: a | H6: b | I6: b
B7: a | C7: a | D7: b | E7: a | F7: a | G7: b | H7: b | I7: b
B8: b | C8: a | D8: a | E8: b | F8: b | G8: a | H8: a | I8: b
B9: b | C9: b | D9: b | E9: a | F9: a | G9: b | H9: a | I9: b
B10: a | C10: b | D10: b | E10: a | F10: a | G10: a | H10: b | I10: b
B11: a | C11: a | D11: b | E11: a | F11: b | G11: b | H11: b | I11: a
A12: A | B12: 5 | C12: 2 | D12: 2 | E12: 3 | F12: 2 | G12: 4 | H12: 6 | I12: 5
A13: B | B13: 6 | C13: 4 | D13: 5 | E13: 3 | F13: 1 | G13: 5 | H13: 5 | I13: 6
A14: KOREKSI | B14: 1 | C14: 2 | D14: 1 | E14: 0 | F14: 3 | G14: -1 | H14: 0 | I14: -4
A15: JUMLAH | B15: =+B12+B13+B14 -> 12 | C15: =+C12+C13+C14 -> 8 | D15: =+D12+D13+D14 -> 8 | E15: =+E12+E13+E14 -> 6 | F15: =+F12+F13+F14 -> 6 | G15: =+G12+G13+G14 -> 8 | H15: =+H12+H13+H14 -> 11 | I15: =+I12+I13+I14 -> 7
C16: TO | E16: RO | G16: E | I16: O
A18: Ds ---- A | I18: =B15 -> 12
A20: Mi ---- B | E20: =C15 -> 8
A22: Au ---- C | C22: =D15 -> 8
A24: Co ---- D | C24: =E15 -> 6 | E24: =E15 -> 6
A26: Bu ---- E | G26: =F15 -> 6
A28: Dv ---- F | E28: =G15 -> 8 | G28: =G15 -> 8
A30: Ba ---- G | C30: =H15 -> 11 | G30: =H15 -> 11
A32: E ---- H | C32: =I15 -> 7 | E32: =I15 -> 7 | G32: =I15 -> 7
C34: =+C22+C24+C30+C32 -> 32 | E34: =+E20+E24+E28+E32 -> 29 | G34: =+G26+G28+G30+G32 -> 32 | I34: =I18 -> 12 | L34: Hasil Deserter

Sheet Slamet Fitriyono
A1: SKORING MSDT
B4: b | C4: b | D4: b | E4: a | F4: a | G4: a | H4: a | I4: a
B5: b | C5: a | D5: a | E5: b | F5: b | G5: b | H5: b | I5: b
B6: b | C6: a | D6: a | E6: b | F6: a | G6: b | H6: b | I6: b
B7: b | C7: b | D7: b | E7: a | F7: b | G7: a | H7: a | I7: b
B8: b | C8: b | D8: a | E8: b | F8: a | G8: a | H8: a | I8: b
B9: b | C9: b | D9: b | E9: a | F9: a | G9: b | H9: a | I9: a
B10: a | C10: b | D10: b | E10: b | F10: a | G10: b | H10: a | I10: b
B11: a | C11: b | D11: b | E11: a | F11: a | G11: a | H11: b | I11: b
A12: A | B12: 5 | C12: 2 | D12: 3 | E12: 3 | F12: 4 | G12: 3 | H12: 3 | I12: 5
A13: B | B13: 6 | C13: 6 | D13: 5 | E13: 4 | F13: 2 | G13: 4 | H13: 3 | I13: 6
A14: KOREKSI | B14: 1 | C14: 2 | D14: 1 | E14: 0 | F14: 3 | G14: -1 | H14: 0 | I14: -4
A15: JUMLAH | B15: =+B12+B13+B14 -> 12 | C15: =+C12+C13+C14 -> 10 | D15: =+D12+D13+D14 -> 9 | E15: =+E12+E13+E14 -> 7 | F15: =+F12+F13+F14 -> 9 | G15: =+G12+G13+G14 -> 6 | H15: =+H12+H13+H14 -> 6 | I15: =+I12+I13+I14 -> 7
C16: TO | E16: RO | G16: E | I16: O
A18: Ds ---- A | I18: =B15 -> 12
A20: Mi ---- B | E20: =C15 -> 10
A22: Au ---- C | C22: =D15 -> 9
A24: Co ---- D | C24: =E15 -> 7 | E24: =E15 -> 7
A26: Bu ---- E | G26: =F15 -> 9
A28: Dv ---- F | E28: =G15 -> 6 | G28: =G15 -> 6
A30: Ba ---- G | C30: =H15 -> 6 | G30: =H15 -> 6
A32: E ---- H | C32: =I15 -> 7 | E32: =I15 -> 7 | G32: =I15 -> 7
C34: =+C22+C24+C30+C32 -> 29 | E34: =+E20+E24+E28+E32 -> 30 | G34: =+G26+G28+G30+G32 -> 28 | I34: =I18 -> 12 | K34: hasil deserter

Sheet Bunga - Contoh
A1: SKORING MSDT
B4: b | C4: a | D4: a | E4: a | F4: a | G4: a | H4: a | I4: a
B5: b | C5: a | D5: a | E5: b | F5: b | G5: b | H5: a | I5: b
B6: a | C6: a | D6: a | E6: a | F6: a | G6: b | H6: b | I6: b
B7: b | C7: b | D7: b | E7: a | F7: b | G7: b | H7: a | I7: b
B8: b | C8: b | D8: b | E8: b | F8: a | G8: b | H8: a | I8: b
B9: a | C9: b | D9: b | E9: a | F9: a | G9: a | H9: a | I9: a
B10: b | C10: b | D10: a | E10: a | F10: a | G10: a | H10: a | I10: b
B11: a | C11: a | D11: a | E11: a | F11: a | G11: a | H11: a | I11: b
A12: A | B12: 7 | C12: 3 | D12: 5 | E12: 2 | F12: 2 | G12: 6 | H12: 5 | I12: 7
A13: B | B13: 5 | C13: 4 | D13: 3 | E13: 2 | F13: 2 | G13: 4 | H13: 1 | I13: 6
A14: KOREKSI | B14: 1 | C14: 2 | D14: 1 | E14: 0 | F14: 3 | G14: -1 | H14: 0 | I14: -4
A15: JUMLAH | B15: =+B12+B13+B14 -> 13 | C15: =+C12+C13+C14 -> 9 | D15: =+D12+D13+D14 -> 9 | E15: =+E12+E13+E14 -> 4 | F15: =+F12+F13+F14 -> 7 | G15: =+G12+G13+G14 -> 9 | H15: =+H12+H13+H14 -> 6 | I15: =+I12+I13+I14 -> 9
C16: TO | E16: RO | G16: E | I16: O
A18: Ds ---- A | I18: =B15 -> 13
A20: Mi ---- B | E20: =C15 -> 9
A22: Au ---- C | C22: =D15 -> 9
A24: Co ---- D | C24: =E15 -> 4 | E24: =E15 -> 4
A26: Bu ---- E | G26: =F15 -> 7
A28: Dv ---- F | E28: =G15 -> 9 | G28: =G15 -> 9
A30: Ba ---- G | C30: =H15 -> 6 | G30: =H15 -> 6
A32: E ---- H | C32: =I15 -> 9 | E32: =I15 -> 9 | G32: =I15 -> 9
C34: =+C22+C24+C30+C32 -> 28 | E34: =+E20+E24+E28+E32 -> 31 | G34: =+G26+G28+G30+G32 -> 31 | I34: =I18 -> 13 | K34: hasil deserter

Sheet Questionnaire
B2: SOAL MSDT
B15: 1 | C15: A | D15: Saya mengabaikan pelanggar-pelanggar peraturan bila saya merasa pasti bahwa tidak ada satu orangpun yang mengetahui tentang pelanggar-pelanggar tersebut. | M15: A | O15: 21 | P15: A | Q15: Adalah penting bagi saya untuk memperoleh nilai kredit bagi ideide saya yang baik. | AB15: 41 | AC15: A | AD15: Di dalam diskusi, saya memberikan fakta-fakta seperti apa yang mereka pahami, dan membiarkan mereka melukiskan kesimpulankesimpulan mereka sendiri. | AO15: 61 | AP15: A | AQ15: Saya percaya bahwa kenaikan jabatan adalah semata-mata berdasarkan kemampuan yang ada.
C18: B | D18: Bila saya mengumumkan suatu keputusan yang kurang menyenangkan, saya akan menjelaskan kepada bawahan saya bahwa keputusan ini dibuat oleh Direktur. | P18: B | Q18: B. Saya menyuarakan pendapat-pendapat saya di muka umum hanya bila saya merasa bahwa orang lain akan setuju dengan saya. | AC18: B | AD18: B. Bila Direktur memberikan perintah yang kurang menyenangkan, saya pikir adalah cukup bijaksana bila saya menyebutkan namanya dan bukan nama saya. | AP18: B | AQ18: B. Saya merasa bahwa masalah-masalah yang timbul di antara mereka sendiri, tanpa campur tangan dari saya.
B21: =1+B15 -> 2 | C21: A | D21: Bila ada seorang karyawan yang hasil kerjanya selalu tidak memuaskan saya, saya akan menunggu suatu kesempatan untuk memindahkannya dan bukan untuk memecatnya. | M21: B | O21: =O15+1 -> 22 | P21: A | Q21: Saya percaya bahwa Serikat-Serikat Buruh akan mencoba meruntuhkan kewibawaan pimpinan perusahaan. | AB21: =AB15+1 -> 42 | AC21: A | AD21: Bila ada tugas-tugas yang tidak dikehendaki yang harus dikerjakan, sebelumnya saya akan menanyakan kepada beberapa sukarelawan yang mau mengerjakan tugas tersebut. | AO21: =AO15+1 -> 62 | AP21: A | AQ21: Saya merasa bahwa Serikat-Serikat Buruh dan pimpinan perusahaan adalah bekerja untuk mencapai tujuan-tujuan yang sama.
C24: B | D24: Bila ada bawahan saya yang dikucilkan dari kelompok kerjanya, saya akan mencarikan cara-cara agar supaya orang lain dapat berteman dengannya. | P24: B | Q24: B. Saya percaya bahwa pertemuan-pertemuan yang sering dengan karyawan secara pribadi adalah membantu pengembangan diri mereka. | AC24: B | AD24: B. Saya menunjukkan minat saya terhadap kehidupan pribadi bawahan-bawahan saya, sebab saya merasa bahwa sayapun mengharapkan mereka berbuat seperti itu kepada saya. | AP24: B | AQ24: B. Di dalam diskusi, saya memberikan fakta-fakta seperti apa yang mereka pahami, dan membiarkan mereka melukiskan kesimpulan-kesimpulan mereka sendiri
B27: =1+B21 -> 3 | C27: A | D27: Bila Direktur memberikan perintah yang kurang menyenangkan, saya pikir adalah cukup bijaksana bila saya menyebutkan namanya dan bukan nama saya. | O27: =1+O21 -> 23 | P27: A | Q27: Saya merasa bahwa tidak terlalu perlu untuk bawahan-bawahan saya mengerti mengapa mereka mengerjakan seuatu hal sejauh mereka mengerjakan hal tersebut. | AB27: =1+AB21 -> 43 | AC27: A | AD27: Saya adalah seorang yang sangat memperhatikan kebahagiaan karyawan-karyawan saya di dalam mereka mengerjakan tugastugas mereka. | AO27: =1+AO21 -> 63 | AP27: A | AQ27: Bila seorang karyawan tidak sanggup menyelesaikan tugasnya, saya akan membantu dia untuk menyelesaikan tugas tersebut.
C30: B | D30: Saya biasanya membuat keputusan-keputusan saya sendiri dan menyampaikannya kepada bawahan saya. | P30: B | Q30: B. Saya merasa bahwa jam pencatat waktu datang dan pulangnya para pegawai, mengurangi keterlambatan. | AC30: B | AD30: B. Saya selalu memperhatikan mengenai keterlambatan dan kemangkiran. | AP30: B | AQ30: B. Saya merasa bahwa semua karyawan pada jabatan yang sama seharusnya memperoleh gaji yang sama.
B33: =1+B27 -> 4 | C33: A | D33: Bila saya ditegur oleh atasan saya, saya akan memanggil semua bawahan saya dan mengatakan semua teguran tersebut kepada mereka. | O33: =1+O27 -> 24 | P33: A | Q33: Saya biasanya membuat keputusan-keputusan saya sendiri dan menyampaikannya kepada bawahan saya. | AB33: =1+AB27 -> 44 | AC33: A | AD33: Sebagian besar dari bawahan-bawahan saya dapat menyelesaikan tugas-tugas mereka, bila perlu tanpa kehadiran saya. | AO33: =1+AO27 -> 64 | AP33: A | AQ33: Saya mengijinkan bawahan-bawahan saya untuk ikut serta di dalam pengambilan keputusan, tetapi sayapun menyediakan sesuatu yang jitu untuk membuat keputusan terakhir.
C36: B | D36: Saya selalu memberikan tugas-tugas yang sangat sulit kepada karyawan-karyawan yang paling berpengalaman | P36: B | Q36: B. Saya merasa bahwa Serikat-Serikat Buruh dan pimpinan perusahaan adalah bekerja untuk mencapai tujuan-tujuan yang sama. | AC36: B | AD36: B. Bila ada sesuatu tugas yang mendesak, walaupun semua peralatannya sesudah disediakan, saya akan membiarkannya saja dan mengatakan kepada salah seorang bawahan saya untuk mengerjakan tugas tersebut. | AP36: B | AQ36: B. Saya tidak akan ragu-ragu untuk mempekerjakan pegawaipegawai yang cacat jasmaninya, bilamana saya merasa bahwa dia dapat mempelajari pekerjaannya.
B39: =1+B33 -> 5 | C39: A | D39: Saya selalu melakukan diskusi-diskusi untuk mencapai kata sepakat. | O39: =1+O33 -> 25 | P39: A | Q39: Saya menyukai penggunaan dari skala penggajian karyawan. | AB39: =1+AB33 -> 45 | AC39: A | AD39: Saya percaya bahwa bawahan-bawahan saya akan merasakan kepuasan kerja mereka tanpa merasakan tekanan apapun dari saya.
C42: B | D42: Saya selalu menganjurkan kepada bawahan saya untuk memberikan usul-usul, tetapi kadang-kadang juga saya langsung membuat suatu tindakan tertentu. | P42: B | Q42: B. Saya selalu melakukan diskusi-diskusi untuk mencapai kata sepakat. | AC42: B | AD42: B. Saya memberikan informasi kepada “Dewan Direksi” tidak lebih daripada apa yang mereka tanyakan.
B45: =1+B39 -> 6 | C45: A | D45: Kadang-kadang saya berpikir bahwa perasaan-perasaan saya dan sikap-sikap saya adalah mementingkan tugas saya. | O45: =1+O39 -> 26 | P45: A | Q45: Saya merasa bangga di dalam kenyataannya bahwa saya biasanya tidak akan menanyakan kepada seseorang untuk mengerjakan suatu tugas yang kalau untuk saya sendiri, tidak akan saya kerjakan. | AB45: =1+AB39 -> 46 | AC45: A | AD45: Saya percaya bahwa pertemuan-pertemuan yang sering dengan karyawan secara pribadi adalah membantu pengembangan diri mereka.
C48: B | D48: Saya mengijinkan bawahan-bawahan saya untuk ikut serta mengambil keputusan yang dibuat berdasarkan atas suara terbanyak. | P48: B | Q48: B. Saya berpikir bahwa bila beberapa bawahan saya merasa tidak berbahagia, saya akan mencoba melakukan sesuatu mengenai hal tersebut. | AC48: B | AD48: B. Saya adalah seorang yang sangat memperhatikan karyawankaryawan saya di dalam mereka mengerjakan tugas-tugas mereka.
B51: =1+B45 -> 7 | C51: A | D51: Bila jumlah dan mutu hasil kerja bagian saya tidak memuaskan, saya menjelaskan kepada bawahan-bawahan saya bahwa Direktur merasa kecewa dan oleh karena itu mereka harus memperbaiki kerja mereka. | O51: =1+O45 -> 27 | P51: A | Q51: Bila ada suatu tugas yang mendesak, walaupun semua peralatannya sudah disediakan saya akan membiarkannya saja, dan mengatakan kepada salah seorang bawahan saya untuk mengerjakan sesuatu tugas tersebut. | AB51: =1+AB45 -> 47 | AC51: A | AD51: Saya menunjukkan persetujuan untuk meningkatkan pengetahuan tentang pekerjaan dan perusahaan dari bawahanbawahan saya, walaupun hal itu sebenarnya belum diperlukan untuk kedudukan mereka sekarang.
C54: B | D54: Saya membuat keputusan-keputusan sendiri dan kemudian saya mencoba untuk menjual keputusan-keputusan itu kepada bawahan saya. | P54: B | Q54: B. Adalah penting bagi saya untuk memperoleh nilai kredit bagi ideide saya yang baik. | AC54: B | AD54: B. Saya mengawasi benar bawahan-bawahan saya yang kurang mahir di dalam bekerjanya atau bawahan-bawahan saya yang hasil kerjanya kurang memuaskan.
B57: =1+B51 -> 8 | C57: A | D57: Bila saya mengumumkan suatu keputusan yang kurang menyenangkan, saya akan menjelaskan kepada bawahan saya bahwa keputusan ini dibuat oleh Direktur. | O57: =1+O51 -> 28 | P57: A | Q57: Tujuan saya adalah mencapai bagaimana tugas-tugas dapat dikerjakan, tanpa saya merasa lebih benci daripada siapapun yang mengerjakan. | AB57: =1+AB51 -> 48 | AC57: A | AD57: Saya mengijinkan bawahan-bawahan saya untuk ikut serta mengambil keputusan dan saya selalu mematuhi keputusan yang dibuat berdasarkan atas suara terbanyak.
C60: B | D60: Saya mengijinkan bawahan-bawahan saya untuk ikut serta di dalam pengambilan keputusan, tetapi sayapun menyediakan sesuatu keputusan terakhir. | P60: B | Q60: B. Saya mungkin menentukan tugas-tugas tanpa banyak mempertimbangkan pengalaman atau kemampuan, tetapi saya lebih menuntut pada pencapaian hasil-hasilnya saja. | AC60: B | AD60: B. Saya membuat bawahan-bawahan saya bekerja keras, dan saya berusaha menyakinkan mereka bahwa biasanya mereka mendapat perlakukan yang adil dari “Dewan Direksi”.
B63: =1+B57 -> 9 | C63: A | D63: Saya akan memberikan tugas-tugas yang sulit kepada bawahan saya yang belum berpengalaman, tetapi bila mereka memperoleh kesukaran, saya akan mengambil alih tanggung jawab mereka. | O63: =1+O57 -> 29 | P63: A | Q63: Saya mungkin menentukan tugas-tugas tanpa banyak mempertimbangkan pengalaman atau kemampuan, tetapi saya lebih menuntut pada pencapaian hasil-hasilnya saja. | AB63: =1+AB57 -> 49 | AC63: A | AD63: Saya merasa bahwa semua karyawan pada jabatan yang sama seharusnya memperoleh gaji yang sama.
C66: B | D66: Bila jumlah dan mutu hasil kerja bagian saya tidak memuaskan, saya menjelaskan kepada bawahan-bawahan saya bahwa Direktur merasa kecewa dan oleh karena itu mereka harus memperbaiki mutu kerja mereka itu. | P66: B | Q66: B. Saya dengan sabar mendengarkan keluhan-keluhan dan ketidakpuasan-ketidakpuasan dari bawahan saya tetapi seringkali saya meralat apa yang mereka katakan. | AC66: B | AD66: B. Bila ada seorang karyawan yang hasil kerjanya selalu tidak memuaskan saya, saya akan menunggu suatu kesempatan untuk memindahkannya dan bukan untuk memecatnya.
B69: =1+B63 -> 10 | C69: A | D69: Saya merasa bahwa adalah penting agar bawahan-bawahan menyukai saya apabila saya bekerja keras untuk mereka. | O69: =1+O63 -> 30 | P69: A | Q69: Saya merasa bahwa keluhan-keluhan tidak dapat dicegah dan saya mencoba sebaik mungkin untuk dapat dilenyapkan. | AB69: =1+AB63 -> 50 | AC69: A | AD69: Saya merasa bahwa tujuan-tujuan Serikat Buruh dan tujuantujuan perusahaan adalah saling berbeda dan saya mencoba untuk tidak membuat pandangan saya secara jelas.
C72: B | D72: Saya membiarkan orang-orang lain menangani tugas-tugas mereka masing-masing, walaupun mereka membuat banyak kesalahan. | P72: B | Q72: B. Saya percaya bahwa bawahan-bawahan saya akan merasakan kepuasan kerja mereka tanpa merasakan tekanan apapun dari saya. | AC72: B | AD72: B. Saya merasa bahwa adalah penting agar bawahan saya menyukai saya apabila saya bekerja keras untuk mereka.
B75: =1+B69 -> 11 | C75: A | D75: Saya menunjukkan minat saya terhadap kehidupan pribadi bawahan-bawahan saya, sebab saya merasa bahwa saya mengerti mengapa mereka mengerjakan sesuatu hal sejauh mereka mengerjakan hal tersebut. | O75: =1+O69 -> 31 | P75: A | Q75: Bila menghadapi masalah yang sulit, saya berusaha untuk mencapai pemecahan yang paling sedikit bisa diterima oleh sebagian besar orang-orang yang bersangkutan. | AB75: =1+AB69 -> 51 | AC75: A | AD75: Saya mengawasi benar bawahan-bawahan saya yang kurang mahir di dalam bekerjanya atau bawahan-bawahan saya yang hasil kerjanya kurang memuaskan.
C78: B | D78: Saya saya merasa bahwa adalah tidak terlalu perlu untuk bawahan-bawahan saya mengerti mengapa mereka mengerjakan sesuatu hal sejauh mereka mengerjakan hal tersebut. | P78: B | Q78: B. Saya percaya bahwa latihan melalui pengalaman bekerja, adalah lebih bermanfaat daripada pendidikan teoritis | AC78: B | AD78: B. Saya mencela pembicaraan-pembicaraan yang tidak perlu di antara bawahan-bawahan saya selama mereka bekerja.
B81: =1+B75 -> 12 | C81: A | D81: Saya percaya bahwa bawahan-bawahan yang disiplin tidak akan memperbaiki jumlah atau mutu kerja mereka di dalam jangka waktu yang panjang. | O81: =1+O75 -> 32 | P81: A | Q81: Saya selalu memberikan tugas-tugas yang sangat sulit kepada karyawan-karyawan yang paling berpengalaman. . | AB81: =1+AB75 -> 52 | AC81: A | AD81: Bila saya memberikan perintah kepada bawahan-bawahan saya, saya menentukan batas waktu untuk mereka menyelesaikannya.
C84: B | D84: Bila menghadapi masalah yang sulit, saya berusaha untuk mencapai pemecahan yang paling sedikit bisa diterima oleh sebagian besar orang-orang yang bersangkutan. | P84: B | Q84: B. Saya percaya bahwa kenaikan jabatan adalah semata-mata berdasarkan kemampuan yang ada | AC84: B | AD84: B. Saya merasa bangga di dalam kenyataannya bahwa saya biasanya tidak akan menanyakan kepada seseorang untuk mengerjakan suatu tugas yang kalau saya sendiri tidak akan saya kerjakan.
B87: =1+B81 -> 13 | C87: A | D87: Saya berpikir bahwa bila beberapa bawahan saya merasa tidak berbahagia, saya akan mencoba melakukan sesuatu mengenai hal tersebut. | O87: =1+O81 -> 33 | P87: A | Q87: Saya merasa bahwa masalah-masalah yang timbul di antara para karyawan biasanya akan dapat diselesaikan di antara mereka sendiri, tanpa campur tangan dari saya. | AB87: =1+AB81 -> 53 | AC87: A | AD87: Saya percaya bahwa latihan melalui pengalaman bekerja, adalah lebih bermanfaat daripada pendidikan teoritis.
C90: B | D90: Saya mengurusi pekerjaan saya sendiri dan saya merasa bahwa pekerjaan saya itu bisa mencapai “Dewan Direksi” untuk mengembangkan ide-ide baru. | P90: B | Q90: B. Bila saya ditegur oleh atasan saya, saya akan memanggil semua bawahan saya dan mengatakan semua teguran tersebut kepada mereka. | AC90: B | AD90: B. Saya tidak peduli dengan apa yang dikerjakan oleh para pegawai saya di luar jam kantornya.
B93: =1+B87 -> 14 | C93: A | D93: Saya menyetujui kenaikan tunjangan-tunjangan untuk staf dan karyawan. | O93: =1+O87 -> 34 | P93: A | Q93: Saya tidak peduli dengan apa yang dikerjakan oleh karyawan saya di luar jam kerja kantornya. | AB93: =1+AB87 -> 54 | AC93: A | AD93: Saya merasa bahwa jam pencatat waktu datang dan pulangnya para pegawai, mengurangi keterlambatan.
C96: B | D96: Saya menunjukkan persetujuan untuk meningkatkan pengetahuan tentang pekerjaan dan perusahaan dari bawahanbawahan saya, walaupun hal itu sebenarnya belum diperlukan untuk kedudukan mereka sekarang. | P96: B | Q96: B. Saya percaya bahwa bawahan-bawahan yang disiplin tidak akan memperbaiki jumlah atau mutu kerja mereka di dalam jangka waktu panjang. | AC96: B | AD96: B. Saya mengijinkan bawahan-bawahan saya untuk ikut serta mengambil keputusan dan saya selalu mematuhi keputusan yang dibuat berdasarkan atas suara terbanyak
B99: =1+B93 -> 15 | C99: A | D99: Saya membiarkan orang-orang lain menangani tugas-tugas mereka masing-masing, walaupun mereka membuat banyak kesalahan. | O99: =1+O93 -> 35 | P99: A | Q99: Saya memberikan informasi kepada “Dewan Direksi” tidak lebih dari pada apa yang mereka tanyakan. | AB99: =1+AB93 -> 55 | AC99: A | AD99: Saya mengambil keputusan-keputusan saya sendiri, tetapi saya dapat mempertimbangkan saran-saran yang wajar dari bawahanbawahan saya untuk saya manfaatkan, bilamana saya bertanya kepada mereka.
C102: B | D102: B. Saya membuat keputusan-keputusan sendiri tetapi saya akan mempertimbangkan usul-usul yang masuk di akal dari bawahanbawahan saya yang untuk memperbaiki keputusan tersebut apabila saya bertanya kepada mereka. | P102: B | Q102: B. Kadang-kadang saya menentang keluhan-keluhan Serikat Buruh sebagai sesuatu perkara yang prinsipil. | AC102: B | AD102: B. Saya merasa bahwa tujuan-tujuan Serikat Buruh dan tujuantujuan perusahaan adalah saling berbeda, dan saya mencoba untuk tidak membuat pandangan saya secara jelas.
B105: =1+B99 -> 16 | C105: A | D105: Bila ada bawahan saya yang dikucilkan dari kelompok kerjanya, saya akan mencarikan cara-cara agar supaya orang lain dapat berteman dengannya. | O105: =1+O99 -> 36 | P105: A | Q105: Saya kadang-kadang merasa ragu-ragu untuk membuat suatu keputusan yang akan tidak disukai oleh bawahan-bawahan saya. | AB105: =1+AB99 -> 56 | AC105: A | AD105: Saya membuat keputusan-keputusan sendiri dan kemudian saya mencoba untuk “menjual” keputusan-keputusan itu kepada bawahan saya.
C108: B | D108: B. Bila seorang karyawan tidak sanggup menyelesaikan tugasnya, saya akan membantu dia untuk menyelesaikan tugas tersebut | P108: B | Q108: B. Tujuan saya adalah mencapai bagaimana tugas-tugas dapat dikerjakan, tanpa saya merasa lebih benci daripada siapapun yang mengerjakannya. | AC108: B | AD108: B. Apabila mungkin saya membentuk kelompok-kelompok kerja yang terdiri dari orang-orang yang sudah menjadi teman-teman baik saya.
B111: =1+B105 -> 17 | C111: A | D111: Saya percaya bahwa suatu penerapan disiplin adalah merupakan seperangkat contoh untuk karyawan-karyawan lainnya. | O111: =1+O105 -> 37 | P111: A | Q111: Saya dengan sabar mendengarkan keluhan-keluhan dan ketidakpuasan–ketidakpuasan dari bawahan saya, tetapi seringkali saya meralat apa yang mereka katakan. | AB111: =1+AB105 -> 57 | AC111: A | AD111: Saya tidak akan ragu-ragu untuk mempekerjakan pegawaipegawai yang cacat jasmaninya, bilamana saya merasa pasti bahwa dia dapat mempelajari pekerjannya.
C114: B | D114: B. Kadang-kadang saya berpikir bahwa perasaan-perasaan saya dan sikap-sikap saya adalah mementingkan tugas saya. | P114: B | Q114: B. Saya kadang-kadang merasa ragu-ragu untuk membuat keputusan-keputusan yang akan tidak disukai oleh bawahanbawahan saya. | AC114: B | AD114: B. Saya mengabaikan pelanggar-pelanggar peraturan bila saya merasa pasti bahwa tidak ada satu orangpun yang mengetahui tentang pelanggaran-pelanggaran tersebut.
B117: =1+B111 -> 18 | C117: A | D117: Saya mencela pembicaraan-pembicaraan yang tidak perlu di antara bawahan-bawahan saya selama mereka bekerja. | O117: =1+O111 -> 38 | P117: A | Q117: Saya menyuarakan pendapat-pendapat saya di muka umum hanya bila saya merasa bahwa orang lain akan setuju dengan saya. | AB117: =1+AB111 -> 58 | AC117: A | AD117: Apabila mungkin saya membentuk kelompok-kelompok kerja yang terdiri dari orang-orang yang sudah menjadi teman-teman baik saya.
C120: B | D120: B. Saya menyetujui tunjangan-tunjangan untuk staf dan karyawankaryawan. | P120: B | Q120: B. Sebagian besar dari bawahan-bawahan saya dapat menyelesaikan tugas-tugas mereka, bila perlu, tanpa kehadiran saya. | AC120: B | AD120: B. Saya akan memberikan tugas-tugas yang sulit kepada bawahanbawahan saya yang berpengalaman, tetapi bila mereka memperoleh kesukaran, saya akan mengambil alih tanggung jawab mereka.
B123: =1+B117 -> 19 | C123: A | D123: Saya selalu memperhatikan mengenai keterlambatan dan kemangkiran. | O123: =1+O117 -> 39 | P123: A | Q123: Saya mengurusi pekerjaan saya sendiri, dan saya merasa bahwa pekerjaan saya itu bisa mencapai “Dewan Direksi” untuk mengembangkan ide-ide baru. | AB123: =1+AB117 -> 59 | AC123: A | AD123: Saya membuat bawahan-bawahan saya bekerja keras, dan saya berusaha meyakinkan mereka bahwa biasanya mereka mendapat perlakuan yang adil dari “Dewan Direksi”.
C126: B | D126: B. Saya percaya bahwa Serikat-Serikat Buruh akan mencoba untuk meruntuhkan kewibawaan pimpinan perusahaan. | P126: B | Q126: B. Bila saya memberikan perintah kepada bawahan-bawahan saya, saya menentukan batas waktu untuk mereka menyelesaikannya. | AC126: B | AD126: B. Saya percaya bahwa suatu penerapan disiplin adalah merupakan seperangkat contoh untuk karyawan-karyawan lainnya.
B129: =1+B123 -> 20 | C129: A | D129: Kadang-kadang saya menentang keluhan-keluhan serikat buruh sebagai suatu perkara yang prinsipil. | O129: =1+O123 -> 40 | P129: A | Q129: Saya selalu menganjurkan kepada bawahan saya untuk memberikan usul-usul, tetapi kadang-kadang juga saya langsung membuat suatu tindakan tertentu. | AB129: =1+AB123 -> 60 | AC129: A | AD129: Saya mencoba untuk membuat bawahan-bawahan saya merasa senang hatinya apabila mereka berbicara dengan saya.
...

Sheet Otomatis Scoring
B2: SKORING MSDT
C5: =Questionnaire!M15 -> A | D5: =Questionnaire!M21 -> B | E5: =Questionnaire!M27 | F5: =Questionnaire!M33 | G5: =Questionnaire!M39 | H5: =Questionnaire!M45 | I5: =Questionnaire!M51 | J5: =Questionnaire!M57 | K5: 8
C6: =Questionnaire!M63 | D6: =Questionnaire!M69 | E6: =Questionnaire!M75 | F6: =Questionnaire!M81 | G6: =Questionnaire!M87 | H6: =Questionnaire!M93 | I6: =Questionnaire!M99 | J6: =Questionnaire!M105 | K6: 16
C7: =Questionnaire!M111 | D7: =Questionnaire!M117 | E7: =Questionnaire!M123 | F7: =Questionnaire!M129 | G7: =Questionnaire!Z15 | H7: =Questionnaire!Z21 | I7: =Questionnaire!Z27 | J7: =Questionnaire!Z33 | K7: 24
C8: =Questionnaire!Z39 | D8: =Questionnaire!Z45 | E8: =Questionnaire!Z51 | F8: =Questionnaire!Z57 | G8: =Questionnaire!Z63 | H8: =Questionnaire!Z69 | I8: =Questionnaire!Z75 | J8: =Questionnaire!Z81 | K8: 32
C9: =Questionnaire!Z87 | D9: =Questionnaire!Z93 | E9: =Questionnaire!Z99 | F9: =Questionnaire!Z105 | G9: =Questionnaire!Z111 | H9: =Questionnaire!Z117 | I9: =Questionnaire!Z123 | J9: =Questionnaire!Z129 | K9: 40
C10: =Questionnaire!$AM15 | D10: =Questionnaire!$AM21 | E10: =Questionnaire!$AM27 | F10: =Questionnaire!$AM33 | G10: =Questionnaire!$AM39 | H10: =Questionnaire!$AM45 | I10: =Questionnaire!$AM51 | J10: =Questionnaire!$AM57 | K10: 48
C11: =Questionnaire!$AM63 | D11: =Questionnaire!$AM69 | E11: =Questionnaire!$AM75 | F11: =Questionnaire!$AM81 | G11: =Questionnaire!$AM87 | H11: =Questionnaire!$AM93 | I11: =Questionnaire!$AM99 | J11: =Questionnaire!$AM105 | K11: 56
C12: =Questionnaire!$AM111 | D12: =Questionnaire!$AM117 | E12: =Questionnaire!$AM123 | F12: =Questionnaire!$AM129 | G12: =Questionnaire!AZ15 | H12: =Questionnaire!AZ21 | I12: =Questionnaire!AZ27 | J12: =Questionnaire!AZ33 | K12: 64
B13: A | C13: =COUNTIF(C5:J5,"A") -> 1 | D13: =COUNTIF($C6:$J6,"A") -> 0 | E13: =COUNTIF($C7:$J7,"A") -> 0 | F13: =COUNTIF($C8:$J8,"A") -> 0 | G13: =COUNTIF($C9:$J9,"A") -> 0 | H13: =COUNTIF($C10:$J10,"A") -> 0 | I13: =COUNTIF($C11:$J11,"A") -> 0 | J13: =COUNTIF($C12:$J12,"A") -> 0
B14: B | C14: =COUNTIF(C5:C12,"B") -> 0 | D14: =COUNTIF(D5:D12,"B") -> 1 | E14: =COUNTIF(E5:E12,"B") -> 0 | F14: =COUNTIF(F5:F12,"B") -> 0 | G14: =COUNTIF(G5:G12,"B") -> 0 | H14: =COUNTIF(H5:H12,"B") -> 0 | I14: =COUNTIF(I5:I12,"B") -> 0 | J14: =COUNTIF(J5:J12,"B") -> 0
B15: KOREKSI | C15: 1 | D15: 2 | E15: 1 | F15: 0 | G15: 3 | H15: -1 | I15: 0 | J15: -4
B16: JUMLAH | C16: =+C13+C14+C15 -> 2 | D16: =+D13+D14+D15 -> 3 | E16: =+E13+E14+E15 -> 1 | F16: =+F13+F14+F15 -> 0 | G16: =+G13+G14+G15 -> 3 | H16: =+H13+H14+H15 -> -1 | I16: =+I13+I14+I15 -> 0 | J16: =+J13+J14+J15 -> -4
D17: TO | F17: RO | H17: E | J17: O
B19: Ds ---- A | J19: =C16 -> 2
B21: Mi ---- B | F21: =D16 -> 3
B23: Au ---- C | D23: =E16 -> 1
B25: Co ---- D | D25: =F16 -> 0 | F25: =F16 -> 0
B27: Bu ---- E | H27: =G16 -> 3
B29: Dv ---- F | F29: =H16 -> -1 | H29: =H16 -> -1
B31: Ba ---- G | D31: =I16 -> 0 | H31: =I16 -> 0
B33: E ---- H | D33: =J16 -> -4 | F33: =J16 -> -4 | H33: =J16 -> -4
D35: =+D23+D25+D31+D33 -> -3 | F35: =+F21+F25+F29+F33 -> -2 | H35: =+H27+H29+H31+H33 -> -2 | J35: =J19 -> 2 | L35: hasil deserter
D37: KONVERSI
D38: =IF(D35<30,0,IF(D35<32,0.6,IF(D35=32,1.2,IF(D35=33,1.8,IF(D35=34,2.4,IF(D35=35,3,IF(D35<38,3.6,4))))))) -> 0 | F38: =IF(F35<30,0,IF(F35<32,0.6,IF(F35=32,1.2,IF(F35=33,1.8,IF(F35=34,2.4,IF(F35=35,3,IF(F35<38,3.6,4))))))) -> 0 | H38: =IF(H35<30,0,IF(H35<32,0.6,IF(H35=32,1.2,IF(H35=33,1.8,IF(H35=34,2.4,IF(H35=35,3,IF(H35<38,3.6,4))))))) -> 0 | J38: =IF(J35<30,0,IF(J35<32,0.6,IF(J35=32,1.2,IF(J35=33,1.8,IF(J35=34,2.4,IF(J35=35,3,IF(J35<38,3.6,4))))))) -> 0
D39: TO | F39: RO | H39: E | J39: O
D41: HASIL
D42: E | E42: Co | F42: Ba | G42: Au | H42: Dv | I42: Mi | J42: Bu | K42: Ds
D43: =IF($D$38>2,IF($F$38>2,IF($H$38>2,"Ok",""),""),"") | E43: =IF($D$38>2,IF($F$38>2,IF($H$38<2,"Ok",""),""),"") | F43: =IF($D$38>2,IF($F$38<2,IF($H$38>2,"Ok",""),""),"") | G43: =IF($D$38>2,IF($F$38<2,IF($H$38<2,"Ok",""),""),"") | H43: =IF($D$38<2,IF($F$38>2,IF($H$38>2,"Ok",""),""),"") | I43: =IF($D$38<2,IF($F$38>2,IF($H$38<2,"Ok",""),""),"") | J43: =IF($D$38<2,IF($F$38<2,IF($H$38>2,"Ok",""),""),"") | K43: =IF($D$38<2,IF($F$38<2,IF($H$38<2,"Ok",""),""),"") -> Ok
