Workbook

Sheet Soal
E1: KODE : AQ
A2: Petunjuk :
A3: Isilah lembar jawaban dengan memberi tanda silang pada setiap jawaban yang sesuai dengan diri anda !
A5: 1. Bagi saya, kesulitan adalah :
B6: a. Sesuatu yang harus dihindari
B7: b. Sesuatu yang bisa dicoba untuk dihadapi
B8: c. Bagian dari hidup. Menghindari kesulitan sama saja dengan menghindari kehidupan
A10: 2. Keyakinan saya terhadap masa depan adalah :
B11: a. Saya tidak berani menjamin, saya akan menunggu dan melihat bagaimana nantinya
B12: b. Melihat kemampuan yang sekarang ini, saya cukup yakin dengan masa depan saya
B13: c. Saya belum seberapa yakin, tetapi saya berharap bisa berhasil
A15: 3. Jika saya dihadapkan pada suatu masalah yang menurut saya sangat sulit dicapai keberhasilannya
A16: maka tanggapannya saya adalah :
B17: a. Saya akan mengerjakannya, tidak peduli betapapun sulitnya
B18: b. Saya akan mencoba, namun jika keadaannya bertambah buruk saya akan berhenti
B19: c. Saya tidak mau mengerjakannya, karena ini mustahil bisa berhasil
A21: 4. Saya adalah orang yang :
B22: a. Kadang-kadang menyerah tergantung situasi dan kondisi
B23: b. Mudah menyerah
B24: c. Pantang menyerah
A26: 5. Bagi saya, pengembangan diri adalah :
B27: a. Cukup perlu
B28: b. Hal yang tidak seberapa perlu
B29: c. Segalanya
A31: 6. Sikap saya terhadap perubahan adalah :
B32: a. Saya selalu menerima perubahan yang ditawarkan kepada saya
B33: b. Saya agak sulit menyesuaikan diri dengan perubahan yang terjadi
B34: c. Saya akan lihat dulu perubahan yang seperti apa, baru saya bisa memutuskannya
A36: 7. Saya tergolong sebagai orang yang :
B37: a. Menunjukkan beberapa usaha jika memang diperlukan
B38: b. Ambisius
B39: c. Santai, tidak terlalu berambisi
A41: 8. Diantara tiga hal dibawah ini, yang paling sesuai dengan keadaan diri saya :
B42: a. Saya sudah puas dengan kehidupan saya sekarang ini
B43: b. Dalam hal tertentu saya sudah puas
B44: c. Masih banyak hal yang perlu saya capai
A46: 9. Jika menghadapi masalah yang sangat sulit saya cenderung :
B47: a. Menghadapi dan menyelesaikan hingga saya berhasil
B48: b. Menghindarinya
B49: c. Menghadapinya namun jika merasa tidak mampu maka saya akan berhenti
...

Sheet Lembar Jwb
I1: KODE : AQ
A2: LEMBAR JAWABAN
A4: Nama | C4: : | E4: Jenis Kelamin | G4: : L / P
A5: Usia | C5: : | E5: Tanggal Tes | G5: :
A9: 1. | C9: a | D9: b | E9: c
A10: 2. | C10: a | D10: b | E10: c
A11: 3. | C11: a | D11: b | E11: c
A12: 4. | C12: a | D12: b | E12: c
A13: 5. | C13: a | D13: b | E13: c
A14: 6. | C14: a | D14: b | E14: c
A15: 7. | C15: a | D15: b | E15: c
A16: 8. | C16: a | D16: b | E16: c
A17: 9. | C17: a | D17: b | E17: c
A18: 10. | C18: a | D18: b | E18: c
A19: 11. | C19: a | D19: b | E19: c
A20: 12. | C20: a | D20: b | E20: c
... A23: 15. | C23: a | D23: b | E23: c

Sheet Interpretasi
A1: HASIL TES ADVERSITY QUOTIENT
A4: Nama | K4: Jenis Kelamin | M4: Laki-Laki
A5: Usia | C5: 42 Tahun | K5: Tanggal Tes | M5: 14 Maret 2012
G10: TIPE : | I10: =Kode!G141 -> CAMPER
A12: NO | B12: JAWABAN | G12: PENJELASAN :
B13: (a / b / c) | D13: Q | E13: Ca | F13: Cl | G13: =IF(Kode!$E$141=1,Kode!F$1,IF(Kode!$E$141=2,Kode!F$2,IF(Kode!$E$141=3,Kode!F$3,""))) -> 201 | H13: =IF(((VLOOKUP(G13,Kode!$A$144:$B$194,2,0))=0),"",(VLOOKUP(G13,Kode!$A$144:$B$194,2,0))) -> - Mau berusaha untuk mendaki, namun berhenti pada satu titik tertentu
A14: 1 | B14: b | C14: =IF(B14="a","Q",IF(B14="b","Ca",IF(B14="c","Cl",""))) -> Ca | D14: =IF(($C14="Q"),1,"") | E14: =IF(($C14="Ca"),1,"") -> 1 | F14: =IF(($C14="Cl"),1,"") | G14: =IF(Kode!$E$141=1,Kode!G$1,IF(Kode!$E$141=2,Kode!G$2,IF(Kode!$E$141=3,Kode!G$3,""))) -> 202 | H14: =IF(((VLOOKUP(G14,Kode!$A$144:$B$194,2,0))=0),"",(VLOOKUP(G14,Kode!$A$144:$B$194,2,0))) -> - Cukup puas saat mencapai suatu tahapan tertentu
A15: 2 | B15: b | C15: =IF(B15="a","Q",IF(B15="b","Cl",IF(B15="c","Ca",""))) -> Cl | D15: =IF(($C15="Q"),1,"") | E15: =IF(($C15="Ca"),1,"") | F15: =IF(($C15="Cl"),1,"") -> 1 | G15: =IF(Kode!$E$141=1,Kode!H$1,IF(Kode!$E$141=2,Kode!H$2,IF(Kode!$E$141=3,Kode!H$3,""))) -> 203 | H15: =IF(((VLOOKUP(G15,Kode!$A$144:$B$194,2,0))=0),"",(VLOOKUP(G15,Kode!$A$144:$B$194,2,0))) -> - Masih memiliki sejumlah inisiatif, sedikit semangat dan beberapa usaha
A16: 3 | B16: a | C16: =IF(B16="a","Cl",IF(B16="b","Ca",IF(B16="c","Q",""))) -> Cl | D16: =IF(($C16="Q"),1,"") | E16: =IF(($C16="Ca"),1,"") | F16: =IF(($C16="Cl"),1,"") -> 1 | G16: =IF(Kode!$E$141=1,Kode!I$1,IF(Kode!$E$141=2,Kode!I$2,IF(Kode!$E$141=3,Kode!I$3,""))) -> 204 | H16: =IF(((VLOOKUP(G16,Kode!$A$144:$B$194,2,0))=0),"",(VLOOKUP(G16,Kode!$A$144:$B$194,2,0))) -> - Mampu mengorbankan kemampuan pribadinya demi mendapat kepuasan
A17: 4 | B17: c | C17: =IF(B17="a","Ca",IF(B17="b","Q",IF(B17="c","Cl",""))) -> Cl | D17: =IF(($C17="Q"),1,"") | E17: =IF(($C17="Ca"),1,"") | F17: =IF(($C17="Cl"),1,"") -> 1 | G17: =IF(Kode!$E$141=1,Kode!J$1,IF(Kode!$E$141=2,Kode!J$2,IF(Kode!$E$141=3,Kode!J$3,""))) -> 205 | H17: =IF(((VLOOKUP(G17,Kode!$A$144:$B$194,2,0))=0),"",(VLOOKUP(G17,Kode!$A$144:$B$194,2,0))) -> - Mampu membina hubungan dengan camper lainnya
A18: 5 | B18: a | C18: =IF(B18="a","Ca",IF(B18="b","Q",IF(B18="c","Cl",""))) -> Ca | D18: =IF(($C18="Q"),1,"") | E18: =IF(($C18="Ca"),1,"") -> 1 | F18: =IF(($C18="Cl"),1,"") | G18: =IF(Kode!$E$141=1,Kode!K$1,IF(Kode!$E$141=2,Kode!K$2,IF(Kode!$E$141=3,Kode!K$3,""))) -> 206 | H18: =IF(((VLOOKUP(G18,Kode!$A$144:$B$194,2,0))=0),"",(VLOOKUP(G18,Kode!$A$144:$B$194,2,0))) -> - Menahan diri terhadap perubahan sekalipun itu adalah perubahan besar
A19: 6 | B19: c | C19: =IF(B19="a","Cl",IF(B19="b","Q",IF(B19="c","Ca",""))) -> Ca | D19: =IF(($C19="Q"),1,"") | E19: =IF(($C19="Ca"),1,"") -> 1 | F19: =IF(($C19="Cl"),1,"") | G19: =IF(Kode!$E$141=1,Kode!L$1,IF(Kode!$E$141=2,Kode!L$2,IF(Kode!$E$141=3,Kode!L$3,""))) -> 207 | H19: =IF(((VLOOKUP(G19,Kode!$A$144:$B$194,2,0))=0),"",(VLOOKUP(G19,Kode!$A$144:$B$194,2,0))) -> karena merasa nyaman dengan kondisi yang ada
A20: 7 | B20: a | C20: =IF(B20="a","Ca",IF(B20="b","Cl",IF(B20="c","Q",""))) -> Ca | D20: =IF(($C20="Q"),1,"") | E20: =IF(($C20="Ca"),1,"") -> 1 | F20: =IF(($C20="Cl"),1,"") | G20: =IF(Kode!$E$141=1,Kode!M$1,IF(Kode!$E$141=2,Kode!M$2,IF(Kode!$E$141=3,Kode!M$3,""))) -> 208 | H20: =IF(((VLOOKUP(G20,Kode!$A$144:$B$194,2,0))=0),"",(VLOOKUP(G20,Kode!$A$144:$B$194,2,0))) -> - Menggunakan kata - kata yang bersifat kompromistis, seperti :
A21: 8 | B21: b | C21: =IF(B21="a","Q",IF(B21="b","Ca",IF(B21="c","Cl",""))) -> Ca | D21: =IF(($C21="Q"),1,"") | E21: =IF(($C21="Ca"),1,"") -> 1 | F21: =IF(($C21="Cl"),1,"") | G21: =IF(Kode!$E$141=1,Kode!N$1,IF(Kode!$E$141=2,Kode!N$2,IF(Kode!$E$141=3,Kode!N$3,""))) -> 209 | H21: =IF(((VLOOKUP(G21,Kode!$A$144:$B$194,2,0))=0),"",(VLOOKUP(G21,Kode!$A$144:$B$194,2,0))) -> "ini cukup bagus", "cukup sampai di sini saja", dll
A22: 9 | B22: a | C22: =IF(B22="a","Cl",IF(B22="b","Q",IF(B22="c","Ca",""))) -> Cl | D22: =IF(($C22="Q"),1,"") | E22: =IF(($C22="Ca"),1,"") | F22: =IF(($C22="Cl"),1,"") -> 1 | G22: =IF(Kode!$E$141=1,Kode!O$1,IF(Kode!$E$141=2,Kode!O$2,IF(Kode!$E$141=3,Kode!O$3,""))) -> 210 | H22: =IF(((VLOOKUP(G22,Kode!$A$144:$B$194,2,0))=0),"",(VLOOKUP(G22,Kode!$A$144:$B$194,2,0))) -> - Prestasi yang tidak tinggi dan kontribusi yang tidak besar juga
A23: 10 | B23: a | C23: =IF(B23="a","Cl",IF(B23="b","Q",IF(B23="c","Ca",""))) -> Cl | D23: =IF(($C23="Q"),1,"") | E23: =IF(($C23="Ca"),1,"") | F23: =IF(($C23="Cl"),1,"") -> 1 | G23: =IF(Kode!$E$141=1,Kode!P$1,IF(Kode!$E$141=2,Kode!P$2,IF(Kode!$E$141=3,Kode!P$3,""))) -> 211 | H23: =IF(((VLOOKUP(G23,Kode!$A$144:$B$194,2,0))=0),"",(VLOOKUP(G23,Kode!$A$144:$B$194,2,0)))
A24: 11 | B24: c | C24: =IF(B24="a","Q",IF(B24="b","Ca",IF(B24="c","Cl",""))) -> Cl | D24: =IF(($C24="Q"),1,"") | E24: =IF(($C24="Ca"),1,"") | F24: =IF(($C24="Cl"),1,"") -> 1 | G24: =IF(Kode!$E$141=1,Kode!Q$1,IF(Kode!$E$141=2,Kode!Q$2,IF(Kode!$E$141=3,Kode!Q$3,""))) -> 212 | H24: =IF(((VLOOKUP(G24,Kode!$A$144:$B$194,2,0))=0),"",(VLOOKUP(G24,Kode!$A$144:$B$194,2,0)))
A25: 12 | B25: c | C25: =IF(B25="a","Cl",IF(B25="b","Q",IF(B25="c","Ca",""))) -> Ca | D25: =IF(($C25="Q"),1,"") | E25: =IF(($C25="Ca"),1,"") -> 1 | F25: =IF(($C25="Cl"),1,"") | G25: =IF(Kode!$E$141=1,Kode!R$1,IF(Kode!$E$141=2,Kode!R$2,IF(Kode!$E$141=3,Kode!R$3,""))) -> 213 | H25: =IF(((VLOOKUP(G25,Kode!$A$144:$B$194,2,0))=0),"",(VLOOKUP(G25,Kode!$A$144:$B$194,2,0)))
A26: 13 | B26: c | C26: =IF(B26="a","Ca",IF(B26="b","Q",IF(B26="c","Cl",""))) -> Cl | D26: =IF(($C26="Q"),1,"") | E26: =IF(($C26="Ca"),1,"") | F26: =IF(($C26="Cl"),1,"") -> 1 | G26: =IF(Kode!$E$141=1,Kode!S$1,IF(Kode!$E$141=2,Kode!S$2,IF(Kode!$E$141=3,Kode!S$3,""))) -> 214 | H26: =IF(((VLOOKUP(G26,Kode!$A$144:$B$194,2,0))=0),"",(VLOOKUP(G26,Kode!$A$144:$B$194,2,0)))
A27: 14 | B27: a | C27: =IF(B27="a","Q",IF(B27="b","Ca",IF(B27="c","Cl",""))) -> Q | D27: =IF(($C27="Q"),1,"") -> 1 | E27: =IF(($C27="Ca"),1,"") | F27: =IF(($C27="Cl"),1,"") | G27: =IF(Kode!$E$141=1,Kode!T$1,IF(Kode!$E$141=2,Kode!T$2,IF(Kode!$E$141=3,Kode!T$3,""))) -> 215 | H27: =IF(((VLOOKUP(G27,Kode!$A$144:$B$194,2,0))=0),"",(VLOOKUP(G27,Kode!$A$144:$B$194,2,0)))
A28: 15 | B28: a | C28: =IF(B28="a","Ca",IF(B28="b","Cl",IF(B28="c","Q",""))) -> Ca | D28: =IF(($C28="Q"),1,"") | E28: =IF(($C28="Ca"),1,"") -> 1 | F28: =IF(($C28="Cl"),1,"") | G28: =IF(Kode!$E$141=1,Kode!U$1,IF(Kode!$E$141=2,Kode!U$2,IF(Kode!$E$141=3,Kode!U$3,""))) -> 216 | H28: =IF(((VLOOKUP(G28,Kode!$A$144:$B$194,2,0))=0),"",(VLOOKUP(G28,Kode!$A$144:$B$194,2,0)))
D29: =SUM(D14:D28) -> 1 | E29: =SUM(E14:E28) -> 7 | F29: =SUM(F14:F28) -> 7
A31: KESIMPULAN :
A32: - Kandidat | C32: =Kode!I141 -> kurang disarankan | G32: untuk posisi pekerjaan di lapangan yang penuh tantangan dan
A33: membutuhkan daya tahan serta daya juang yang cukup tinggi.

Sheet Kode
A1: QUITTER | B1: =Interpretasi!D29 -> 1 | E1: QUITTER | F1: 101 | G1: 102 | H1: 103 | I1: 104 | J1: 105 | K1: 106 | L1: 107 | M1: 108 | N1: 109 | O1: 110 | P1: 111 | Q1: 112 | R1: 113 | S1: 114 | T1: 115 | U1: 116
A2: CAMPER | B2: =Interpretasi!E29 -> 7 | E2: CAMPER | F2: 201 | G2: 202 | H2: 203 | I2: 204 | J2: 205 | K2: 206 | L2: 207 | M2: 208 | N2: 209 | O2: 210 | P2: 211 | Q2: 212 | R2: 213 | S2: 214 | T2: 215 | U2: 216
A3: CLIMBER | B3: =Interpretasi!F29 -> 7 | E3: CLIMBER | F3: 301 | G3: 302 | H3: 303 | I3: 304 | J3: 305 | K3: 306 | L3: 307 | M3: 308 | N3: 309 | O3: 310 | P3: 311 | Q3: 312 | R3: 313 | S3: 314 | T3: 315 | U3: 316
A5: 7 | B5: 1 | C5: 7 | E5: =IF(AND($B$1=A5,($B$2=B5),($B$3=C5)),2,"") | F5: CAMPER
A6: 6 | B6: 3 | C6: 6 | E6: =IF(AND($B$1=A6,($B$2=B6),($B$3=C6)),2,"") | F6: CAMPER
A7: 5 | B7: 5 | C7: 5 | E7: =IF(AND($B$1=A7,($B$2=B7),($B$3=C7)),2,"") | F7: CAMPER
A8: 4 | B8: 6 | C8: 5 | E8: =IF(AND($B$1=A8,($B$2=B8),($B$3=C8)),2,"") | F8: CAMPER
A9: 5 | B9: 6 | C9: 4 | E9: =IF(AND($B$1=A9,($B$2=B9),($B$3=C9)),2,"") | F9: CAMPER
A10: 6 | B10: 6 | C10: 3 | E10: =IF(AND($B$1=A10,($B$2=B10),($B$3=C10)),2,"") | F10: CAMPER
A11: 2 | B11: 7 | C11: 6 | E11: =IF(AND($B$1=A11,($B$2=B11),($B$3=C11)),2,"") | F11: CAMPER
A12: 3 | B12: 7 | C12: 5 | E12: =IF(AND($B$1=A12,($B$2=B12),($B$3=C12)),2,"") | F12: CAMPER
A13: 4 | B13: 7 | C13: 4 | E13: =IF(AND($B$1=A13,($B$2=B13),($B$3=C13)),2,"") | F13: CAMPER
A14: 5 | B14: 7 | C14: 3 | E14: =IF(AND($B$1=A14,($B$2=B14),($B$3=C14)),2,"") | F14: CAMPER
A15: 6 | B15: 7 | C15: 2 | E15: =IF(AND($B$1=A15,($B$2=B15),($B$3=C15)),2,"") | F15: CAMPER
A16: 7 | B16: 7 | C16: 1 | E16: =IF(AND($B$1=A16,($B$2=B16),($B$3=C16)),2,"") | F16: CAMPER
... A53: 3 | B53: 6 | C53: 6 | E53: =IF(AND($B$1=A53,($B$2=B53),($B$3=C53)),2,"") | F53: CAMPER
A54: 4 | B54: 5 | C54: 6 | E54: =IF(AND($B$1=A54,($B$2=B54),($B$3=C54)),3,"") | F54: CLIMBER
A55: 5 | B55: 4 | C55: 6 | E55: =IF(AND($B$1=A55,($B$2=B55),($B$3=C55)),3,"") | F55: CLIMBER
A56: 1 | B56: 7 | C56: 7 | E56: =IF(AND($B$1=A56,($B$2=B56),($B$3=C56)),2,"") -> 2 | F56: CAMPER
A57: 2 | B57: 6 | C57: 7 | E57: =IF(AND($B$1=A57,($B$2=B57),($B$3=C57)),3,"") | F57: CLIMBER
A58: 3 | B58: 5 | C58: 7 | E58: =IF(AND($B$1=A58,($B$2=B58),($B$3=C58)),3,"") | F58: CLIMBER
A59: 4 | B59: 4 | C59: 7 | E59: =IF(AND($B$1=A59,($B$2=B59),($B$3=C59)),3,"") | F59: CLIMBER
A60: 5 | B60: 3 | C60: 7 | E60: =IF(AND($B$1=A60,($B$2=B60),($B$3=C60)),3,"") | F60: CLIMBER
A61: 6 | B61: 2 | C61: 7 | E61: =IF(AND($B$1=A61,($B$2=B61),($B$3=C61)),3,"") | F61: CLIMBER
A62: 0 | B62: 7 | C62: 8 | E62: =IF(AND($B$1=A62,($B$2=B62),($B$3=C62)),3,"") | F62: CLIMBER
A63: 1 | B63: 6 | C63: 8 | E63: =IF(AND($B$1=A63,($B$2=B63),($B$3=C63)),3,"") | F63: CLIMBER
A64: 2 | B64: 5 | C64: 8 | E64: =IF(AND($B$1=A64,($B$2=B64),($B$3=C64)),3,"") | F64: CLIMBER
A65: 3 | B65: 4 | C65: 8 | E65: =IF(AND($B$1=A65,($B$2=B65),($B$3=C65)),3,"") | F65: CLIMBER
A66: 4 | B66: 3 | C66: 8 | E66: =IF(AND($B$1=A66,($B$2=B66),($B$3=C66)),3,"") | F66: CLIMBER
A67: 5 | B67: 2 | C67: 8 | E67: =IF(AND($B$1=A67,($B$2=B67),($B$3=C67)),3,"") | F67: CLIMBER
A68: 6 | B68: 1 | C68: 8 | E68: =IF(AND($B$1=A68,($B$2=B68),($B$3=C68)),3,"") | F68: CLIMBER
... A97: 0 | B97: 0 | C97: 15 | E97: =IF(AND($B$1=A97,($B$2=B97),($B$3=C97)),3,"") | F97: CLIMBER
A98: 6 | B98: 4 | C98: 5 | E98: =IF(AND($B$1=A98,($B$2=B98),($B$3=C98)),1,"") | F98: QUITTER
A99: 6 | B99: 5 | C99: 4 | E99: =IF(AND($B$1=A99,($B$2=B99),($B$3=C99)),1,"") | F99: QUITTER
A100: 7 | B100: 2 | C100: 6 | E100: =IF(AND($B$1=A100,($B$2=B100),($B$3=C100)),1,"") | F100: QUITTER
A101: 7 | B101: 3 | C101: 5 | E101: =IF(AND($B$1=A101,($B$2=B101),($B$3=C101)),1,"") | F101: QUITTER
A102: 7 | B102: 4 | C102: 4 | E102: =IF(AND($B$1=A102,($B$2=B102),($B$3=C102)),1,"") | F102: QUITTER
A103: 7 | B103: 5 | C103: 3 | E103: =IF(AND($B$1=A103,($B$2=B103),($B$3=C103)),1,"") | F103: QUITTER
A104: 7 | B104: 6 | C104: 2 | E104: =IF(AND($B$1=A104,($B$2=B104),($B$3=C104)),1,"") | F104: QUITTER
A105: 8 | B105: 0 | C105: 7 | E105: =IF(AND($B$1=A105,($B$2=B105),($B$3=C105)),1,"") | F105: QUITTER
...
